<robot name="106">


	<link name="1:wheel">
		<visual>
			<origin xyz="-0.16592684388160706 4.846891027421307e-09 0.22176782367751002" rpy="0 0 0"/>
			<geometry>
				<mesh filename="raw_data/part_dae/1.dae" />
			</geometry>
		</visual>
	</link>


	<link name="2:caster">
		<visual>
			<origin xyz="-0.0 -0.0 -0.0" rpy="0 0 0"/>
			<geometry>
				<mesh filename="raw_data/part_dae/2.dae" />
			</geometry>
		</visual>
	</link>


	<link name="3:wheel">
		<visual>
			<origin xyz="-0.06868565082550049 0.39346974258781975 -0.2537205144762993" rpy="0 0 0"/>
			<geometry>
				<mesh filename="raw_data/part_dae/3.dae" />
			</geometry>
		</visual>
	</link>


	<link name="4:caster">
		<visual>
			<origin xyz="-0.0 -0.0 -0.0" rpy="0 0 0"/>
			<geometry>
				<mesh filename="raw_data/part_dae/4.dae" />
			</geometry>
		</visual>
	</link>


	<link name="5:wheel">
		<visual>
			<origin xyz="0.26165415346622467 1.8829651171614614e-09 0.086154505610466" rpy="0 0 0"/>
			<geometry>
				<mesh filename="raw_data/part_dae/5.dae" />
			</geometry>
		</visual>
	</link>


	<link name="6:caster">
		<visual>
			<origin xyz="-0.0 -0.0 -0.0" rpy="0 0 0"/>
			<geometry>
				<mesh filename="raw_data/part_dae/6.dae" />
			</geometry>
		</visual>
	</link>


	<link name="7:wheel">
		<visual>
			<origin xyz="0.26165415346622467 7.880555097372621e-09 0.3605721518397331" rpy="0 0 0"/>
			<geometry>
				<mesh filename="raw_data/part_dae/7.dae" />
			</geometry>
		</visual>
	</link>


	<link name="8:caster">
		<visual>
			<origin xyz="-0.0 -0.0 -0.0" rpy="0 0 0"/>
			<geometry>
				<mesh filename="raw_data/part_dae/8.dae" />
			</geometry>
		</visual>
	</link>


	<link name="9:wheel">
		<visual>
			<origin xyz="-0.00319099985063076 9.658934985168344e-09 0.441940002143383" rpy="0 0 0"/>
			<geometry>
				<mesh filename="raw_data/part_dae/9.dae" />
			</geometry>
		</visual>
	</link>


	<link name="10:caster">
		<visual>
			<origin xyz="-0.0 -0.0 -0.0" rpy="0 0 0"/>
			<geometry>
				<mesh filename="raw_data/part_dae/10.dae" />
			</geometry>
		</visual>
	</link>


	<link name="11:base">
		<visual>
			<origin xyz="-0.0 -0.0 -0.0" rpy="0 0 0"/>
			<geometry>
				<mesh filename="raw_data/part_dae/11.dae" />
			</geometry>
		</visual>
	</link>


	<link name="12:gas lift piece">
		<visual>
			<origin xyz="-0.0 -0.0 -0.0" rpy="0 0 0"/>
			<geometry>
				<mesh filename="raw_data/part_dae/12.dae" />
			</geometry>
		</visual>
	</link>


	<link name="13:gas lift piece">
		<visual>
			<origin xyz="0.06868569145071565 -0.26775474017025536 0.22430335969031795" rpy="0 0 0"/>
			<geometry>
				<mesh filename="raw_data/part_dae/13.dae" />
			</geometry>
		</visual>
	</link>


	<link name="14:arm">
		<visual>
			<origin xyz="-0.0 -0.0 -0.0" rpy="0 0 0"/>
			<geometry>
				<mesh filename="raw_data/part_dae/14.dae" />
			</geometry>
		</visual>
	</link>


	<link name="15:arm">
		<visual>
			<origin xyz="-0.0 -0.0 -0.0" rpy="0 0 0"/>
			<geometry>
				<mesh filename="raw_data/part_dae/15.dae" />
			</geometry>
		</visual>
	</link>


	<link name="16:back">
		<visual>
			<origin xyz="-0.0 -0.0 -0.0" rpy="0 0 0"/>
			<geometry>
				<mesh filename="raw_data/part_dae/16.dae" />
			</geometry>
		</visual>
	</link>


	<link name="17:seat">
		<visual>
			<origin xyz="-0.0 -0.4177574962377548 0.002097010612487793" rpy="0 0 0"/>
			<geometry>
				<mesh filename="raw_data/part_dae/17.dae" />
			</geometry>
		</visual>
	</link>


	<joint name="15:arm::16:back" type="fixed">
		<parent link="15:arm"/>
		<child link="16:back"/>
		<origin xyz="0.0 0.0 0.0" rpy="0 0 0"/>
	</joint>


	<joint name="14:arm::16:back" type="fixed">
		<parent link="14:arm"/>
		<child link="16:back"/>
		<origin xyz="0.0 0.0 0.0" rpy="0 0 0"/>
	</joint>


	<joint name="17:seat::16:back" type="fixed">
		<parent link="17:seat"/>
		<child link="16:back"/>
		<origin xyz="0.0 -0.4177574962377548 0.002097010612487793" rpy="0 0 0"/>
	</joint>


	<joint name="17:seat::15:arm" type="fixed">
		<parent link="17:seat"/>
		<child link="15:arm"/>
		<origin xyz="0.0 -0.4177574962377548 0.002097010612487793" rpy="0 0 0"/>
	</joint>


	<joint name="17:seat::14:arm" type="fixed">
		<parent link="17:seat"/>
		<child link="14:arm"/>
		<origin xyz="0.0 -0.4177574962377548 0.002097010612487793" rpy="0 0 0"/>
	</joint>


	<joint name="13:gas lift piece::17:seat_rotation" type="revolute">
		<parent link="13:gas lift piece"/>
		<child link="17:seat"/>
		<origin xyz="0.06868569145071565 0.15000275606749947 0.22220634907783016" rpy="0 0 0"/>
		<limit lower="-3.141592653589793" upper="3.141592653589793" effort="10" velocity="3"/>
		<axis xyz="0.0 1.0 0.0"/>
	</joint>


	<joint name="4:caster::3:wheel_rotation" type="revolute">
		<parent link="4:caster"/>
		<child link="3:wheel"/>
		<origin xyz="0.06868565082550049 -0.39346974258781975 0.2537205144762993" rpy="0 0 0"/>
		<limit lower="-3.141592653589793" upper="3.141592653589793" effort="10" velocity="3"/>
		<axis xyz="1.0 0.0 0.0"/>
	</joint>


	<joint name="2:caster::1:wheel_rotation" type="revolute">
		<parent link="2:caster"/>
		<child link="1:wheel"/>
		<origin xyz="0.16592684388160706 -4.846891027421307e-09 -0.22176782367751002" rpy="0 0 0"/>
		<limit lower="-3.141592653589793" upper="3.141592653589793" effort="10" velocity="3"/>
		<axis xyz="1.0 0.0 0.0"/>
	</joint>


	<joint name="10:caster::9:wheel_rotation" type="revolute">
		<parent link="10:caster"/>
		<child link="9:wheel"/>
		<origin xyz="0.00319099985063076 -9.658934985168344e-09 -0.441940002143383" rpy="0 0 0"/>
		<limit lower="-3.141592653589793" upper="3.141592653589793" effort="10" velocity="3"/>
		<axis xyz="1.0 0.0 0.0"/>
	</joint>


	<joint name="6:caster::5:wheel_rotation" type="revolute">
		<parent link="6:caster"/>
		<child link="5:wheel"/>
		<origin xyz="-0.26165415346622467 -1.8829651171614614e-09 -0.086154505610466" rpy="0 0 0"/>
		<limit lower="-3.141592653589793" upper="3.141592653589793" effort="10" velocity="3"/>
		<axis xyz="1.0 0.0 0.0"/>
	</joint>


	<joint name="11:base::5:wheel" type="fixed">
		<parent link="11:base"/>
		<child link="5:wheel"/>
		<origin xyz="-0.26165415346622467 -1.8829651171614614e-09 -0.086154505610466" rpy="0 0 0"/>
	</joint>


	<joint name="8:caster::7:wheel_rotation" type="revolute">
		<parent link="8:caster"/>
		<child link="7:wheel"/>
		<origin xyz="-0.26165415346622467 -7.880555097372621e-09 -0.3605721518397331" rpy="0 0 0"/>
		<limit lower="-3.141592653589793" upper="3.141592653589793" effort="10" velocity="3"/>
		<axis xyz="1.0 0.0 0.0"/>
	</joint>


	<joint name="2:caster::11:base" type="fixed">
		<parent link="2:caster"/>
		<child link="11:base"/>
		<origin xyz="0.0 0.0 0.0" rpy="0 0 0"/>
	</joint>


	<joint name="10:caster::11:base" type="fixed">
		<parent link="10:caster"/>
		<child link="11:base"/>
		<origin xyz="0.0 0.0 0.0" rpy="0 0 0"/>
	</joint>


	<joint name="8:caster::11:base" type="fixed">
		<parent link="8:caster"/>
		<child link="11:base"/>
		<origin xyz="0.0 0.0 0.0" rpy="0 0 0"/>
	</joint>


	<joint name="4:caster::11:base" type="fixed">
		<parent link="4:caster"/>
		<child link="11:base"/>
		<origin xyz="0.0 0.0 0.0" rpy="0 0 0"/>
	</joint>


	<joint name="12:gas lift piece::11:base" type="fixed">
		<parent link="12:gas lift piece"/>
		<child link="11:base"/>
		<origin xyz="0.0 0.0 0.0" rpy="0 0 0"/>
	</joint>


	<joint name="6:caster::11:base" type="fixed">
		<parent link="6:caster"/>
		<child link="11:base"/>
		<origin xyz="0.0 0.0 0.0" rpy="0 0 0"/>
	</joint>


	<joint name="12:gas lift piece::13:gas lift piece_translation" type="prismatic">
		<parent link="12:gas lift piece"/>
		<child link="13:gas lift piece"/>
		<origin xyz="-0.06868569145071565 0.26775474017025536 -0.22430335969031795" rpy="0 0 0"/>
		<limit lower="-0.0365284856855869" upper="0.00347151431441307" effort="10" velocity="3"/>
		<axis xyz="0.0 1.0 0.0"/>
	</joint>


</robot>