<robot name="106">


	<link name="1:wheel">
		<visual>
			<origin xyz="-0.23461249470710754 -0.024287748803044046 -0.02985568018630147" rpy="0 0 0"/>
			<geometry>
				<mesh filename="raw_data/part_dae/1.dae" />
			</geometry>
		</visual>
	</link>


	<link name="2:caster">
		<visual>
			<origin xyz="-0.0 -0.0 -0.0" rpy="0 0 0"/>
			<geometry>
				<mesh filename="raw_data/part_dae/2.dae" />
			</geometry>
		</visual>
	</link>


	<link name="3:wheel">
		<visual>
			<origin xyz="-0.06868565082550049 -0.024287753649935073 -0.2516235038638115" rpy="0 0 0"/>
			<geometry>
				<mesh filename="raw_data/part_dae/3.dae" />
			</geometry>
		</visual>
	</link>


	<link name="4:caster">
		<visual>
			<origin xyz="-0.0 -0.0 -0.0" rpy="0 0 0"/>
			<geometry>
				<mesh filename="raw_data/part_dae/4.dae" />
			</geometry>
		</visual>
	</link>


	<link name="5:wheel">
		<visual>
			<origin xyz="0.19296850264072418 -0.024287751766969956 -0.1654689982533455" rpy="0 0 0"/>
			<geometry>
				<mesh filename="raw_data/part_dae/5.dae" />
			</geometry>
		</visual>
	</link>


	<link name="6:caster">
		<visual>
			<origin xyz="-0.0 -0.0 -0.0" rpy="0 0 0"/>
			<geometry>
				<mesh filename="raw_data/part_dae/6.dae" />
			</geometry>
		</visual>
	</link>


	<link name="7:wheel">
		<visual>
			<origin xyz="0.19296850264072418 -0.024287745769379976 0.10894864797592163" rpy="0 0 0"/>
			<geometry>
				<mesh filename="raw_data/part_dae/7.dae" />
			</geometry>
		</visual>
	</link>


	<link name="8:caster">
		<visual>
			<origin xyz="-0.0 -0.0 -0.0" rpy="0 0 0"/>
			<geometry>
				<mesh filename="raw_data/part_dae/8.dae" />
			</geometry>
		</visual>
	</link>


	<link name="9:wheel">
		<visual>
			<origin xyz="-0.07187665067613125 -0.024287743991000088 0.19031649827957153" rpy="0 0 0"/>
			<geometry>
				<mesh filename="raw_data/part_dae/9.dae" />
			</geometry>
		</visual>
	</link>


	<link name="10:caster">
		<visual>
			<origin xyz="-0.0 -0.0 -0.0" rpy="0 0 0"/>
			<geometry>
				<mesh filename="raw_data/part_dae/10.dae" />
			</geometry>
		</visual>
	</link>


	<link name="11:base">
		<visual>
			<origin xyz="-0.0 -0.0 -0.0" rpy="0 0 0"/>
			<geometry>
				<mesh filename="raw_data/part_dae/11.dae" />
			</geometry>
		</visual>
	</link>


	<link name="12:gas lift piece">
		<visual>
			<origin xyz="-2.5680730458832457e-09 -0.11304300278425217 -0.028758065351089032" rpy="0 0 0"/>
			<geometry>
				<mesh filename="raw_data/part_dae/12.dae" />
			</geometry>
		</visual>
	</link>


	<link name="13:gas lift piece">
		<visual>
			<origin xyz="0.019719761365080152 -0.1806190013885498 -0.024017783463802116" rpy="0 0 0"/>
			<geometry>
				<mesh filename="raw_data/part_dae/13.dae" />
			</geometry>
		</visual>
	</link>


	<link name="14:arm">
		<visual>
			<origin xyz="-0.0 -0.0 -0.0" rpy="0 0 0"/>
			<geometry>
				<mesh filename="raw_data/part_dae/14.dae" />
			</geometry>
		</visual>
	</link>


	<link name="15:arm">
		<visual>
			<origin xyz="-0.0 -0.0 -0.0" rpy="0 0 0"/>
			<geometry>
				<mesh filename="raw_data/part_dae/15.dae" />
			</geometry>
		</visual>
	</link>


	<link name="16:back">
		<visual>
			<origin xyz="-0.0 -0.0 -0.0" rpy="0 0 0"/>
			<geometry>
				<mesh filename="raw_data/part_dae/16.dae" />
			</geometry>
		</visual>
	</link>


	<link name="17:seat">
		<visual>
			<origin xyz="0.01249459573411859 -0.40261900138854984 -0.023186566122892122" rpy="0 0 0"/>
			<geometry>
				<mesh filename="raw_data/part_dae/17.dae" />
			</geometry>
		</visual>
	</link>


	<joint name="15:arm::16:back" type="fixed">
		<parent link="15:arm"/>
		<child link="16:back"/>
		<origin xyz="0.0 0.0 0.0" rpy="0 0 0"/>
	</joint>


	<joint name="14:arm::16:back" type="fixed">
		<parent link="14:arm"/>
		<child link="16:back"/>
		<origin xyz="0.0 0.0 0.0" rpy="0 0 0"/>
	</joint>


	<joint name="17:seat::16:back" type="fixed">
		<parent link="17:seat"/>
		<child link="16:back"/>
		<origin xyz="0.01249459573411859 -0.40261900138854984 -0.023186566122892122" rpy="0 0 0"/>
	</joint>


	<joint name="17:seat::15:arm" type="fixed">
		<parent link="17:seat"/>
		<child link="15:arm"/>
		<origin xyz="0.01249459573411859 -0.40261900138854984 -0.023186566122892122" rpy="0 0 0"/>
	</joint>


	<joint name="17:seat::14:arm" type="fixed">
		<parent link="17:seat"/>
		<child link="14:arm"/>
		<origin xyz="0.01249459573411859 -0.40261900138854984 -0.023186566122892122" rpy="0 0 0"/>
	</joint>


	<joint name="13:gas lift piece::17:seat_rotation" type="revolute">
		<parent link="13:gas lift piece"/>
		<child link="17:seat"/>
		<origin xyz="0.007225165630961563 0.22200000000000003 -0.0008312173409099934" rpy="0 0 0"/>
		<limit lower="-3.141592653589793" upper="3.141592653589793" effort="10" velocity="3"/>
		<axis xyz="0.0 1.0 0.0"/>
	</joint>


	<joint name="4:caster::3:wheel_rotation" type="revolute">
		<parent link="4:caster"/>
		<child link="3:wheel"/>
		<origin xyz="0.06868565082550049 0.024287753649935073 0.2516235038638115" rpy="0 0 0"/>
		<limit lower="-3.141592653589793" upper="3.141592653589793" effort="10" velocity="3"/>
		<axis xyz="-1.0 0.0 0.0"/>
	</joint>


	<joint name="2:caster::1:wheel_rotation" type="revolute">
		<parent link="2:caster"/>
		<child link="1:wheel"/>
		<origin xyz="0.23461249470710754 0.024287748803044046 0.02985568018630147" rpy="0 0 0"/>
		<limit lower="-3.141592653589793" upper="3.141592653589793" effort="10" velocity="3"/>
		<axis xyz="0.0 0.0 1.0"/>
	</joint>


	<joint name="10:caster::9:wheel_rotation" type="revolute">
		<parent link="10:caster"/>
		<child link="9:wheel"/>
		<origin xyz="0.07187665067613125 0.024287743991000088 -0.19031649827957153" rpy="0 0 0"/>
		<limit lower="-3.141592653589793" upper="3.141592653589793" effort="10" velocity="3"/>
		<axis xyz="-1.0 0.0 0.0"/>
	</joint>


	<joint name="6:caster::5:wheel_rotation" type="revolute">
		<parent link="6:caster"/>
		<child link="5:wheel"/>
		<origin xyz="-0.19296850264072418 0.024287751766969956 0.1654689982533455" rpy="0 0 0"/>
		<limit lower="-3.141592653589793" upper="3.141592653589793" effort="10" velocity="3"/>
		<axis xyz="0.0 0.0 1.0"/>
	</joint>


	<joint name="11:base::5:wheel" type="fixed">
		<parent link="11:base"/>
		<child link="5:wheel"/>
		<origin xyz="-0.19296850264072418 0.024287751766969956 0.1654689982533455" rpy="0 0 0"/>
	</joint>


	<joint name="8:caster::7:wheel_rotation" type="revolute">
		<parent link="8:caster"/>
		<child link="7:wheel"/>
		<origin xyz="-0.19296850264072418 0.024287745769379976 -0.10894864797592163" rpy="0 0 0"/>
		<limit lower="-3.141592653589793" upper="3.141592653589793" effort="10" velocity="3"/>
		<axis xyz="0.0 0.0 1.0"/>
	</joint>


	<joint name="2:caster::11:base" type="fixed">
		<parent link="2:caster"/>
		<child link="11:base"/>
		<origin xyz="0.0 0.0 0.0" rpy="0 0 0"/>
	</joint>


	<joint name="10:caster::11:base" type="fixed">
		<parent link="10:caster"/>
		<child link="11:base"/>
		<origin xyz="0.0 0.0 0.0" rpy="0 0 0"/>
	</joint>


	<joint name="8:caster::11:base" type="fixed">
		<parent link="8:caster"/>
		<child link="11:base"/>
		<origin xyz="0.0 0.0 0.0" rpy="0 0 0"/>
	</joint>


	<joint name="4:caster::11:base" type="fixed">
		<parent link="4:caster"/>
		<child link="11:base"/>
		<origin xyz="0.0 0.0 0.0" rpy="0 0 0"/>
	</joint>


	<joint name="12:gas lift piece::11:base" type="fixed">
		<parent link="12:gas lift piece"/>
		<child link="11:base"/>
		<origin xyz="-2.5680730458832457e-09 -0.11304300278425217 -0.028758065351089032" rpy="0 0 0"/>
	</joint>


	<joint name="6:caster::11:base" type="fixed">
		<parent link="6:caster"/>
		<child link="11:base"/>
		<origin xyz="0.0 0.0 0.0" rpy="0 0 0"/>
	</joint>


	<joint name="13:gas lift piece::12:gas lift piece_rotation" type="revolute">
		<parent link="13:gas lift piece"/>
		<child link="12:gas lift piece"/>
		<origin xyz="0.0197197639331532 -0.06757599860429764 0.0047402818872869165" rpy="0 0 0"/>
		<limit lower="-3.141592653589793" upper="3.141592653589793" effort="10" velocity="3"/>
		<axis xyz="0.0 1.0 0.0"/>
	</joint>


</robot>