<robot name="106">


	<link name="wheel7">
		<visual>
			<origin xyz="0.26165415346622467 7.880555097372621e-09 0.3605721518397331" rpy="0 0 0"/>
			<geometry>
				<mesh filename="./raw_data/part_dae/7.dae" />
			</geometry>
		</visual>
	</link>


	<link name="caster8">
		<visual>
			<origin xyz="-0.0 -0.0 -0.0" rpy="0 0 0"/>
			<geometry>
				<mesh filename="./raw_data/part_dae/8.dae" />
			</geometry>
		</visual>
	</link>





	<joint name="caster8_wheel7_rotation" type="revolute">
		<parent link="caster8"/>
		<child link="wheel7"/>
		<origin xyz="-0.26165415346622467 -7.880555097372621e-09 -0.3605721518397331" rpy="0 0 0"/>
		<limit lower="-3.141592653589793" upper="3.141592653589793" effort="10" velocity="3"/>
		<axis xyz="1.0 0.0 0.0"/>
	</joint>



</robot>