<robot name="129">


	<link name="0:virtual">
		<visual>
			<origin xyz="0.0 0.0 0.0" rpy="0 0 0"/>
			<geometry>
				<cylinder length="0" radius="0"/>
			</geometry>
		</visual>
	</link>


	<link name="1:static">
		<visual>
			<origin xyz="-0.0 -0.0 -0.0" rpy="0 0 0"/>
			<geometry>
				<mesh filename="raw_data/129/part_meshes/1.dae" />
			</geometry>
		</visual>
	</link>


	<link name="2:drawer 1">
		<visual>
			<origin xyz="-0.19905999302864075 -0.20582934096455574 0.005532495677471161" rpy="0 0 0"/>
			<geometry>
				<mesh filename="raw_data/129/part_meshes/2.dae" />
			</geometry>
		</visual>
	</link>


	<link name="3:drawer 2">
		<visual>
			<origin xyz="-0.19905999302864075 -0.402492493391037 0.005532495677471161" rpy="0 0 0"/>
			<geometry>
				<mesh filename="raw_data/129/part_meshes/3.dae" />
			</geometry>
		</visual>
	</link>


	<link name="4:drawer 3">
		<visual>
			<origin xyz="-0.19905999302864075 -0.5877389907836914 0.005532495677471161" rpy="0 0 0"/>
			<geometry>
				<mesh filename="raw_data/129/part_meshes/4.dae" />
			</geometry>
		</visual>
	</link>


	<link name="5:drawer 4">
		<visual>
			<origin xyz="-0.19855999201536179 -0.7751494944095612 0.005532495677471161" rpy="0 0 0"/>
			<geometry>
				<mesh filename="raw_data/129/part_meshes/5.dae" />
			</geometry>
		</visual>
	</link>


	<link name="6:cabinet door 1">
		<visual>
			<origin xyz="0.5968620181083679 -0.39107634499669075 -0.13301100581884384" rpy="0 0 0"/>
			<geometry>
				<mesh filename="raw_data/129/part_meshes/6.dae" />
			</geometry>
		</visual>
	</link>


	<link name="7:drawer 5">
		<visual>
			<origin xyz="0.39788150787353516 -0.7751494944095612 0.005532495677471161" rpy="0 0 0"/>
			<geometry>
				<mesh filename="raw_data/129/part_meshes/7.dae" />
			</geometry>
		</visual>
	</link>


	<joint name="0:virtual::1:static" type="fixed">
		<parent link="0:virtual"/>
		<child link="1:static"/>
		<origin xyz="0.0 0.0 0.0" rpy="0 0 0"/>
	</joint>


	<joint name="0:virtual::2:drawer 1_translation" type="prismatic">
		<parent link="0:virtual"/>
		<child link="2:drawer 1"/>
		<origin xyz="0.19905999302864075 0.20582934096455574 -0.005532495677471161" rpy="0 0 0"/>
		<limit lower="-0.0001015064716339" upper="0.235898493528366" effort="10" velocity="3"/>
		<axis xyz="0.0 0.0 1.0"/>
	</joint>


	<joint name="0:virtual::3:drawer 2_translation" type="prismatic">
		<parent link="0:virtual"/>
		<child link="3:drawer 2"/>
		<origin xyz="0.19905999302864075 0.402492493391037 -0.005532495677471161" rpy="0 0 0"/>
		<limit lower="-0.0001015064716339" upper="0.235898493528366" effort="10" velocity="3"/>
		<axis xyz="0.0 0.0 1.0"/>
	</joint>


	<joint name="0:virtual::4:drawer 3_translation" type="prismatic">
		<parent link="0:virtual"/>
		<child link="4:drawer 3"/>
		<origin xyz="0.19905999302864075 0.5877389907836914 -0.005532495677471161" rpy="0 0 0"/>
		<limit lower="-0.0001015064716339" upper="0.235898493528366" effort="10" velocity="3"/>
		<axis xyz="0.0 0.0 1.0"/>
	</joint>


	<joint name="0:virtual::5:drawer 4_translation" type="prismatic">
		<parent link="0:virtual"/>
		<child link="5:drawer 4"/>
		<origin xyz="0.19855999201536179 0.7751494944095612 -0.005532495677471161" rpy="0 0 0"/>
		<limit lower="-0.0001015064716339" upper="0.235898493528366" effort="10" velocity="3"/>
		<axis xyz="0.0 0.0 1.0"/>
	</joint>


	<joint name="0:virtual::6:cabinet door 1_rotation" type="revolute">
		<parent link="0:virtual"/>
		<child link="6:cabinet door 1"/>
		<origin xyz="-0.5968620181083679 0.39107634499669075 0.13301100581884384" rpy="0 0 0"/>
		<limit lower="-3.0473448739820994" upper="0.0" effort="10" velocity="3"/>
		<axis xyz="0.0 1.0 0.0"/>
	</joint>


	<joint name="0:virtual::7:drawer 5_translation" type="prismatic">
		<parent link="0:virtual"/>
		<child link="7:drawer 5"/>
		<origin xyz="-0.39788150787353516 0.7751494944095612 -0.005532495677471161" rpy="0 0 0"/>
		<limit lower="-0.0001015064716339" upper="0.235898493528366" effort="10" velocity="3"/>
		<axis xyz="0.0 0.0 1.0"/>
	</joint>


</robot>