<robot name="397">


	<link name="1:handle">
		 <visual>
      <geometry>
        <cylinder length="0" radius="0.03"/>
      </geometry>
    </visual>

	</link>


	<link name="2:handle">
		<visual>
			<origin xyz="-0.0 -0.0 -0.0" rpy="0 0 0"/>
			<geometry>
				<mesh filename="raw_data/397/part_dae/2.dae" />
			</geometry>
		</visual>
	</link>


	<link name="3:handle">
		<visual>
			<origin xyz="-0.0 -0.0 -0.0" rpy="0 0 0"/>
			<geometry>
				<mesh filename="raw_data/397/part_dae/3.dae" />
			</geometry>
		</visual>
	</link>


	<link name="4:handle">
		<visual>
			<origin xyz="-0.0 -0.0 -0.0" rpy="0 0 0"/>
			<geometry>
				<mesh filename="raw_data/397/part_dae/4.dae" />
			</geometry>
		</visual>
	</link>


	<link name="5:bottom panel">
		<visual>
			<origin xyz="-0.0 -0.0 -0.0" rpy="0 0 0"/>
			<geometry>
				<mesh filename="raw_data/397/part_dae/5.dae" />
			</geometry>
		</visual>
	</link>


	<link name="6:front panel">
		<visual>
			<origin xyz="-0.0 -0.0 -0.0" rpy="0 0 0"/>
			<geometry>
				<mesh filename="raw_data/397/part_dae/6.dae" />
			</geometry>
		</visual>
	</link>


	<link name="7:top panel">
		<visual>
			<origin xyz="-0.0 -0.0 -0.0" rpy="0 0 0"/>
			<geometry>
				<mesh filename="raw_data/397/part_dae/7.dae" />
			</geometry>
		</visual>
	</link>


	<link name="8:side panel">
		<visual>
			<origin xyz="-0.0 -0.0 -0.0" rpy="0 0 0"/>
			<geometry>
				<mesh filename="raw_data/397/part_dae/8.dae" />
			</geometry>
		</visual>
	</link>


	<link name="9:back panel">
		<visual>
			<origin xyz="-0.0 -0.0 -0.0" rpy="0 0 0"/>
			<geometry>
				<mesh filename="raw_data/397/part_dae/9.dae" />
			</geometry>
		</visual>
	</link>


	<link name="10:side panel">
		<visual>
			<origin xyz="-0.0 -0.0 -0.0" rpy="0 0 0"/>
			<geometry>
				<mesh filename="raw_data/397/part_dae/10.dae" />
			</geometry>
		</visual>
	</link>


	<link name="11:drawer">
		<visual>
			<origin xyz="5.4001808166503906e-05 -0.7689925134181976 0.002888500690460205" rpy="0 0 0"/>
			<geometry>
				<mesh filename="raw_data/397/part_dae/11.dae" />
			</geometry>
		</visual>
	</link>


	<link name="12:drawer">
		<visual>
			<origin xyz="5.4001808166503906e-05 -0.18896714970469475 0.002888500690460205" rpy="0 0 0"/>
			<geometry>
				<mesh filename="raw_data/397/part_dae/12.dae" />
			</geometry>
		</visual>
	</link>


	<link name="13:drawer">
		<visual>
			<origin xyz="5.4001808166503906e-05 -0.3823090046644211 0.002888500690460205" rpy="0 0 0"/>
			<geometry>
				<mesh filename="raw_data/397/part_dae/13.dae" />
			</geometry>
		</visual>
	</link>


	<link name="14:drawer">
		<visual>
			<origin xyz="5.4001808166503906e-05 -0.57362499833107 0.002888500690460205" rpy="0 0 0"/>
			<geometry>
				<mesh filename="raw_data/397/part_dae/14.dae" />
			</geometry>
		</visual>
	</link>


	<joint name="8:side panel::6:front panel" type="fixed">
		<parent link="8:side panel"/>
		<child link="6:front panel"/>
		<origin xyz="0.0 0.0 0.0" rpy="0 0 0"/>
	</joint>


	<joint name="10:side panel::6:front panel" type="fixed">
		<parent link="10:side panel"/>
		<child link="6:front panel"/>
		<origin xyz="0.0 0.0 0.0" rpy="0 0 0"/>
	</joint>


	<joint name="5:bottom panel::6:front panel" type="fixed">
		<parent link="5:bottom panel"/>
		<child link="6:front panel"/>
		<origin xyz="0.0 0.0 0.0" rpy="0 0 0"/>
	</joint>


	<joint name="7:top panel::9:back panel" type="fixed">
		<parent link="7:top panel"/>
		<child link="9:back panel"/>
		<origin xyz="0.0 0.0 0.0" rpy="0 0 0"/>
	</joint>


	<joint name="8:side panel::9:back panel" type="fixed">
		<parent link="8:side panel"/>
		<child link="9:back panel"/>
		<origin xyz="0.0 0.0 0.0" rpy="0 0 0"/>
	</joint>


	<joint name="10:side panel::9:back panel" type="fixed">
		<parent link="10:side panel"/>
		<child link="9:back panel"/>
		<origin xyz="0.0 0.0 0.0" rpy="0 0 0"/>
	</joint>


	<joint name="5:bottom panel::9:back panel" type="fixed">
		<parent link="5:bottom panel"/>
		<child link="9:back panel"/>
		<origin xyz="0.0 0.0 0.0" rpy="0 0 0"/>
	</joint>


	<joint name="8:side panel::5:bottom panel" type="fixed">
		<parent link="8:side panel"/>
		<child link="5:bottom panel"/>
		<origin xyz="0.0 0.0 0.0" rpy="0 0 0"/>
	</joint>


	<joint name="10:side panel::5:bottom panel" type="fixed">
		<parent link="10:side panel"/>
		<child link="5:bottom panel"/>
		<origin xyz="0.0 0.0 0.0" rpy="0 0 0"/>
	</joint>


	<joint name="7:top panel::10:side panel" type="fixed">
		<parent link="7:top panel"/>
		<child link="10:side panel"/>
		<origin xyz="0.0 0.0 0.0" rpy="0 0 0"/>
	</joint>


	<joint name="7:top panel::8:side panel" type="fixed">
		<parent link="7:top panel"/>
		<child link="8:side panel"/>
		<origin xyz="0.0 0.0 0.0" rpy="0 0 0"/>
	</joint>


	<joint name="12:drawer::1:handle" type="fixed">
		<parent link="12:drawer"/>
		<child link="1:handle"/>
		<origin xyz="5.4001808166503906e-05 -0.18896714970469475 0.002888500690460205" rpy="0 0 0"/>
	</joint>


	<joint name="13:drawer::2:handle" type="fixed">
		<parent link="13:drawer"/>
		<child link="2:handle"/>
		<origin xyz="5.4001808166503906e-05 -0.3823090046644211 0.002888500690460205" rpy="0 0 0"/>
	</joint>


	<joint name="14:drawer::3:handle" type="fixed">
		<parent link="14:drawer"/>
		<child link="3:handle"/>
		<origin xyz="5.4001808166503906e-05 -0.57362499833107 0.002888500690460205" rpy="0 0 0"/>
	</joint>


	<joint name="11:drawer::4:handle" type="fixed">
		<parent link="11:drawer"/>
		<child link="4:handle"/>
		<origin xyz="5.4001808166503906e-05 -0.7689925134181976 0.002888500690460205" rpy="0 0 0"/>
	</joint>


	<joint name="8:side panel::12:drawer_translation" type="prismatic">
		<parent link="8:side panel"/>
		<child link="12:drawer"/>
		<origin xyz="-5.4001808166503906e-05 0.18896714970469475 -0.002888500690460205" rpy="0 0 0"/>
		<limit lower="-0.0001615035533905" upper="0.32883849644661" effort="10" velocity="3"/>
		<axis xyz="0.0 0.0 1.0"/>
	</joint>


	<joint name="8:side panel::13:drawer_translation" type="prismatic">
		<parent link="8:side panel"/>
		<child link="13:drawer"/>
		<origin xyz="-5.4001808166503906e-05 0.3823090046644211 -0.002888500690460205" rpy="0 0 0"/>
		<limit lower="-0.0001615035533905" upper="0.32883849644661" effort="10" velocity="3"/>
		<axis xyz="0.0 0.0 1.0"/>
	</joint>


	<joint name="8:side panel::14:drawer_translation" type="prismatic">
		<parent link="8:side panel"/>
		<child link="14:drawer"/>
		<origin xyz="-5.4001808166503906e-05 0.57362499833107 -0.002888500690460205" rpy="0 0 0"/>
		<limit lower="-0.0001615035533905" upper="0.32883849644661" effort="10" velocity="3"/>
		<axis xyz="0.0 0.0 1.0"/>
	</joint>


	<joint name="8:side panel::11:drawer_translation" type="prismatic">
		<parent link="8:side panel"/>
		<child link="11:drawer"/>
		<origin xyz="-5.4001808166503906e-05 0.7689925134181976 -0.002888500690460205" rpy="0 0 0"/>
		<limit lower="-0.0001615035533905" upper="0.32883849644661" effort="10" velocity="3"/>
		<axis xyz="0.0 0.0 1.0"/>
	</joint>


</robot>