<robot name="101">


	<link name="0:virtual">
		<visual>
			<origin xyz="0.0 0.0 0.0" rpy="0 0 0"/>
			<geometry>
				<cylinder length="0" radius="0"/>
			</geometry>
		</visual>
	</link>


	<link name="1:static">
		<visual>
			<origin xyz="-0.0 -0.0 -0.0" rpy="0 0 0"/>
			<geometry>
				<mesh filename="../raw_data/101/part_meshes/1.dae" />
			</geometry>
		</visual>
	</link>


	<link name="2:dial 1">
		<visual>
			<origin xyz="-0.11667504534125328 -0.6887584924697876 -0.2776990085840225" rpy="0 0 0"/>
			<geometry>
				<mesh filename="../raw_data/101/part_meshes/2.dae" />
			</geometry>
		</visual>
	</link>


	<link name="3:dial 2">
		<visual>
			<origin xyz="0.11667510122060776 -0.6887584924697876 -0.2776990085840225" rpy="0 0 0"/>
			<geometry>
				<mesh filename="../raw_data/101/part_meshes/3.dae" />
			</geometry>
		</visual>
	</link>


	<link name="4:oven door 1">
		<visual>
			<origin xyz="-0.0 -0.16499998750669992 -0.23601500689983368" rpy="0 0 0"/>
			<geometry>
				<mesh filename="../raw_data/101/part_meshes/4.dae" />
			</geometry>
		</visual>
	</link>


	<joint name="0:virtual::1:static" type="fixed">
		<parent link="0:virtual"/>
		<child link="1:static"/>
		<origin xyz="0.0 0.0 0.0" rpy="0 0 0"/>
	</joint>


	<joint name="0:virtual::2:dial 1_rotation" type="revolute">
		<parent link="0:virtual"/>
		<child link="2:dial 1"/>
		<origin xyz="0.11667504534125328 0.6887584924697876 0.2776990085840225" rpy="0 0 0"/>
		<limit lower="-3.141592653589793" upper="3.141592653589793" effort="10" velocity="3"/>
		<axis xyz="0.0 0.0 1.0"/>
	</joint>


	<joint name="0:virtual::3:dial 2_rotation" type="revolute">
		<parent link="0:virtual"/>
		<child link="3:dial 2"/>
		<origin xyz="-0.11667510122060776 0.6887584924697876 0.2776990085840225" rpy="0 0 0"/>
		<limit lower="-3.141592653589793" upper="3.141592653589793" effort="10" velocity="3"/>
		<axis xyz="0.0 0.0 1.0"/>
	</joint>


	<joint name="0:virtual::4:oven door 1_rotation" type="revolute">
		<parent link="0:virtual"/>
		<child link="4:oven door 1"/>
		<origin xyz="0.0 0.16499998750669992 0.23601500689983368" rpy="0 0 0"/>
		<limit lower="1.9634954084936207" upper="3.141592653589793" effort="10" velocity="3"/>
		<axis xyz="1.0 0.0 0.0"/>
	</joint>


</robot>