<robot name="107">


	<link name="0:virtual">
		<visual>
			<origin xyz="0.0 0.0 0.0" rpy="0 0 0"/>
			<geometry>
				<cylinder length="0" radius="0"/>
			</geometry>
		</visual>
	</link>


	<link name="1:static">
		<visual>
			<origin xyz="-0.0 -0.0 -0.0" rpy="0 0 0"/>
			<geometry>
				<mesh filename="../raw_data/107/part_meshes/1.dae" />
			</geometry>
		</visual>
	</link>


	<link name="2:drawer 1">
		<visual>
			<origin xyz="-0.5806649923324585 -0.5994524955749512 -0.010685011744499207" rpy="0 0 0"/>
			<geometry>
				<mesh filename="../raw_data/107/part_meshes/2.dae" />
			</geometry>
		</visual>
	</link>


	<link name="3:drawer 2">
		<visual>
			<origin xyz="-0.5806649923324585 -0.3513619974255562 -0.010685011744499207" rpy="0 0 0"/>
			<geometry>
				<mesh filename="../raw_data/107/part_meshes/3.dae" />
			</geometry>
		</visual>
	</link>


	<link name="4:cabinet door 1">
		<visual>
			<origin xyz="0.7475789785385132 -0.43593699485063553 -0.274725005030632" rpy="0 0 0"/>
			<geometry>
				<mesh filename="../raw_data/107/part_meshes/4.dae" />
			</geometry>
		</visual>
	</link>


	<joint name="0:virtual::1:static" type="fixed">
		<parent link="0:virtual"/>
		<child link="1:static"/>
		<origin xyz="0.0 0.0 0.0" rpy="0 0 0"/>
	</joint>


	<joint name="0:virtual::2:drawer 1_translation" type="prismatic">
		<parent link="0:virtual"/>
		<child link="2:drawer 1"/>
		<origin xyz="0.5806649923324585 0.5994524955749512 0.010685011744499207" rpy="0 0 0"/>
		<limit lower="0.0" upper="0.516426478505135" effort="10" velocity="3"/>
		<axis xyz="0.0 0.0 1.0"/>
	</joint>


	<joint name="0:virtual::3:drawer 2_translation" type="prismatic">
		<parent link="0:virtual"/>
		<child link="3:drawer 2"/>
		<origin xyz="0.5806649923324585 0.3513619974255562 0.010685011744499207" rpy="0 0 0"/>
		<limit lower="0.0" upper="0.516426478505135" effort="10" velocity="3"/>
		<axis xyz="0.0 0.0 1.0"/>
	</joint>


	<joint name="0:virtual::4:cabinet door 1_rotation" type="revolute">
		<parent link="0:virtual"/>
		<child link="4:cabinet door 1"/>
		<origin xyz="-0.7475789785385132 0.43593699485063553 0.274725005030632" rpy="0 0 0"/>
		<limit lower="-3.141592653589793" upper="0.0" effort="10" velocity="3"/>
		<axis xyz="0.0 1.0 0.0"/>
	</joint>


</robot>