<robot name="125">


	<link name="0:virtual">
		<visual>
			<origin xyz="0.0 0.0 0.0" rpy="0 0 0"/>
			<geometry>
				<cylinder length="0" radius="0"/>
			</geometry>
		</visual>
	</link>


	<link name="1:static">
		<inertial>
			<origin xyz="0.0 0.0 0.0" rpy="0.0 0.0 0.0"/>
			<mass value="1.0"/>
			<inertia ixx="1.0" ixy="0.0" ixz="0.0" iyy="1.0" iyz="0.0" izz="1.0"/>
		</inertial>
		<visual>
			<origin xyz="-0.0 -0.0 -0.0" rpy="0 0 0"/>
			<geometry>
				<mesh filename="../raw_data/125/part_meshes/1.dae" />
			</geometry>
		</visual>
	</link>


	<link name="2:cabinet door 1">
		<inertial>
			<origin xyz="0.0 0.0 0.0" rpy="0.0 0.0 0.0"/>
			<mass value="1.0"/>
			<inertia ixx="1.0" ixy="0.0" ixz="0.0" iyy="1.0" iyz="0.0" izz="1.0"/>
		</inertial>
		<visual>
			<origin xyz="0.03751914899266176 -0.4232254587113857 -0.006705547407272874" rpy="0 0 0"/>
			<geometry>
				<mesh filename="../raw_data/125/part_meshes/2.dae" />
			</geometry>
		</visual>
	</link>


	<link name="3:cabinet door 2">
		<inertial>
			<origin xyz="0.0 0.0 0.0" rpy="0.0 0.0 0.0"/>
			<mass value="1.0"/>
			<inertia ixx="1.0" ixy="0.0" ixz="0.0" iyy="1.0" iyz="0.0" izz="1.0"/>
		</inertial>
		<visual>
			<origin xyz="-0.5972049832344055 -0.4232254587113857 0.00763791985809803" rpy="0 0 0"/>
			<geometry>
				<mesh filename="../raw_data/125/part_meshes/3.dae" />
			</geometry>
		</visual>
	</link>


	<link name="4:faucet handle 1">
		<inertial>
			<origin xyz="0.0 0.0 0.0" rpy="0.0 0.0 0.0"/>
			<mass value="1.0"/>
			<inertia ixx="1.0" ixy="0.0" ixz="0.0" iyy="1.0" iyz="0.0" izz="1.0"/>
		</inertial>
		<visual>
			<origin xyz="0.4292668819295359 -0.8848250102996826 0.4236432989573781" rpy="0 0 0"/>
			<geometry>
				<mesh filename="../raw_data/125/part_meshes/4.dae" />
			</geometry>
		</visual>
	</link>


	<link name="5:faucet spout 1">
		<inertial>
			<origin xyz="0.0 0.0 0.0" rpy="0.0 0.0 0.0"/>
			<mass value="1.0"/>
			<inertia ixx="1.0" ixy="0.0" ixz="0.0" iyy="1.0" iyz="0.0" izz="1.0"/>
		</inertial>
		<visual>
			<origin xyz="0.42757480058550135 -0.7980260252952576 0.4582274358083104" rpy="0 0 0"/>
			<geometry>
				<mesh filename="../raw_data/125/part_meshes/5.dae" />
			</geometry>
		</visual>
	</link>


	<joint name="0:virtual::1:static" type="fixed">
		<parent link="0:virtual"/>
		<child link="1:static"/>
		<origin xyz="0.0 0.0 0.0" rpy="0 0 0"/>
	</joint>


	<joint name="0:virtual::2:cabinet door 1_rotation" type="revolute">
		<parent link="0:virtual"/>
		<child link="2:cabinet door 1"/>
		<origin xyz="-0.03751914899266176 0.4232254587113857 0.006705547407272874" rpy="0 0 0"/>
		<limit lower="0.0" upper="1.350884841043611" effort="10" velocity="3"/>
		<axis xyz="0.0 1.0 0.0"/>
	</joint>


	<joint name="0:virtual::3:cabinet door 2_rotation" type="revolute">
		<parent link="0:virtual"/>
		<child link="3:cabinet door 2"/>
		<origin xyz="0.5972049832344055 0.4232254587113857 -0.00763791985809803" rpy="0 0 0"/>
		<limit lower="0.0" upper="1.350884841043611" effort="10" velocity="3"/>
		<axis xyz="0.0 1.0 0.0"/>
	</joint>


	<joint name="5:faucet spout 1::4:faucet handle 1_rotation" type="revolute">
		<parent link="5:faucet spout 1"/>
		<child link="4:faucet handle 1"/>
		<origin xyz="-0.001692081344034535 0.08679898500442507 0.03458413685093226" rpy="0 0 0"/>
		<limit lower="-0.8168140899333463" upper="0.8639379797371932" effort="10" velocity="3"/>
		<axis xyz="0.0 1.0 0.0"/>
	</joint>


	<joint name="0:virtual::5:faucet spout 1_rotation" type="revolute">
		<parent link="0:virtual"/>
		<child link="5:faucet spout 1"/>
		<origin xyz="-0.42757480058550135 0.7980260252952576 -0.4582274358083104" rpy="0 0 0"/>
		<limit lower="-0.6283185307179586" upper="0.39269908169872414" effort="10" velocity="3"/>
		<axis xyz="0.0 1.0 0.0"/>
	</joint>


</robot>