<robot name="133">


	<link name="0:virtual">
		<visual>
			<origin xyz="0.0 0.0 0.0" rpy="0 0 0"/>
			<geometry>
				<cylinder length="0" radius="0"/>
			</geometry>
		</visual>
	</link>


	<link name="1:static">
		<visual>
			<origin xyz="-0.0 -0.0 -0.0" rpy="0 0 0"/>
			<geometry>
				<mesh filename="../raw_data/133/part_meshes/1.dae" />
			</geometry>
		</visual>
	</link>


	<link name="2:door 1">
		<visual>
			<origin xyz="0.7680416382256241 -0.05000000074505806 0.06754932285442018" rpy="0 0 0"/>
			<geometry>
				<mesh filename="../raw_data/133/part_meshes/2.dae" />
			</geometry>
		</visual>
	</link>


	<link name="3:door 2">
		<visual>
			<origin xyz="-0.8002469467468379 -0.05000000074505806 0.10017209214695046" rpy="0 0 0"/>
			<geometry>
				<mesh filename="../raw_data/133/part_meshes/3.dae" />
			</geometry>
		</visual>
	</link>


	<link name="4:handle 1">
		<visual>
			<origin xyz="0.23575050879787252 -0.9423599705696106 0.5889078013424442" rpy="0 0 0"/>
			<geometry>
				<mesh filename="../raw_data/133/part_meshes/4.dae" />
			</geometry>
		</visual>
	</link>


	<joint name="0:virtual::1:static" type="fixed">
		<parent link="0:virtual"/>
		<child link="1:static"/>
		<origin xyz="0.0 0.0 0.0" rpy="0 0 0"/>
	</joint>


	<joint name="0:virtual::2:door 1_rotation" type="revolute">
		<parent link="0:virtual"/>
		<child link="2:door 1"/>
		<origin xyz="-0.7680416382256241 0.05000000074505806 -0.06754932285442018" rpy="0 0 0"/>
		<limit lower="-0.7853981633974483" upper="1.6807520696705394" effort="10" velocity="3"/>
		<axis xyz="0.0 1.0 0.0"/>
	</joint>


	<joint name="0:virtual::3:door 2_rotation" type="revolute">
		<parent link="0:virtual"/>
		<child link="3:door 2"/>
		<origin xyz="0.8002469467468379 0.05000000074505806 -0.10017209214695046" rpy="0 0 0"/>
		<limit lower="-2.0263272615654166" upper="0.8482300164692442" effort="10" velocity="3"/>
		<axis xyz="0.0 1.0 0.0"/>
	</joint>


	<joint name="2:door 1::4:handle 1_rotation" type="revolute">
		<parent link="2:door 1"/>
		<child link="4:handle 1"/>
		<origin xyz="0.5322911294277516 0.8923599698245526 -0.5213584784880241" rpy="0 0 0"/>
		<limit lower="-0.7382742735936013" upper="0.0" effort="10" velocity="3"/>
		<axis xyz="-0.7025243861900091 0.0 -0.7116596706350242"/>
	</joint>


</robot>