<robot name="183">


	<link name="0:virtual">
		<visual>
			<origin xyz="0.0 0.0 0.0" rpy="0 0 0"/>
			<geometry>
				<cylinder length="0" radius="0"/>
			</geometry>
		</visual>
	</link>


	<link name="1:static">
		<visual>
			<origin xyz="-0.0 -0.0 -0.0" rpy="0 0 0"/>
			<geometry>
				<mesh filename="../raw_data/183/part_meshes/1.dae" />
			</geometry>
		</visual>
	</link>


	<link name="2:drawer 1">
		<visual>
			<origin xyz="-0.0 -0.13599950457089038 0.051110006868839264" rpy="0 0 0"/>
			<geometry>
				<mesh filename="../raw_data/183/part_meshes/2.dae" />
			</geometry>
		</visual>
	</link>


	<link name="3:faucet handle 1">
		<visual>
			<origin xyz="-0.053959401324391365 -0.4762919992208481 0.28250350058078766" rpy="0 0 0"/>
			<geometry>
				<mesh filename="../raw_data/183/part_meshes/3.dae" />
			</geometry>
		</visual>
	</link>


	<link name="4:faucet handle 2">
		<visual>
			<origin xyz="0.053959401324391365 -0.4762919992208481 0.28250350058078766" rpy="0 0 0"/>
			<geometry>
				<mesh filename="../raw_data/183/part_meshes/4.dae" />
			</geometry>
		</visual>
	</link>


	<joint name="0:virtual::1:static" type="fixed">
		<parent link="0:virtual"/>
		<child link="1:static"/>
		<origin xyz="0.0 0.0 0.0" rpy="0 0 0"/>
	</joint>


	<joint name="0:virtual::2:drawer 1_translation" type="prismatic">
		<parent link="0:virtual"/>
		<child link="2:drawer 1"/>
		<origin xyz="0.0 0.13599950457089038 -0.051110006868839264" rpy="0 0 0"/>
		<limit lower="-0.0001754917502403" upper="0.41482450824976" effort="10" velocity="3"/>
		<axis xyz="0.0 0.0 1.0"/>
	</joint>


	<joint name="0:virtual::3:faucet handle 1_rotation" type="revolute">
		<parent link="0:virtual"/>
		<child link="3:faucet handle 1"/>
		<origin xyz="0.053959401324391365 0.4762919992208481 -0.28250350058078766" rpy="0 0 0"/>
		<limit lower="-3.141592653589793" upper="3.141592653589793" effort="10" velocity="3"/>
		<axis xyz="1.0 0.0 0.0"/>
	</joint>


	<joint name="0:virtual::4:faucet handle 2_rotation" type="revolute">
		<parent link="0:virtual"/>
		<child link="4:faucet handle 2"/>
		<origin xyz="-0.053959401324391365 0.4762919992208481 -0.28250350058078766" rpy="0 0 0"/>
		<limit lower="-3.141592653589793" upper="3.141592653589793" effort="10" velocity="3"/>
		<axis xyz="1.0 0.0 0.0"/>
	</joint>


</robot>