<robot name="184">


	<link name="0:virtual">
		<visual>
			<origin xyz="0.0 0.0 0.0" rpy="0 0 0"/>
			<geometry>
				<cylinder length="0" radius="0"/>
			</geometry>
		</visual>
	</link>


	<link name="1:static">
		<visual>
			<origin xyz="-0.0 -0.0 -0.0" rpy="0 0 0"/>
			<geometry>
				<mesh filename="raw_data/184/part_meshes/1.dae" />
			</geometry>
		</visual>
	</link>


	<link name="2:drawer 1">
		<visual>
			<origin xyz="-0.4124946380034089 -0.8063510060310364 0.016566134989261627" rpy="0 0 0"/>
			<geometry>
				<mesh filename="raw_data/184/part_meshes/2.dae" />
			</geometry>
		</visual>
	</link>


	<link name="3:drawer 2">
		<visual>
			<origin xyz="-0.4124946380034089 -0.5362470000982285 0.016566261649131775" rpy="0 0 0"/>
			<geometry>
				<mesh filename="raw_data/184/part_meshes/3.dae" />
			</geometry>
		</visual>
	</link>


	<link name="4:drawer 3">
		<visual>
			<origin xyz="0.41249473858624697 -0.8063510060310364 0.016566134989261627" rpy="0 0 0"/>
			<geometry>
				<mesh filename="raw_data/184/part_meshes/4.dae" />
			</geometry>
		</visual>
	</link>


	<link name="5:drawer 4">
		<visual>
			<origin xyz="0.41249473858624697 -0.5362470000982285 0.016566261649131775" rpy="0 0 0"/>
			<geometry>
				<mesh filename="raw_data/184/part_meshes/5.dae" />
			</geometry>
		</visual>
	</link>


	<link name="6:cabinet door 1">
		<visual>
			<origin xyz="-2.0 -1.0999666256830096 -0.19941399991512299" rpy="0 0 0"/>
			<geometry>
				<mesh filename="raw_data/184/part_meshes/6.dae" />
			</geometry>
		</visual>
	</link>


	<link name="7:cabinet door 2">
		<visual>
			<origin xyz="0.9964194819331169 -1.1000000378116965 -0.24000000208616257" rpy="0 0 0"/>
			<geometry>
				<mesh filename="raw_data/184/part_meshes/7.dae" />
			</geometry>
		</visual>
	</link>


	<link name="8:cabinet door 3">
		<visual>
			<origin xyz="1.4051694869995117 -1.0999996280297637 -0.2199999988079071" rpy="0 0 0"/>
			<geometry>
				<mesh filename="raw_data/184/part_meshes/8.dae" />
			</geometry>
		</visual>
	</link>


	<joint name="0:virtual::1:static" type="fixed">
		<parent link="0:virtual"/>
		<child link="1:static"/>
		<origin xyz="0.0 0.0 0.0" rpy="0 0 0"/>
	</joint>


	<joint name="0:virtual::2:drawer 1_translation" type="prismatic">
		<parent link="0:virtual"/>
		<child link="2:drawer 1"/>
		<origin xyz="0.4124946380034089 0.8063510060310364 -0.016566134989261627" rpy="0 0 0"/>
		<limit lower="0.0" upper="0.278128490746021" effort="10" velocity="3"/>
		<axis xyz="0.0 0.0 1.0"/>
	</joint>


	<joint name="0:virtual::3:drawer 2_translation" type="prismatic">
		<parent link="0:virtual"/>
		<child link="3:drawer 2"/>
		<origin xyz="0.4124946380034089 0.5362470000982285 -0.016566261649131775" rpy="0 0 0"/>
		<limit lower="0.0" upper="0.282411990046501" effort="10" velocity="3"/>
		<axis xyz="0.0 0.0 1.0"/>
	</joint>


	<joint name="0:virtual::4:drawer 3_translation" type="prismatic">
		<parent link="0:virtual"/>
		<child link="4:drawer 3"/>
		<origin xyz="-0.41249473858624697 0.8063510060310364 -0.016566134989261627" rpy="0 0 0"/>
		<limit lower="0.0" upper="0.285411990046501" effort="10" velocity="3"/>
		<axis xyz="0.0 0.0 1.0"/>
	</joint>


	<joint name="0:virtual::5:drawer 4_translation" type="prismatic">
		<parent link="0:virtual"/>
		<child link="5:drawer 4"/>
		<origin xyz="-0.41249473858624697 0.5362470000982285 -0.016566261649131775" rpy="0 0 0"/>
		<limit lower="0.0" upper="0.279411990046501" effort="10" velocity="3"/>
		<axis xyz="0.0 0.0 1.0"/>
	</joint>


	<joint name="0:virtual::6:cabinet door 1_rotation" type="revolute">
		<parent link="0:virtual"/>
		<child link="6:cabinet door 1"/>
		<origin xyz="2.0 1.0999666256830096 0.19941399991512299" rpy="0 0 0"/>
		<limit lower="0.0" upper="3.141592653589793" effort="10" velocity="3"/>
		<axis xyz="0.0 1.0 0.0"/>
	</joint>


	<joint name="0:virtual::7:cabinet door 2_translation" type="prismatic">
		<parent link="0:virtual"/>
		<child link="7:cabinet door 2"/>
		<origin xyz="-0.9964194819331169 1.1000000378116965 0.24000000208616257" rpy="0 0 0"/>
		<limit lower="-0.216" upper="2.175" effort="10" velocity="3"/>
		<axis xyz="1.0 0.0 0.0"/>
	</joint>


	<joint name="0:virtual::8:cabinet door 3_translation" type="prismatic">
		<parent link="0:virtual"/>
		<child link="8:cabinet door 3"/>
		<origin xyz="-1.4051694869995117 1.0999996280297637 0.2199999988079071" rpy="0 0 0"/>
		<limit lower="0.0" upper="1.597" effort="10" velocity="3"/>
		<axis xyz="1.0 0.0 0.0"/>
	</joint>


</robot>