<robot name="186">


	<link name="0:virtual">
		<visual>
			<origin xyz="0.0 0.0 0.0" rpy="0 0 0"/>
			<geometry>
				<cylinder length="0" radius="0"/>
			</geometry>
		</visual>
	</link>


	<link name="1:static">
		<visual>
			<origin xyz="-0.0 -0.0 -0.0" rpy="0 0 0"/>
			<geometry>
				<mesh filename="../raw_data/186/part_meshes/1.dae" />
			</geometry>
		</visual>
	</link>


	<link name="2:faucet spout 1">
		<visual>
			<origin xyz="-0.0 -0.6515345275402069 0.2274613996446133" rpy="0 0 0"/>
			<geometry>
				<mesh filename="../raw_data/186/part_meshes/2.dae" />
			</geometry>
		</visual>
	</link>


	<link name="3:drawer 1">
		<visual>
			<origin xyz="-0.0 -0.30392350256443024 -0.0066605061292648315" rpy="0 0 0"/>
			<geometry>
				<mesh filename="../raw_data/186/part_meshes/3.dae" />
			</geometry>
		</visual>
	</link>


	<link name="4:drawer 2">
		<visual>
			<origin xyz="-0.0 -0.10323300954769365 -0.0066605061292648315" rpy="0 0 0"/>
			<geometry>
				<mesh filename="../raw_data/186/part_meshes/4.dae" />
			</geometry>
		</visual>
	</link>


	<link name="5:faucet handle 1">
		<visual>
			<origin xyz="0.025790697541252027 -0.6819350123405457 0.22680968813495406" rpy="0 0 0"/>
			<geometry>
				<mesh filename="../raw_data/186/part_meshes/5.dae" />
			</geometry>
		</visual>
	</link>


	<joint name="0:virtual::1:static" type="fixed">
		<parent link="0:virtual"/>
		<child link="1:static"/>
		<origin xyz="0.0 0.0 0.0" rpy="0 0 0"/>
	</joint>


	<joint name="0:virtual::2:faucet spout 1_rotation" type="revolute">
		<parent link="0:virtual"/>
		<child link="2:faucet spout 1"/>
		<origin xyz="0.0 0.6515345275402069 -0.2274613996446133" rpy="0 0 0"/>
		<limit lower="-0.8482300164692442" upper="0.5026548245743669" effort="10" velocity="3"/>
		<axis xyz="0.0 1.0 0.0"/>
	</joint>


	<joint name="0:virtual::3:drawer 1_translation" type="prismatic">
		<parent link="0:virtual"/>
		<child link="3:drawer 1"/>
		<origin xyz="0.0 0.30392350256443024 0.0066605061292648315" rpy="0 0 0"/>
		<limit lower="0.0" upper="0.428109987854958" effort="10" velocity="3"/>
		<axis xyz="0.0 0.0 1.0"/>
	</joint>


	<joint name="0:virtual::4:drawer 2_translation" type="prismatic">
		<parent link="0:virtual"/>
		<child link="4:drawer 2"/>
		<origin xyz="0.0 0.10323300954769365 0.0066605061292648315" rpy="0 0 0"/>
		<limit lower="0.0" upper="0.428109987854958" effort="10" velocity="3"/>
		<axis xyz="0.0 0.0 1.0"/>
	</joint>


	<joint name="2:faucet spout 1::5:faucet handle 1_rotation" type="revolute">
		<parent link="2:faucet spout 1"/>
		<child link="5:faucet handle 1"/>
		<origin xyz="-0.025790697541252027 0.030400484800338745 0.0006517115096592307" rpy="0 0 0"/>
		<limit lower="-0.07853981633974483" upper="0.3141592653589793" effort="10" velocity="3"/>
		<axis xyz="-0.9998990528438284 0.0 -0.014208593245462153"/>
	</joint>


</robot>