<robot name="194">


	<link name="0:virtual">
		<visual>
			<origin xyz="0.0 0.0 0.0" rpy="0 0 0"/>
			<geometry>
				<cylinder length="0" radius="0"/>
			</geometry>
		</visual>
	</link>


	<link name="1:static">
		<visual>
			<origin xyz="-0.0 -0.0 -0.0" rpy="0 0 0"/>
			<geometry>
				<mesh filename="raw_data/194/part_meshes/1.dae" />
			</geometry>
		</visual>
	</link>


	<link name="2:cabinet door 1">
		<visual>
			<origin xyz="-0.9758101802317241 -1.0499988039955497 -0.16028468172042487" rpy="0 0 0"/>
			<geometry>
				<mesh filename="raw_data/194/part_meshes/2.dae" />
			</geometry>
		</visual>
	</link>


	<link name="3:cabinet door 2">
		<visual>
			<origin xyz="0.9581099890001904 -1.0499991038814187 -0.2177363586243497" rpy="0 0 0"/>
			<geometry>
				<mesh filename="raw_data/194/part_meshes/3.dae" />
			</geometry>
		</visual>
	</link>


	<joint name="0:virtual::1:static" type="fixed">
		<parent link="0:virtual"/>
		<child link="1:static"/>
		<origin xyz="0.0 0.0 0.0" rpy="0 0 0"/>
	</joint>


	<joint name="0:virtual::2:cabinet door 1_rotation" type="revolute">
		<parent link="0:virtual"/>
		<child link="2:cabinet door 1"/>
		<origin xyz="0.9758101802317241 1.0499988039955497 0.16028468172042487" rpy="0 0 0"/>
		<limit lower="0.0" upper="2.0263272615654166" effort="10" velocity="3"/>
		<axis xyz="0.0 1.0 0.0"/>
	</joint>


	<joint name="0:virtual::3:cabinet door 2_rotation" type="revolute">
		<parent link="0:virtual"/>
		<child link="3:cabinet door 2"/>
		<origin xyz="-0.9581099890001904 1.0499991038814187 0.2177363586243497" rpy="0 0 0"/>
		<limit lower="-2.0106192982974678" upper="0.0" effort="10" velocity="3"/>
		<axis xyz="0.0 1.0 0.0"/>
	</joint>


</robot>