<robot name="247">


	<link name="0:virtual">
		<visual>
			<origin xyz="0.0 0.0 0.0" rpy="0 0 0"/>
			<geometry>
				<cylinder length="0" radius="0"/>
			</geometry>
		</visual>
	</link>


	<link name="1:static">
		<visual>
			<origin xyz="-0.0 -0.0 -0.0" rpy="0 0 0"/>
			<geometry>
				<mesh filename="../raw_data/247/part_meshes/1.dae" />
			</geometry>
		</visual>
	</link>


	<link name="2:door 1">
		<visual>
			<origin xyz="0.3643872955259246 -1.455000002980232 0.04707076504483003" rpy="0 0 0"/>
			<geometry>
				<mesh filename="../raw_data/247/part_meshes/2.dae" />
			</geometry>
		</visual>
	</link>


	<joint name="0:virtual::1:static" type="fixed">
		<parent link="0:virtual"/>
		<child link="1:static"/>
		<origin xyz="0.0 0.0 0.0" rpy="0 0 0"/>
	</joint>


	<joint name="0:virtual::2:door 1_rotation" type="revolute">
		<parent link="0:virtual"/>
		<child link="2:door 1"/>
		<origin xyz="-0.3643872955259246 1.455000002980232 -0.04707076504483003" rpy="0 0 0"/>
		<limit lower="-0.8639379797371932" upper="1.4451326206513049" effort="10" velocity="3"/>
		<axis xyz="0.0 1.0 0.0"/>
	</joint>


</robot>