<robot name="266">


	<link name="0:virtual">
		<visual>
			<origin xyz="0.0 0.0 0.0" rpy="0 0 0"/>
			<geometry>
				<cylinder length="0" radius="0"/>
			</geometry>
		</visual>
	</link>


	<link name="1:static">
		<visual>
			<origin xyz="-0.0 -0.0 -0.0" rpy="0 0 0"/>
			<geometry>
				<mesh filename="raw_data/266/part_meshes/1.dae" />
			</geometry>
		</visual>
	</link>


	<link name="2:door 1">
		<visual>
			<origin xyz="0.36953699588775635 -1.1101054698228836 -0.24659500271081924" rpy="0 0 0"/>
			<geometry>
				<mesh filename="raw_data/266/part_meshes/2.dae" />
			</geometry>
		</visual>
	</link>


	<link name="3:door 2">
		<visual>
			<origin xyz="-0.36953699588775635 -1.1101054698228836 -0.24659500271081924" rpy="0 0 0"/>
			<geometry>
				<mesh filename="raw_data/266/part_meshes/3.dae" />
			</geometry>
		</visual>
	</link>


	<joint name="0:virtual::1:static" type="fixed">
		<parent link="0:virtual"/>
		<child link="1:static"/>
		<origin xyz="0.0 0.0 0.0" rpy="0 0 0"/>
	</joint>


	<joint name="0:virtual::2:door 1_rotation" type="revolute">
		<parent link="0:virtual"/>
		<child link="2:door 1"/>
		<origin xyz="-0.36953699588775635 1.1101054698228836 0.24659500271081924" rpy="0 0 0"/>
		<limit lower="-1.4922565104551517" upper="0.0" effort="10" velocity="3"/>
		<axis xyz="0.0 1.0 0.0"/>
	</joint>


	<joint name="0:virtual::3:door 2_rotation" type="revolute">
		<parent link="0:virtual"/>
		<child link="3:door 2"/>
		<origin xyz="0.36953699588775635 1.1101054698228836 0.24659500271081924" rpy="0 0 0"/>
		<limit lower="0.0" upper="1.4765485471872026" effort="10" velocity="3"/>
		<axis xyz="0.0 1.0 0.0"/>
	</joint>


</robot>