<robot name="271">


	<link name="0:virtual">
		<visual>
			<origin xyz="0.0 0.0 0.0" rpy="0 0 0"/>
			<geometry>
				<cylinder length="0" radius="0"/>
			</geometry>
		</visual>
	</link>


	<link name="1:static">
		<visual>
			<origin xyz="-0.0 -0.0 -0.0" rpy="0 0 0"/>
			<geometry>
				<mesh filename="raw_data/271/part_meshes/1.dae" />
			</geometry>
		</visual>
	</link>


	<link name="2:drawer 1">
		<visual>
			<origin xyz="-0.00030300021171569824 -1.0758389830589294 0.0049974992871284485" rpy="0 0 0"/>
			<geometry>
				<mesh filename="raw_data/271/part_meshes/2.dae" />
			</geometry>
		</visual>
	</link>


	<link name="3:drawer 2">
		<visual>
			<origin xyz="-0.00030300021171569824 -0.8525895178318024 0.0049974992871284485" rpy="0 0 0"/>
			<geometry>
				<mesh filename="raw_data/271/part_meshes/3.dae" />
			</geometry>
		</visual>
	</link>


	<link name="4:drawer 3">
		<visual>
			<origin xyz="-9.000301361083984e-06 -0.6308709979057312 0.0049974992871284485" rpy="0 0 0"/>
			<geometry>
				<mesh filename="raw_data/271/part_meshes/4.dae" />
			</geometry>
		</visual>
	</link>


	<link name="5:door 1">
		<visual>
			<origin xyz="-0.6299980282783508 -1.1851799488067627 -0.23997201025485992" rpy="0 0 0"/>
			<geometry>
				<mesh filename="raw_data/271/part_meshes/5.dae" />
			</geometry>
		</visual>
	</link>


	<link name="6:door 2">
		<visual>
			<origin xyz="0.6492749691605572 -1.7799999713897705 -0.23900000953674277" rpy="0 0 0"/>
			<geometry>
				<mesh filename="raw_data/271/part_meshes/6.dae" />
			</geometry>
		</visual>
	</link>


	<joint name="0:virtual::1:static" type="fixed">
		<parent link="0:virtual"/>
		<child link="1:static"/>
		<origin xyz="0.0 0.0 0.0" rpy="0 0 0"/>
	</joint>


	<joint name="0:virtual::2:drawer 1_translation" type="prismatic">
		<parent link="0:virtual"/>
		<child link="2:drawer 1"/>
		<origin xyz="0.00030300021171569824 1.0758389830589294 -0.0049974992871284485" rpy="0 0 0"/>
		<limit lower="0.0" upper="0.448000022351742" effort="10" velocity="3"/>
		<axis xyz="0.0 0.0 1.0"/>
	</joint>


	<joint name="0:virtual::3:drawer 2_translation" type="prismatic">
		<parent link="0:virtual"/>
		<child link="3:drawer 2"/>
		<origin xyz="0.00030300021171569824 0.8525895178318024 -0.0049974992871284485" rpy="0 0 0"/>
		<limit lower="0.0" upper="0.438220986247063" effort="10" velocity="3"/>
		<axis xyz="0.0 0.0 1.0"/>
	</joint>


	<joint name="0:virtual::4:drawer 3_translation" type="prismatic">
		<parent link="0:virtual"/>
		<child link="4:drawer 3"/>
		<origin xyz="9.000301361083984e-06 0.6308709979057312 -0.0049974992871284485" rpy="0 0 0"/>
		<limit lower="0.0" upper="0.446000022351742" effort="10" velocity="3"/>
		<axis xyz="0.0 0.0 1.0"/>
	</joint>


	<joint name="0:virtual::5:door 1_rotation" type="revolute">
		<parent link="0:virtual"/>
		<child link="5:door 1"/>
		<origin xyz="0.6299980282783508 1.1851799488067627 0.23997201025485992" rpy="0 0 0"/>
		<limit lower="0.0" upper="1.4765485471872026" effort="10" velocity="3"/>
		<axis xyz="0.0 1.0 0.0"/>
	</joint>


	<joint name="0:virtual::6:door 2_rotation" type="revolute">
		<parent link="0:virtual"/>
		<child link="6:door 2"/>
		<origin xyz="-0.6492749691605572 1.7799999713897705 0.23900000953674277" rpy="0 0 0"/>
		<limit lower="-1.6493361431346414" upper="0.0" effort="10" velocity="3"/>
		<axis xyz="0.0 1.0 0.0"/>
	</joint>


</robot>