<robot name="335">


	<link name="0:virtual">
		<visual>
			<origin xyz="0.0 0.0 0.0" rpy="0 0 0"/>
			<geometry>
				<cylinder length="0" radius="0"/>
			</geometry>
		</visual>
	</link>


	<link name="1:static">
		<visual>
			<origin xyz="-0.0 -0.0 -0.0" rpy="0 0 0"/>
			<geometry>
				<mesh filename="raw_data/335/part_meshes/1.dae" />
			</geometry>
		</visual>
	</link>


	<link name="2:seat 1">
		<visual>
			<origin xyz="0.0006612018783845874 -0.48143652081489563 0.012038486080212785" rpy="0 0 0"/>
			<geometry>
				<mesh filename="raw_data/335/part_meshes/2.dae" />
			</geometry>
		</visual>
	</link>


	<link name="3:back 1">
		<visual>
			<origin xyz="-0.0 -0.7962155342102051 0.232573501765728" rpy="0 0 0"/>
			<geometry>
				<mesh filename="raw_data/335/part_meshes/3.dae" />
			</geometry>
		</visual>
	</link>


	<link name="4:wheel 1">
		<visual>
			<origin xyz="-0.2790089157069972 -0.025259584668674506 -0.0658795236838393" rpy="0 0 0"/>
			<geometry>
				<mesh filename="raw_data/335/part_meshes/4.dae" />
			</geometry>
		</visual>
	</link>


	<link name="5:wheel 2">
		<visual>
			<origin xyz="-0.008753250353038311 -0.025259589165216312 -0.2834869921207428" rpy="0 0 0"/>
			<geometry>
				<mesh filename="raw_data/335/part_meshes/5.dae" />
			</geometry>
		</visual>
	</link>


	<link name="6:wheel 3">
		<visual>
			<origin xyz="0.2735989465889165 -0.025259585163439624 -0.08320913510829739" rpy="0 0 0"/>
			<geometry>
				<mesh filename="raw_data/335/part_meshes/6.dae" />
			</geometry>
		</visual>
	</link>


	<link name="7:wheel 4">
		<visual>
			<origin xyz="0.17784655607603142 -0.02525957715988625 0.25817708051272775" rpy="0 0 0"/>
			<geometry>
				<mesh filename="raw_data/335/part_meshes/7.dae" />
			</geometry>
		</visual>
	</link>


	<link name="8:wheel 5">
		<visual>
			<origin xyz="-0.16368376790822767 -0.02525957715988625 0.26888736477292197" rpy="0 0 0"/>
			<geometry>
				<mesh filename="raw_data/335/part_meshes/8.dae" />
			</geometry>
		</visual>
	</link>


	<link name="9:gas lift piece 1">
		<visual>
			<origin xyz="1.5506874742610144e-09 -0.1991405040025711 0.018897852546253202" rpy="0 0 0"/>
			<geometry>
				<mesh filename="raw_data/335/part_meshes/9.dae" />
			</geometry>
		</visual>
	</link>


	<link name="10:caster 1">
		<visual>
			<origin xyz="0.017370465453642785 -0.04694264940917492 -0.2832771436720425" rpy="0 0 0"/>
			<geometry>
				<mesh filename="raw_data/335/part_meshes/10.dae" />
			</geometry>
		</visual>
	</link>


	<link name="11:caster 2">
		<visual>
			<origin xyz="-0.27404881776393314 -0.0474907001554966 -0.08430500426129597" rpy="0 0 0"/>
			<geometry>
				<mesh filename="raw_data/335/part_meshes/11.dae" />
			</geometry>
		</visual>
	</link>


	<link name="12:caster 3">
		<visual>
			<origin xyz="-0.18542075624881676 -0.04694264940917492 0.25237669248498834" rpy="0 0 0"/>
			<geometry>
				<mesh filename="raw_data/335/part_meshes/12.dae" />
			</geometry>
		</visual>
	</link>


	<link name="13:caster 4">
		<visual>
			<origin xyz="0.15578748791753266 -0.04694264940917492 0.2741130091421757" rpy="0 0 0"/>
			<geometry>
				<mesh filename="raw_data/335/part_meshes/13.dae" />
			</geometry>
		</visual>
	</link>


	<link name="14:caster 5">
		<visual>
			<origin xyz="0.2812476877765576 -0.04694264940917492 -0.058887474768614584" rpy="0 0 0"/>
			<geometry>
				<mesh filename="raw_data/335/part_meshes/14.dae" />
			</geometry>
		</visual>
	</link>


	<joint name="0:virtual::1:static" type="fixed">
		<parent link="0:virtual"/>
		<child link="1:static"/>
		<origin xyz="0.0 0.0 0.0" rpy="0 0 0"/>
	</joint>


	<joint name="9:gas lift piece 1::2:seat 1_translation" type="prismatic">
		<parent link="9:gas lift piece 1"/>
		<child link="2:seat 1"/>
		<origin xyz="-0.0006612003276971132 0.2822960168123245 0.006859366466040417" rpy="0 0 0"/>
		<limit lower="-0.060016512870788574" upper="0.060016512870788574" effort="10" velocity="3"/>
		<axis xyz="0.0 1.0 0.0"/>
	</joint>


	<joint name="2:seat 1::3:back 1_translation" type="prismatic">
		<parent link="2:seat 1"/>
		<child link="3:back 1"/>
		<origin xyz="0.0006612018783845874 0.31477901339530945 -0.2205350156855152" rpy="0 0 0"/>
		<limit lower="-0.0011159952878952" upper="0.0468840047121048" effort="10" velocity="3"/>
		<axis xyz="0.0 0.0 -1.0"/>
	</joint>


	<joint name="11:caster 2::4:wheel 1_rotation" type="revolute">
		<parent link="11:caster 2"/>
		<child link="4:wheel 1"/>
		<origin xyz="0.004960097943064068 -0.022231115486822092 -0.018425480577456674" rpy="0 0 0"/>
		<limit lower="-3.141592653589793" upper="3.141592653589793" effort="10" velocity="3"/>
		<axis xyz="-0.9545696653889917 0.0 -0.2979878418982032"/>
	</joint>


	<joint name="10:caster 1::5:wheel 2_rotation" type="revolute">
		<parent link="10:caster 1"/>
		<child link="5:wheel 2"/>
		<origin xyz="0.026123715806681096 -0.021683060243958607 0.0002098484487003116" rpy="0 0 0"/>
		<limit lower="-3.141592653589793" upper="3.141592653589793" effort="10" velocity="3"/>
		<axis xyz="0.0 0.0 1.0"/>
	</joint>


	<joint name="14:caster 5::6:wheel 3_rotation" type="revolute">
		<parent link="14:caster 5"/>
		<child link="6:wheel 3"/>
		<origin xyz="0.007648741187641139 -0.021683064245735295 0.024321660339682805" rpy="0 0 0"/>
		<limit lower="-3.141592653589793" upper="3.141592653589793" effort="10" velocity="3"/>
		<axis xyz="0.9545708595090903 0.0 -0.29798401664531715"/>
	</joint>


	<joint name="13:caster 4::7:wheel 4_rotation" type="revolute">
		<parent link="13:caster 4"/>
		<child link="7:wheel 4"/>
		<origin xyz="-0.022059068158498757 -0.02168307224928867 0.015935928629447926" rpy="0 0 0"/>
		<limit lower="-3.141592653589793" upper="3.141592653589793" effort="10" velocity="3"/>
		<axis xyz="-0.6031621982172745 0.0 -0.7976185571071583"/>
	</joint>


	<joint name="12:caster 3::8:wheel 5_rotation" type="revolute">
		<parent link="12:caster 3"/>
		<child link="8:wheel 5"/>
		<origin xyz="-0.021736988340589097 -0.02168307224928867 -0.016510672287933625" rpy="0 0 0"/>
		<limit lower="-3.141592653589793" upper="3.141592653589793" effort="10" velocity="3"/>
		<axis xyz="0.6031556388174651 0.0 -0.7976235173079439"/>
	</joint>


	<joint name="0:virtual::9:gas lift piece 1_rotation" type="revolute">
		<parent link="0:virtual"/>
		<child link="9:gas lift piece 1"/>
		<origin xyz="-1.5506874742610144e-09 0.1991405040025711 -0.018897852546253202" rpy="0 0 0"/>
		<limit lower="-3.141592653589793" upper="3.141592653589793" effort="10" velocity="3"/>
		<axis xyz="0.0 1.0 0.0"/>
	</joint>


	<joint name="0:virtual::10:caster 1_rotation" type="revolute">
		<parent link="0:virtual"/>
		<child link="10:caster 1"/>
		<origin xyz="-0.017370465453642785 0.04694264940917492 0.2832771436720425" rpy="0 0 0"/>
		<limit lower="-3.141592653589793" upper="3.141592653589793" effort="10" velocity="3"/>
		<axis xyz="0.0 1.0 0.0"/>
	</joint>


	<joint name="0:virtual::11:caster 2_rotation" type="revolute">
		<parent link="0:virtual"/>
		<child link="11:caster 2"/>
		<origin xyz="0.27404881776393314 0.0474907001554966 0.08430500426129597" rpy="0 0 0"/>
		<limit lower="-3.141592653589793" upper="3.141592653589793" effort="10" velocity="3"/>
		<axis xyz="0.0 1.0 0.0"/>
	</joint>


	<joint name="0:virtual::12:caster 3_rotation" type="revolute">
		<parent link="0:virtual"/>
		<child link="12:caster 3"/>
		<origin xyz="0.18542075624881676 0.04694264940917492 -0.25237669248498834" rpy="0 0 0"/>
		<limit lower="-3.141592653589793" upper="3.141592653589793" effort="10" velocity="3"/>
		<axis xyz="0.0 1.0 0.0"/>
	</joint>


	<joint name="0:virtual::13:caster 4_rotation" type="revolute">
		<parent link="0:virtual"/>
		<child link="13:caster 4"/>
		<origin xyz="-0.15578748791753266 0.04694264940917492 -0.2741130091421757" rpy="0 0 0"/>
		<limit lower="-3.141592653589793" upper="3.141592653589793" effort="10" velocity="3"/>
		<axis xyz="0.0 1.0 0.0"/>
	</joint>


	<joint name="0:virtual::14:caster 5_rotation" type="revolute">
		<parent link="0:virtual"/>
		<child link="14:caster 5"/>
		<origin xyz="-0.2812476877765576 0.04694264940917492 0.058887474768614584" rpy="0 0 0"/>
		<limit lower="-3.141592653589793" upper="3.141592653589793" effort="10" velocity="3"/>
		<axis xyz="0.0 1.0 0.0"/>
	</joint>


</robot>