<robot name="391">


	<link name="0:virtual">
		<visual>
			<origin xyz="0.0 0.0 0.0" rpy="0 0 0"/>
			<geometry>
				<cylinder length="0" radius="0"/>
			</geometry>
		</visual>
	</link>


	<link name="1:static">
		<inertial>
			<origin xyz="0.0 0.0 0.0" rpy="0.0 0.0 0.0"/>
			<mass value="1.0"/>
			<inertia ixx="1.0" ixy="0.0" ixz="0.0" iyy="1.0" iyz="0.0" izz="1.0"/>
		</inertial>
		<visual>
			<origin xyz="-0.0 -0.0 -0.0" rpy="0 0 0"/>
			<geometry>
				<mesh filename="../raw_data/391/part_meshes/1.dae" />
			</geometry>
		</visual>
	</link>


	<link name="2:cabinet door 1">
		<inertial>
			<origin xyz="0.0 0.0 0.0" rpy="0.0 0.0 0.0"/>
			<mass value="1.0"/>
			<inertia ixx="1.0" ixy="0.0" ixz="0.0" iyy="1.0" iyz="0.0" izz="1.0"/>
		</inertial>
		<visual>
			<origin xyz="0.013735150152780928 -2.220249891281128 -0.3643404869342153" rpy="0 0 0"/>
			<geometry>
				<mesh filename="../raw_data/391/part_meshes/2.dae" />
			</geometry>
		</visual>
	</link>


	<link name="3:drawer 1">
		<inertial>
			<origin xyz="0.0 0.0 0.0" rpy="0.0 0.0 0.0"/>
			<mass value="1.0"/>
			<inertia ixx="1.0" ixy="0.0" ixz="0.0" iyy="1.0" iyz="0.0" izz="1.0"/>
		</inertial>
		<visual>
			<origin xyz="0.09516427973521974 -0.3334130048751831 0.09530057394762842" rpy="0 0 0"/>
			<geometry>
				<mesh filename="../raw_data/391/part_meshes/3.dae" />
			</geometry>
		</visual>
	</link>


	<link name="4:drawer 2">
		<inertial>
			<origin xyz="0.0 0.0 0.0" rpy="0.0 0.0 0.0"/>
			<mass value="1.0"/>
			<inertia ixx="1.0" ixy="0.0" ixz="0.0" iyy="1.0" iyz="0.0" izz="1.0"/>
		</inertial>
		<visual>
			<origin xyz="0.09516386722553766 -0.17990099638700485 0.09530070400845894" rpy="0 0 0"/>
			<geometry>
				<mesh filename="../raw_data/391/part_meshes/4.dae" />
			</geometry>
		</visual>
	</link>


	<joint name="0:virtual::1:static" type="fixed">
		<parent link="0:virtual"/>
		<child link="1:static"/>
		<origin xyz="0.0 0.0 0.0" rpy="0 0 0"/>
	</joint>


	<joint name="0:virtual::2:cabinet door 1_rotation" type="revolute">
		<parent link="0:virtual"/>
		<child link="2:cabinet door 1"/>
		<origin xyz="-0.013735150152780928 2.220249891281128 0.3643404869342153" rpy="0 0 0"/>
		<limit lower="-1.5550883635269477" upper="0.12566370614359174" effort="10" velocity="3"/>
		<axis xyz="0.0 1.0 0.0"/>
	</joint>


	<joint name="0:virtual::3:drawer 1_translation" type="prismatic">
		<parent link="0:virtual"/>
		<child link="3:drawer 1"/>
		<origin xyz="-0.09516427973521974 0.3334130048751831 -0.09530057394762842" rpy="0 0 0"/>
		<limit lower="-0.0004969672892222" upper="0.333503032710778" effort="10" velocity="3"/>
		<axis xyz="0.7067019293215732 0.0 0.7075114013874025"/>
	</joint>


	<joint name="0:virtual::4:drawer 2_translation" type="prismatic">
		<parent link="0:virtual"/>
		<child link="4:drawer 2"/>
		<origin xyz="-0.09516386722553766 0.17990099638700485 -0.09530070400845894" rpy="0 0 0"/>
		<limit lower="-0.0004969672892222" upper="0.333503032710778" effort="10" velocity="3"/>
		<axis xyz="0.7067019465164578 0.0 0.7075113842121904"/>
	</joint>


</robot>