<robot name="398">


	<link name="0:virtual">
		<visual>
			<origin xyz="0.0 0.0 0.0" rpy="0 0 0"/>
			<geometry>
				<cylinder length="0" radius="0"/>
			</geometry>
		</visual>
	</link>


	<link name="1:cabinet door 1">
		<visual>
			<origin xyz="-0.5995519757270813 -0.48165565729141235 -0.19635900110006332" rpy="0 0 0"/>
			<geometry>
				<mesh filename="../raw_data/398/part_meshes/1.dae" />
			</geometry>
		</visual>
	</link>


	<link name="2:cabinet door 2">
		<visual>
			<origin xyz="0.5995519757270813 -0.48165565729141235 -0.19635900110006332" rpy="0 0 0"/>
			<geometry>
				<mesh filename="../raw_data/398/part_meshes/2.dae" />
			</geometry>
		</visual>
	</link>


	<link name="3:drawer 1">
		<visual>
			<origin xyz="-0.0002610012888908386 -0.7689925134181976 0.002888500690460205" rpy="0 0 0"/>
			<geometry>
				<mesh filename="../raw_data/398/part_meshes/3.dae" />
			</geometry>
		</visual>
	</link>


	<link name="4:drawer 2">
		<visual>
			<origin xyz="-0.0002610012888908386 -0.57362499833107 0.002888500690460205" rpy="0 0 0"/>
			<geometry>
				<mesh filename="../raw_data/398/part_meshes/4.dae" />
			</geometry>
		</visual>
	</link>


	<link name="5:drawer 3">
		<visual>
			<origin xyz="-0.0002610012888908386 -0.3823090046644211 0.002888500690460205" rpy="0 0 0"/>
			<geometry>
				<mesh filename="../raw_data/398/part_meshes/5.dae" />
			</geometry>
		</visual>
	</link>


	<link name="6:drawer 4">
		<visual>
			<origin xyz="-0.0002610012888908386 -0.18896714970469475 0.002888500690460205" rpy="0 0 0"/>
			<geometry>
				<mesh filename="../raw_data/398/part_meshes/6.dae" />
			</geometry>
		</visual>
	</link>


	<joint name="5:drawer 3::1:cabinet door 1_rotation" type="revolute">
		<parent link="5:drawer 3"/>
		<child link="1:cabinet door 1"/>
		<origin xyz="0.5992909744381905 0.09934665262699127 0.19924750179052353" rpy="0 0 0"/>
		<limit lower="0.0" upper="1.460840583919254" effort="10" velocity="3"/>
		<axis xyz="0.0 1.0 0.0"/>
	</joint>


	<joint name="5:drawer 3::2:cabinet door 2_rotation" type="revolute">
		<parent link="5:drawer 3"/>
		<child link="2:cabinet door 2"/>
		<origin xyz="-0.5998129770159721 0.09934665262699127 0.19924750179052353" rpy="0 0 0"/>
		<limit lower="-1.5079644737231006" upper="0.0" effort="10" velocity="3"/>
		<axis xyz="0.0 1.0 0.0"/>
	</joint>


	<joint name="0:virtual::3:drawer 1_translation" type="prismatic">
		<parent link="0:virtual"/>
		<child link="3:drawer 1"/>
		<origin xyz="0.0002610012888908386 0.7689925134181976 -0.002888500690460205" rpy="0 0 0"/>
		<limit lower="-0.0002425062656403" upper="0.35375749373436" effort="10" velocity="3"/>
		<axis xyz="0.0 0.0 1.0"/>
	</joint>


	<joint name="0:virtual::4:drawer 2_translation" type="prismatic">
		<parent link="0:virtual"/>
		<child link="4:drawer 2"/>
		<origin xyz="0.0002610012888908386 0.57362499833107 -0.002888500690460205" rpy="0 0 0"/>
		<limit lower="-0.0002425062656403" upper="0.35375749373436" effort="10" velocity="3"/>
		<axis xyz="0.0 0.0 1.0"/>
	</joint>


	<joint name="0:virtual::5:drawer 3_translation" type="prismatic">
		<parent link="0:virtual"/>
		<child link="5:drawer 3"/>
		<origin xyz="0.0002610012888908386 0.3823090046644211 -0.002888500690460205" rpy="0 0 0"/>
		<limit lower="-0.0002425062656403" upper="0.35375749373436" effort="10" velocity="3"/>
		<axis xyz="0.0 0.0 1.0"/>
	</joint>


	<joint name="5:drawer 3::6:drawer 4_translation" type="prismatic">
		<parent link="5:drawer 3"/>
		<child link="6:drawer 4"/>
		<origin xyz="0.0 -0.19334185495972633 0.0" rpy="0 0 0"/>
		<limit lower="-0.0002425062656403" upper="0.35375749373436" effort="10" velocity="3"/>
		<axis xyz="0.0 0.0 1.0"/>
	</joint>


</robot>