<robot name="428">


	<link name="0:virtual">
		<visual>
			<origin xyz="0.0 0.0 0.0" rpy="0 0 0"/>
			<geometry>
				<cylinder length="0" radius="0"/>
			</geometry>
		</visual>
	</link>


	<link name="1:static">
		<visual>
			<origin xyz="-0.0 -0.0 -0.0" rpy="0 0 0"/>
			<geometry>
				<mesh filename="raw_data/428/part_meshes/1.dae" />
			</geometry>
		</visual>
	</link>


	<link name="2:drawer 1">
		<visual>
			<origin xyz="-0.4523730054497719 -0.24418560042977333 0.005740508437156677" rpy="0 0 0"/>
			<geometry>
				<mesh filename="raw_data/428/part_meshes/2.dae" />
			</geometry>
		</visual>
	</link>


	<link name="3:drawer 2">
		<visual>
			<origin xyz="-0.4523730054497719 -0.4495314955711365 0.005740508437156677" rpy="0 0 0"/>
			<geometry>
				<mesh filename="raw_data/428/part_meshes/3.dae" />
			</geometry>
		</visual>
	</link>


	<link name="4:drawer 3">
		<visual>
			<origin xyz="0.12542998790740967 -0.699999988079071 0.014967501163482666" rpy="0 0 0"/>
			<geometry>
				<mesh filename="raw_data/428/part_meshes/4.dae" />
			</geometry>
		</visual>
	</link>


	<joint name="0:virtual::1:static" type="fixed">
		<parent link="0:virtual"/>
		<child link="1:static"/>
		<origin xyz="0.0 0.0 0.0" rpy="0 0 0"/>
	</joint>


	<joint name="0:virtual::2:drawer 1_translation" type="prismatic">
		<parent link="0:virtual"/>
		<child link="2:drawer 1"/>
		<origin xyz="0.4523730054497719 0.24418560042977333 -0.005740508437156677" rpy="0 0 0"/>
		<limit lower="0.0" upper="0.493121479034424" effort="10" velocity="3"/>
		<axis xyz="0.0 0.0 1.0"/>
	</joint>


	<joint name="0:virtual::3:drawer 2_translation" type="prismatic">
		<parent link="0:virtual"/>
		<child link="3:drawer 2"/>
		<origin xyz="0.4523730054497719 0.4495314955711365 -0.005740508437156677" rpy="0 0 0"/>
		<limit lower="0.0" upper="0.493121479034424" effort="10" velocity="3"/>
		<axis xyz="0.0 0.0 1.0"/>
	</joint>


	<joint name="0:virtual::4:drawer 3_translation" type="prismatic">
		<parent link="0:virtual"/>
		<child link="4:drawer 3"/>
		<origin xyz="-0.12542998790740967 0.699999988079071 -0.014967501163482666" rpy="0 0 0"/>
		<limit lower="-0.0002924630641937" upper="0.498707536935806" effort="10" velocity="3"/>
		<axis xyz="0.0 0.0 1.0"/>
	</joint>


</robot>