<robot name="429">


	<link name="0:virtual">
		<visual>
			<origin xyz="0.0 0.0 0.0" rpy="0 0 0"/>
			<geometry>
				<cylinder length="0" radius="0"/>
			</geometry>
		</visual>
	</link>


	<link name="1:static">
		<inertial>
			<origin xyz="0.0 0.0 0.0" rpy="0.0 0.0 0.0"/>
			<mass value="1.0"/>
			<inertia ixx="1.0" ixy="0.0" ixz="0.0" iyy="1.0" iyz="0.0" izz="1.0"/>
		</inertial>
		<visual>
			<origin xyz="-0.0 -0.0 -0.0" rpy="0 0 0"/>
			<geometry>
				<mesh filename="../raw_data/429/part_meshes/1.dae" />
			</geometry>
		</visual>
	</link>


	<link name="2:stand 1">
		<inertial>
			<origin xyz="0.0 0.0 0.0" rpy="0.0 0.0 0.0"/>
			<mass value="1.0"/>
			<inertia ixx="1.0" ixy="0.0" ixz="0.0" iyy="1.0" iyz="0.0" izz="1.0"/>
		</inertial>
		<visual>
			<origin xyz="1.7978956431269344e-11 -0.2750075049698353 -0.002747000192239779" rpy="0 0 0"/>
			<geometry>
				<mesh filename="../raw_data/429/part_meshes/2.dae" />
			</geometry>
		</visual>
	</link>


	<link name="3:seat 1">
		<inertial>
			<origin xyz="0.0 0.0 0.0" rpy="0.0 0.0 0.0"/>
			<mass value="1.0"/>
			<inertia ixx="1.0" ixy="0.0" ixz="0.0" iyy="1.0" iyz="0.0" izz="1.0"/>
		</inertial>
		<visual>
			<origin xyz="-0.0 -0.39532849937677383 -0.006563000380992889" rpy="0 0 0"/>
			<geometry>
				<mesh filename="../raw_data/429/part_meshes/3.dae" />
			</geometry>
		</visual>
	</link>


	<joint name="0:virtual::1:static" type="fixed">
		<parent link="0:virtual"/>
		<child link="1:static"/>
		<origin xyz="0.0 0.0 0.0" rpy="0 0 0"/>
	</joint>


	<joint name="0:virtual::2:stand 1_rotation" type="revolute">
		<parent link="0:virtual"/>
		<child link="2:stand 1"/>
		<origin xyz="-1.7978956431269344e-11 0.2750075049698353 0.002747000192239779" rpy="0 0 0"/>
		<limit lower="-3.141592653589793" upper="3.141592653589793" effort="10" velocity="3"/>
		<axis xyz="0.0 1.0 0.0"/>
	</joint>


	<joint name="2:stand 1::3:seat 1_translation" type="prismatic">
		<parent link="2:stand 1"/>
		<child link="3:seat 1"/>
		<origin xyz="1.7978956431269344e-11 0.12032099440693855 0.0038160001887531103" rpy="0 0 0"/>
		<limit lower="-0.0276765238344669" upper="0.0643234761655331" effort="10" velocity="3"/>
		<axis xyz="0.0 1.0 0.0"/>
	</joint>


</robot>