<robot name="430">


	<link name="0:virtual">
		<visual>
			<origin xyz="0.0 0.0 0.0" rpy="0 0 0"/>
			<geometry>
				<cylinder length="0" radius="0"/>
			</geometry>
		</visual>
	</link>


	<link name="1:static">
		<visual>
			<origin xyz="-0.0 -0.0 -0.0" rpy="0 0 0"/>
			<geometry>
				<mesh filename="../raw_data/430/part_meshes/1.dae" />
			</geometry>
		</visual>
	</link>


	<link name="2:drawer 1">
		<visual>
			<origin xyz="-0.5359509885311127 -0.4940279871225357 -0.06069400906562805" rpy="0 0 0"/>
			<geometry>
				<mesh filename="../raw_data/430/part_meshes/2.dae" />
			</geometry>
		</visual>
	</link>


	<link name="3:drawer 2">
		<visual>
			<origin xyz="-0.5359509885311127 -0.39287999272346497 -0.06069400906562805" rpy="0 0 0"/>
			<geometry>
				<mesh filename="../raw_data/430/part_meshes/3.dae" />
			</geometry>
		</visual>
	</link>


	<link name="4:drawer 3">
		<visual>
			<origin xyz="-0.5359509885311127 -0.19659210555255413 -0.06069400906562805" rpy="0 0 0"/>
			<geometry>
				<mesh filename="../raw_data/430/part_meshes/4.dae" />
			</geometry>
		</visual>
	</link>


	<joint name="0:virtual::1:static" type="fixed">
		<parent link="0:virtual"/>
		<child link="1:static"/>
		<origin xyz="0.0 0.0 0.0" rpy="0 0 0"/>
	</joint>


	<joint name="0:virtual::2:drawer 1_translation" type="prismatic">
		<parent link="0:virtual"/>
		<child link="2:drawer 1"/>
		<origin xyz="0.5359509885311127 0.4940279871225357 0.06069400906562805" rpy="0 0 0"/>
		<limit lower="-6.4000248909e-05" upper="0.611935999751091" effort="10" velocity="3"/>
		<axis xyz="0.0 0.0 1.0"/>
	</joint>


	<joint name="0:virtual::3:drawer 2_translation" type="prismatic">
		<parent link="0:virtual"/>
		<child link="3:drawer 2"/>
		<origin xyz="0.5359509885311127 0.39287999272346497 0.06069400906562805" rpy="0 0 0"/>
		<limit lower="-6.4000248909e-05" upper="0.611935999751091" effort="10" velocity="3"/>
		<axis xyz="0.0 0.0 1.0"/>
	</joint>


	<joint name="0:virtual::4:drawer 3_translation" type="prismatic">
		<parent link="0:virtual"/>
		<child link="4:drawer 3"/>
		<origin xyz="0.5359509885311127 0.19659210555255413 0.06069400906562805" rpy="0 0 0"/>
		<limit lower="-6.4000248909e-05" upper="0.611935999751091" effort="10" velocity="3"/>
		<axis xyz="0.0 0.0 1.0"/>
	</joint>


</robot>