<robot name="447">


	<link name="0:virtual">
		<visual>
			<origin xyz="0.0 0.0 0.0" rpy="0 0 0"/>
			<geometry>
				<cylinder length="0" radius="0"/>
			</geometry>
		</visual>
	</link>


	<link name="1:static">
		<visual>
			<origin xyz="-0.0 -0.0 -0.0" rpy="0 0 0"/>
			<geometry>
				<mesh filename="../raw_data/447/part_meshes/1.dae" />
			</geometry>
		</visual>
	</link>


	<link name="2:cabinet door 1">
		<visual>
			<origin xyz="1.0000000000000038 -0.40500498563051224 -0.20861250907182693" rpy="0 0 0"/>
			<geometry>
				<mesh filename="../raw_data/447/part_meshes/2.dae" />
			</geometry>
		</visual>
	</link>


	<link name="3:faucet handle 1">
		<visual>
			<origin xyz="0.40092484551001406 -0.9062594771385193 0.22027550728729045" rpy="0 0 0"/>
			<geometry>
				<mesh filename="../raw_data/447/part_meshes/3.dae" />
			</geometry>
		</visual>
	</link>


	<link name="4:faucet spout 1">
		<visual>
			<origin xyz="0.39934399390220643 -0.8672209749221802 0.22236199676990512" rpy="0 0 0"/>
			<geometry>
				<mesh filename="../raw_data/447/part_meshes/4.dae" />
			</geometry>
		</visual>
	</link>


	<joint name="0:virtual::1:static" type="fixed">
		<parent link="0:virtual"/>
		<child link="1:static"/>
		<origin xyz="0.0 0.0 0.0" rpy="0 0 0"/>
	</joint>


	<joint name="0:virtual::2:cabinet door 1_rotation" type="revolute">
		<parent link="0:virtual"/>
		<child link="2:cabinet door 1"/>
		<origin xyz="-1.0000000000000038 0.40500498563051224 0.20861250907182693" rpy="0 0 0"/>
		<limit lower="-1.8692476288859268" upper="0.0" effort="10" velocity="3"/>
		<axis xyz="0.0 1.0 0.0"/>
	</joint>


	<joint name="0:virtual::3:faucet handle 1_rotation" type="revolute">
		<parent link="0:virtual"/>
		<child link="3:faucet handle 1"/>
		<origin xyz="-0.40092484551001406 0.9062594771385193 -0.22027550728729045" rpy="0 0 0"/>
		<limit lower="-0.6597344572538565" upper="0.26703537555513246" effort="10" velocity="3"/>
		<axis xyz="0.0 1.0 0.0"/>
	</joint>


	<joint name="0:virtual::4:faucet spout 1_rotation" type="revolute">
		<parent link="0:virtual"/>
		<child link="4:faucet spout 1"/>
		<origin xyz="-0.39934399390220643 0.8672209749221802 -0.22236199676990512" rpy="0 0 0"/>
		<limit lower="-0.2827433388230814" upper="0.37699111843077515" effort="10" velocity="3"/>
		<axis xyz="0.0 1.0 0.0"/>
	</joint>


</robot>