<robot name="455">


	<link name="0:virtual">
		<visual>
			<origin xyz="0.0 0.0 0.0" rpy="0 0 0"/>
			<geometry>
				<cylinder length="0" radius="0"/>
			</geometry>
		</visual>
	</link>


	<link name="1:static">
		<visual>
			<origin xyz="-0.0 -0.0 -0.0" rpy="0 0 0"/>
			<geometry>
				<mesh filename="raw_data/455/part_meshes/1.dae" />
			</geometry>
		</visual>
	</link>


	<link name="2:drawer 1">
		<visual>
			<origin xyz="-0.0 -0.7074999809265137 -0.00781773030757904" rpy="0 0 0"/>
			<geometry>
				<mesh filename="raw_data/455/part_meshes/2.dae" />
			</geometry>
		</visual>
	</link>


	<link name="3:drawer cabinet 1">
		<visual>
			<origin xyz="-0.43076652467604953 -0.7074999809265137 -0.00031844160197575097" rpy="0 0 0"/>
			<geometry>
				<mesh filename="raw_data/455/part_meshes/3.dae" />
			</geometry>
		</visual>
	</link>


	<link name="4:drawer cabinet 3">
		<visual>
			<origin xyz="0.4311414957046509 -0.7074999809265137 -0.0" rpy="0 0 0"/>
			<geometry>
				<mesh filename="raw_data/455/part_meshes/4.dae" />
			</geometry>
		</visual>
	</link>


	<joint name="0:virtual::1:static" type="fixed">
		<parent link="0:virtual"/>
		<child link="1:static"/>
		<origin xyz="0.0 0.0 0.0" rpy="0 0 0"/>
	</joint>


	<joint name="0:virtual::2:drawer 1_translation" type="prismatic">
		<parent link="0:virtual"/>
		<child link="2:drawer 1"/>
		<origin xyz="0.0 0.7074999809265137 0.00781773030757904" rpy="0 0 0"/>
		<limit lower="-0.0004029939174652" upper="0.507597006082535" effort="10" velocity="3"/>
		<axis xyz="0.0 0.0 1.0"/>
	</joint>


	<joint name="0:virtual::3:drawer cabinet 1_translation" type="prismatic">
		<parent link="0:virtual"/>
		<child link="3:drawer cabinet 1"/>
		<origin xyz="0.43076652467604953 0.7074999809265137 0.00031844160197575097" rpy="0 0 0"/>
		<limit lower="-0.0004029939174652" upper="0.535597006082535" effort="10" velocity="3"/>
		<axis xyz="-0.0029629879308582063 0.0 0.9999956103416262"/>
	</joint>


	<joint name="0:virtual::4:drawer cabinet 3_translation" type="prismatic">
		<parent link="0:virtual"/>
		<child link="4:drawer cabinet 3"/>
		<origin xyz="-0.4311414957046509 0.7074999809265137 0.0" rpy="0 0 0"/>
		<limit lower="-0.0004029939174652" upper="0.535597006082535" effort="10" velocity="3"/>
		<axis xyz="0.0 0.0 1.0"/>
	</joint>


</robot>