<robot name="516">


	<link name="0:virtual">
		<visual>
			<origin xyz="0.0 0.0 0.0" rpy="0 0 0"/>
			<geometry>
				<cylinder length="0" radius="0"/>
			</geometry>
		</visual>
	</link>


	<link name="1:static">
		<visual>
			<origin xyz="-0.0 -0.0 -0.0" rpy="0 0 0"/>
			<geometry>
				<mesh filename="../raw_data/516/part_meshes/1.dae" />
			</geometry>
		</visual>
	</link>


	<link name="2:armrest 1">
		<visual>
			<origin xyz="0.2751470059156418 -0.6934645175933838 0.007461998611688614" rpy="0 0 0"/>
			<geometry>
				<mesh filename="../raw_data/516/part_meshes/2.dae" />
			</geometry>
		</visual>
	</link>


	<link name="3:armrest 2">
		<visual>
			<origin xyz="-0.2751470059156418 -0.6934645175933838 0.007461998611688614" rpy="0 0 0"/>
			<geometry>
				<mesh filename="../raw_data/516/part_meshes/3.dae" />
			</geometry>
		</visual>
	</link>


	<link name="4:backrest 1">
		<visual>
			<origin xyz="-0.23217172102628017 -0.4293150041103362 0.18078520651190394" rpy="0 0 0"/>
			<geometry>
				<mesh filename="../raw_data/516/part_meshes/4.dae" />
			</geometry>
		</visual>
	</link>


	<link name="5:wheel 1">
		<visual>
			<origin xyz="2.8500333428382874e-05 -0.025014499100507237 -0.31538400053977966" rpy="0 0 0"/>
			<geometry>
				<mesh filename="../raw_data/516/part_meshes/5.dae" />
			</geometry>
		</visual>
	</link>


	<link name="6:wheel 2">
		<visual>
			<origin xyz="-0.32976644030748237 -0.025014499100507237 -0.07881467496090609" rpy="0 0 0"/>
			<geometry>
				<mesh filename="../raw_data/516/part_meshes/6.dae" />
			</geometry>
		</visual>
	</link>


	<link name="7:wheel 3">
		<visual>
			<origin xyz="0.32978458130077376 -0.025014499100507237 -0.07876124182861405" rpy="0 0 0"/>
			<geometry>
				<mesh filename="../raw_data/516/part_meshes/7.dae" />
			</geometry>
		</visual>
	</link>


	<link name="8:wheel 4">
		<visual>
			<origin xyz="-0.203835192202454 -0.025014499100507237 0.30887009292989054" rpy="0 0 0"/>
			<geometry>
				<mesh filename="../raw_data/516/part_meshes/8.dae" />
			</geometry>
		</visual>
	</link>


	<link name="9:wheel 5">
		<visual>
			<origin xyz="0.20378965217786538 -0.025014499100507237 0.3089031815654103" rpy="0 0 0"/>
			<geometry>
				<mesh filename="../raw_data/516/part_meshes/9.dae" />
			</geometry>
		</visual>
	</link>


	<link name="10:seat 1">
		<visual>
			<origin xyz="-0.0 -0.4195210039615631 -0.08163700252771378" rpy="0 0 0"/>
			<geometry>
				<mesh filename="../raw_data/516/part_meshes/10.dae" />
			</geometry>
		</visual>
	</link>


	<link name="11:arm 1">
		<visual>
			<origin xyz="-0.2601584851737282 -0.6207724809646606 0.11514195753724817" rpy="0 0 0"/>
			<geometry>
				<mesh filename="../raw_data/516/part_meshes/11.dae" />
			</geometry>
		</visual>
	</link>


	<link name="12:caster 1">
		<visual>
			<origin xyz="2.800021320581436e-05 -0.03805199917405844 -0.3013509912490845" rpy="0 0 0"/>
			<geometry>
				<mesh filename="../raw_data/516/part_meshes/12.dae" />
			</geometry>
		</visual>
	</link>


	<link name="13:caster 2">
		<visual>
			<origin xyz="-0.30868655915566734 -0.03805199917405844 -0.07196498073319178" rpy="0 0 0"/>
			<geometry>
				<mesh filename="../raw_data/516/part_meshes/13.dae" />
			</geometry>
		</visual>
	</link>


	<link name="14:caster 3">
		<visual>
			<origin xyz="-0.19712791284663858 -0.03805199917405844 0.2996388844519469" rpy="0 0 0"/>
			<geometry>
				<mesh filename="../raw_data/516/part_meshes/14.dae" />
			</geometry>
		</visual>
	</link>


	<link name="15:caster 4">
		<visual>
			<origin xyz="0.1931123082611337 -0.03805199917405844 0.29420678789379795" rpy="0 0 0"/>
			<geometry>
				<mesh filename="../raw_data/516/part_meshes/15.dae" />
			</geometry>
		</visual>
	</link>


	<link name="16:caster 5">
		<visual>
			<origin xyz="0.30680168114605333 -0.03805199917405844 -0.07129380838184372" rpy="0 0 0"/>
			<geometry>
				<mesh filename="../raw_data/516/part_meshes/16.dae" />
			</geometry>
		</visual>
	</link>


	<link name="17:arm 2">
		<visual>
			<origin xyz="0.26015813139043586 -0.6207724809646606 0.11514281002613701" rpy="0 0 0"/>
			<geometry>
				<mesh filename="../raw_data/516/part_meshes/17.dae" />
			</geometry>
		</visual>
	</link>


	<link name="18:gas lift piece 2">
		<visual>
			<origin xyz="-0.0 -0.1816760003566742 0.02836250001564622" rpy="0 0 0"/>
			<geometry>
				<mesh filename="../raw_data/516/part_meshes/18.dae" />
			</geometry>
		</visual>
	</link>


	<joint name="0:virtual::1:static" type="fixed">
		<parent link="0:virtual"/>
		<child link="1:static"/>
		<origin xyz="0.0 0.0 0.0" rpy="0 0 0"/>
	</joint>


	<joint name="17:arm 2::2:armrest 1_translation" type="prismatic">
		<parent link="17:arm 2"/>
		<child link="2:armrest 1"/>
		<origin xyz="-0.01498887452520592 0.07269203662872314 0.1076808114144484" rpy="0 0 0"/>
		<limit lower="-0.0701422626250384" upper="0.0701422626250384" effort="10" velocity="3"/>
		<axis xyz="0.0 0.0 1.0"/>
	</joint>


	<joint name="11:arm 1::3:armrest 2_translation" type="prismatic">
		<parent link="11:arm 1"/>
		<child link="3:armrest 2"/>
		<origin xyz="0.014988520741913591 0.07269203662872314 0.10767995892555955" rpy="0 0 0"/>
		<limit lower="-0.0701422626250384" upper="0.0701422626250384" effort="10" velocity="3"/>
		<axis xyz="0.0 0.0 1.0"/>
	</joint>


	<joint name="18:gas lift piece 2::4:backrest 1_rotation" type="revolute">
		<parent link="18:gas lift piece 2"/>
		<child link="4:backrest 1"/>
		<origin xyz="0.23217172102628017 0.247639003753662 -0.15242270649625772" rpy="0 0 0"/>
		<limit lower="-0.18849555921538758" upper="0.07853981633974483" effort="10" velocity="3"/>
		<axis xyz="0.9993551401656505 0.0 0.035906877119751233"/>
	</joint>


	<joint name="12:caster 1::5:wheel 1_rotation" type="revolute">
		<parent link="12:caster 1"/>
		<child link="5:wheel 1"/>
		<origin xyz="-5.00120222568512e-07 -0.0130375000735512 0.014033009290695175" rpy="0 0 0"/>
		<limit lower="-3.141592653589793" upper="3.141592653589793" effort="10" velocity="3"/>
		<axis xyz="-1.0 0.0 0.0"/>
	</joint>


	<joint name="13:caster 2::6:wheel 2_rotation" type="revolute">
		<parent link="13:caster 2"/>
		<child link="6:wheel 2"/>
		<origin xyz="0.021079881151815028 -0.0130375000735512 0.006849694227714309" rpy="0 0 0"/>
		<limit lower="-3.141592653589793" upper="3.141592653589793" effort="10" velocity="3"/>
		<axis xyz="0.30901756545265857 0.0 -0.9510563307405676"/>
	</joint>


	<joint name="16:caster 5::7:wheel 3_rotation" type="revolute">
		<parent link="16:caster 5"/>
		<child link="7:wheel 3"/>
		<origin xyz="-0.02298290015472043 -0.0130375000735512 0.007467433446770325" rpy="0 0 0"/>
		<limit lower="-3.141592653589793" upper="3.141592653589793" effort="10" velocity="3"/>
		<axis xyz="0.30901756545265857 0.0 0.9510563307405676"/>
	</joint>


	<joint name="14:caster 3::8:wheel 4_rotation" type="revolute">
		<parent link="14:caster 3"/>
		<child link="8:wheel 4"/>
		<origin xyz="0.006707279355815415 -0.0130375000735512 -0.00923120847794362" rpy="0 0 0"/>
		<limit lower="-3.141592653589793" upper="3.141592653589793" effort="10" velocity="3"/>
		<axis xyz="-0.809017690817185 0.0 -0.5877842937207747"/>
	</joint>


	<joint name="15:caster 4::9:wheel 5_rotation" type="revolute">
		<parent link="15:caster 4"/>
		<child link="9:wheel 5"/>
		<origin xyz="-0.010677343916731669 -0.0130375000735512 -0.014696393671612351" rpy="0 0 0"/>
		<limit lower="-3.141592653589793" upper="3.141592653589793" effort="10" velocity="3"/>
		<axis xyz="0.8090185846641318 0.0 -0.5877830634409646"/>
	</joint>


	<joint name="18:gas lift piece 2::10:seat 1_rotation" type="revolute">
		<parent link="18:gas lift piece 2"/>
		<child link="10:seat 1"/>
		<origin xyz="0.0 0.23784500360488892 0.10999950254336" rpy="0 0 0"/>
		<limit lower="-0.23561944901923448" upper="0.15707963267948966" effort="10" velocity="3"/>
		<axis xyz="-1.0 0.0 0.0"/>
	</joint>


	<joint name="18:gas lift piece 2::11:arm 1_translation" type="prismatic">
		<parent link="18:gas lift piece 2"/>
		<child link="11:arm 1"/>
		<origin xyz="0.2601584851737282 0.43909648060798645 -0.08677945752160195" rpy="0 0 0"/>
		<limit lower="-0.17547250688076" upper="0.0355274931192398" effort="10" velocity="3"/>
		<axis xyz="0.0 1.0 0.0"/>
	</joint>


	<joint name="0:virtual::12:caster 1_rotation" type="revolute">
		<parent link="0:virtual"/>
		<child link="12:caster 1"/>
		<origin xyz="-2.800021320581436e-05 0.03805199917405844 0.3013509912490845" rpy="0 0 0"/>
		<limit lower="-3.141592653589793" upper="3.141592653589793" effort="10" velocity="3"/>
		<axis xyz="0.0 1.0 0.0"/>
	</joint>


	<joint name="0:virtual::13:caster 2_rotation" type="revolute">
		<parent link="0:virtual"/>
		<child link="13:caster 2"/>
		<origin xyz="0.30868655915566734 0.03805199917405844 0.07196498073319178" rpy="0 0 0"/>
		<limit lower="-3.141592653589793" upper="3.141592653589793" effort="10" velocity="3"/>
		<axis xyz="0.0 1.0 0.0"/>
	</joint>


	<joint name="0:virtual::14:caster 3_rotation" type="revolute">
		<parent link="0:virtual"/>
		<child link="14:caster 3"/>
		<origin xyz="0.19712791284663858 0.03805199917405844 -0.2996388844519469" rpy="0 0 0"/>
		<limit lower="-3.141592653589793" upper="3.141592653589793" effort="10" velocity="3"/>
		<axis xyz="0.0 1.0 0.0"/>
	</joint>


	<joint name="0:virtual::15:caster 4_rotation" type="revolute">
		<parent link="0:virtual"/>
		<child link="15:caster 4"/>
		<origin xyz="-0.1931123082611337 0.03805199917405844 -0.29420678789379795" rpy="0 0 0"/>
		<limit lower="-3.141592653589793" upper="3.141592653589793" effort="10" velocity="3"/>
		<axis xyz="0.0 1.0 0.0"/>
	</joint>


	<joint name="0:virtual::16:caster 5_rotation" type="revolute">
		<parent link="0:virtual"/>
		<child link="16:caster 5"/>
		<origin xyz="-0.30680168114605333 0.03805199917405844 0.07129380838184372" rpy="0 0 0"/>
		<limit lower="-3.141592653589793" upper="3.141592653589793" effort="10" velocity="3"/>
		<axis xyz="0.0 1.0 0.0"/>
	</joint>


	<joint name="18:gas lift piece 2::17:arm 2_translation" type="prismatic">
		<parent link="18:gas lift piece 2"/>
		<child link="17:arm 2"/>
		<origin xyz="-0.26015813139043586 0.43909648060798645 -0.08678031001049079" rpy="0 0 0"/>
		<limit lower="-0.17547250688076" upper="0.0355274931192398" effort="10" velocity="3"/>
		<axis xyz="0.0 1.0 0.0"/>
	</joint>


	<joint name="0:virtual::18:gas lift piece 2_rotation" type="revolute">
		<parent link="0:virtual"/>
		<child link="18:gas lift piece 2"/>
		<origin xyz="0.0 0.1816760003566742 -0.02836250001564622" rpy="0 0 0"/>
		<limit lower="-3.141592653589793" upper="3.141592653589793" effort="10" velocity="3"/>
		<axis xyz="0.0 1.0 0.0"/>
	</joint>


</robot>