<robot name="577">


	<link name="0:virtual">
		<visual>
			<origin xyz="0.0 0.0 0.0" rpy="0 0 0"/>
			<geometry>
				<cylinder length="0" radius="0"/>
			</geometry>
		</visual>
	</link>


	<link name="1:static">
		<visual>
			<origin xyz="-0.0 -0.0 -0.0" rpy="0 0 0"/>
			<geometry>
				<mesh filename="../raw_data/577/part_meshes/1.dae" />
			</geometry>
		</visual>
	</link>


	<link name="2:cabinet door 1">
		<visual>
			<origin xyz="0.7549759787793395 -0.9019440038204193 -0.08256950185856853" rpy="0 0 0"/>
			<geometry>
				<mesh filename="../raw_data/577/part_meshes/2.dae" />
			</geometry>
		</visual>
	</link>


	<link name="3:drawer 1">
		<visual>
			<origin xyz="0.19366049766540527 -0.16733034793287516 -0.025034748017787933" rpy="0 0 0"/>
			<geometry>
				<mesh filename="../raw_data/577/part_meshes/3.dae" />
			</geometry>
		</visual>
	</link>


	<joint name="0:virtual::1:static" type="fixed">
		<parent link="0:virtual"/>
		<child link="1:static"/>
		<origin xyz="0.0 0.0 0.0" rpy="0 0 0"/>
	</joint>


	<joint name="0:virtual::2:cabinet door 1_rotation" type="revolute">
		<parent link="0:virtual"/>
		<child link="2:cabinet door 1"/>
		<origin xyz="-0.7549759787793395 0.9019440038204193 0.08256950185856853" rpy="0 0 0"/>
		<limit lower="-2.0263272615654166" upper="-0.23561944901923448" effort="10" velocity="3"/>
		<axis xyz="0.0 1.0 0.0"/>
	</joint>


	<joint name="0:virtual::3:drawer 1_translation" type="prismatic">
		<parent link="0:virtual"/>
		<child link="3:drawer 1"/>
		<origin xyz="-0.19366049766540527 0.16733034793287516 0.025034748017787933" rpy="0 0 0"/>
		<limit lower="-0.0404849998354912" upper="0.582515000164509" effort="10" velocity="3"/>
		<axis xyz="0.0 0.0 1.0"/>
	</joint>


</robot>