<robot name="615">


	<link name="0:virtual">
		<visual>
			<origin xyz="0.0 0.0 0.0" rpy="0 0 0"/>
			<geometry>
				<cylinder length="0" radius="0"/>
			</geometry>
		</visual>
	</link>


	<link name="1:static">
		<visual>
			<origin xyz="-0.0 -0.0 -0.0" rpy="0 0 0"/>
			<geometry>
				<mesh filename="../raw_data/615/part_meshes/1.dae" />
			</geometry>
		</visual>
	</link>


	<link name="2:cabinet door 1">
		<visual>
			<origin xyz="0.6800000071525574 -0.3850002149119973 -0.22173750400543213" rpy="0 0 0"/>
			<geometry>
				<mesh filename="../raw_data/615/part_meshes/2.dae" />
			</geometry>
		</visual>
	</link>


	<link name="3:cabinet door 2">
		<visual>
			<origin xyz="-0.6826670018434524 -0.3850002149119973 -0.21347500383853912" rpy="0 0 0"/>
			<geometry>
				<mesh filename="../raw_data/615/part_meshes/3.dae" />
			</geometry>
		</visual>
	</link>


	<link name="4:drawer 2">
		<visual>
			<origin xyz="-0.0 -0.12883399799466133 -0.0030025020241737366" rpy="0 0 0"/>
			<geometry>
				<mesh filename="../raw_data/615/part_meshes/4.dae" />
			</geometry>
		</visual>
	</link>


	<link name="5:drawer 3">
		<visual>
			<origin xyz="-0.0 -0.334196500480175 -0.0030025020241737366" rpy="0 0 0"/>
			<geometry>
				<mesh filename="../raw_data/615/part_meshes/5.dae" />
			</geometry>
		</visual>
	</link>


	<link name="6:drawer 4">
		<visual>
			<origin xyz="-0.0 -0.5390769988298416 -0.0030025020241737366" rpy="0 0 0"/>
			<geometry>
				<mesh filename="../raw_data/615/part_meshes/6.dae" />
			</geometry>
		</visual>
	</link>


	<joint name="0:virtual::1:static" type="fixed">
		<parent link="0:virtual"/>
		<child link="1:static"/>
		<origin xyz="0.0 0.0 0.0" rpy="0 0 0"/>
	</joint>


	<joint name="0:virtual::2:cabinet door 1_rotation" type="revolute">
		<parent link="0:virtual"/>
		<child link="2:cabinet door 1"/>
		<origin xyz="-0.6800000071525574 0.3850002149119973 0.22173750400543213" rpy="0 0 0"/>
		<limit lower="-1.9792033717615696" upper="0.0" effort="10" velocity="3"/>
		<axis xyz="0.0 1.0 0.0"/>
	</joint>


	<joint name="0:virtual::3:cabinet door 2_rotation" type="revolute">
		<parent link="0:virtual"/>
		<child link="3:cabinet door 2"/>
		<origin xyz="0.6826670018434524 0.3850002149119973 0.21347500383853912" rpy="0 0 0"/>
		<limit lower="0.0" upper="2.1362830044410597" effort="10" velocity="3"/>
		<axis xyz="0.0 1.0 0.0"/>
	</joint>


	<joint name="0:virtual::4:drawer 2_translation" type="prismatic">
		<parent link="0:virtual"/>
		<child link="4:drawer 2"/>
		<origin xyz="0.0 0.12883399799466133 0.0030025020241737366" rpy="0 0 0"/>
		<limit lower="0.0" upper="0.364316996634007" effort="10" velocity="3"/>
		<axis xyz="0.0 0.0 1.0"/>
	</joint>


	<joint name="0:virtual::5:drawer 3_translation" type="prismatic">
		<parent link="0:virtual"/>
		<child link="5:drawer 3"/>
		<origin xyz="0.0 0.334196500480175 0.0030025020241737366" rpy="0 0 0"/>
		<limit lower="0.0" upper="0.364316996634007" effort="10" velocity="3"/>
		<axis xyz="0.0 0.0 1.0"/>
	</joint>


	<joint name="0:virtual::6:drawer 4_translation" type="prismatic">
		<parent link="0:virtual"/>
		<child link="6:drawer 4"/>
		<origin xyz="0.0 0.5390769988298416 0.0030025020241737366" rpy="0 0 0"/>
		<limit lower="0.0" upper="0.364316996634007" effort="10" velocity="3"/>
		<axis xyz="0.0 0.0 1.0"/>
	</joint>


</robot>