<robot name="640">


	<link name="0:virtual">
		<visual>
			<origin xyz="0.0 0.0 0.0" rpy="0 0 0"/>
			<geometry>
				<cylinder length="0" radius="0"/>
			</geometry>
		</visual>
	</link>


	<link name="1:static">
		<visual>
			<origin xyz="-0.0 -0.0 -0.0" rpy="0 0 0"/>
			<geometry>
				<mesh filename="../raw_data/640/part_meshes/1.dae" />
			</geometry>
		</visual>
	</link>


	<link name="2:lid panel 1">
		<visual>
			<origin xyz="0.245004846714437 -0.9441674947738647 -0.00013649463653564453" rpy="0 0 0"/>
			<geometry>
				<mesh filename="../raw_data/640/part_meshes/2.dae" />
			</geometry>
		</visual>
	</link>


	<link name="3:lid panel 2">
		<visual>
			<origin xyz="-0.2378335613757372 -0.9302780032157898 -0.0001359879970550537" rpy="0 0 0"/>
			<geometry>
				<mesh filename="../raw_data/640/part_meshes/3.dae" />
			</geometry>
		</visual>
	</link>


	<joint name="0:virtual::1:static" type="fixed">
		<parent link="0:virtual"/>
		<child link="1:static"/>
		<origin xyz="0.0 0.0 0.0" rpy="0 0 0"/>
	</joint>


	<joint name="0:virtual::2:lid panel 1_translation" type="prismatic">
		<parent link="0:virtual"/>
		<child link="2:lid panel 1"/>
		<origin xyz="-0.245004846714437 0.9441674947738647 0.00013649463653564453" rpy="0 0 0"/>
		<limit lower="-0.5349349975585938" upper="0.5349349975585938" effort="10" velocity="3"/>
		<axis xyz="-1.0 0.0 0.0"/>
	</joint>


	<joint name="0:virtual::3:lid panel 2_translation" type="prismatic">
		<parent link="0:virtual"/>
		<child link="3:lid panel 2"/>
		<origin xyz="0.2378335613757372 0.9302780032157898 0.0001359879970550537" rpy="0 0 0"/>
		<limit lower="-0.5349349975585938" upper="0.5349349975585938" effort="10" velocity="3"/>
		<axis xyz="-1.0 0.0 0.0"/>
	</joint>


</robot>