<robot name="677">


	<link name="0:virtual">
		<visual>
			<origin xyz="0.0 0.0 0.0" rpy="0 0 0"/>
			<geometry>
				<cylinder length="0" radius="0"/>
			</geometry>
		</visual>
	</link>


	<link name="1:static">
		<inertial>
			<origin xyz="0.0 0.0 0.0" rpy="0.0 0.0 0.0"/>
			<mass value="1.0"/>
			<inertia ixx="1.0" ixy="0.0" ixz="0.0" iyy="1.0" iyz="0.0" izz="1.0"/>
		</inertial>
		<visual>
			<origin xyz="-0.0 -0.0 -0.0" rpy="0 0 0"/>
			<geometry>
				<mesh filename="../raw_data/677/part_meshes/1.dae" />
			</geometry>
		</visual>
	</link>


	<link name="2:wheel 1">
		<inertial>
			<origin xyz="0.0 0.0 0.0" rpy="0.0 0.0 0.0"/>
			<mass value="1.0"/>
			<inertia ixx="1.0" ixy="0.0" ixz="0.0" iyy="1.0" iyz="0.0" izz="1.0"/>
		</inertial>
		<visual>
			<origin xyz="-0.027663150588627266 -0.028591479753231397 -0.2406275030271069" rpy="0 0 0"/>
			<geometry>
				<mesh filename="../raw_data/677/part_meshes/2.dae" />
			</geometry>
		</visual>
	</link>


	<link name="3:wheel 2">
		<inertial>
			<origin xyz="0.0 0.0 0.0" rpy="0.0 0.0 0.0"/>
			<mass value="1.0"/>
			<inertia ixx="1.0" ixy="0.0" ixz="0.0" iyy="1.0" iyz="0.0" izz="1.0"/>
		</inertial>
		<visual>
			<origin xyz="0.22030192459882125 -0.02859147645176563 -0.10066716623565913" rpy="0 0 0"/>
			<geometry>
				<mesh filename="../raw_data/677/part_meshes/3.dae" />
			</geometry>
		</visual>
	</link>


	<link name="4:wheel 3">
		<inertial>
			<origin xyz="0.0 0.0 0.0" rpy="0.0 0.0 0.0"/>
			<mass value="1.0"/>
			<inertia ixx="1.0" ixy="0.0" ixz="0.0" iyy="1.0" iyz="0.0" izz="1.0"/>
		</inertial>
		<visual>
			<origin xyz="0.16381675467979262 -0.028591470401806873 0.17841172702578784" rpy="0 0 0"/>
			<geometry>
				<mesh filename="../raw_data/677/part_meshes/4.dae" />
			</geometry>
		</visual>
	</link>


	<link name="5:wheel 4">
		<inertial>
			<origin xyz="0.0 0.0 0.0" rpy="0.0 0.0 0.0"/>
			<mass value="1.0"/>
			<inertia ixx="1.0" ixy="0.0" ixz="0.0" iyy="1.0" iyz="0.0" izz="1.0"/>
		</inertial>
		<visual>
			<origin xyz="-0.11905785305228711 -0.028591469752427656 0.21093176676803724" rpy="0 0 0"/>
			<geometry>
				<mesh filename="../raw_data/677/part_meshes/5.dae" />
			</geometry>
		</visual>
	</link>


	<link name="6:wheel 5">
		<inertial>
			<origin xyz="0.0 0.0 0.0" rpy="0.0 0.0 0.0"/>
			<mass value="1.0"/>
			<inertia ixx="1.0" ixy="0.0" ixz="0.0" iyy="1.0" iyz="0.0" izz="1.0"/>
		</inertial>
		<visual>
			<origin xyz="-0.23739850473662313 -0.028591475253051613 -0.048049303252305026" rpy="0 0 0"/>
			<geometry>
				<mesh filename="../raw_data/677/part_meshes/6.dae" />
			</geometry>
		</visual>
	</link>


	<link name="7:arm 1">
		<inertial>
			<origin xyz="0.0 0.0 0.0" rpy="0.0 0.0 0.0"/>
			<mass value="1.0"/>
			<inertia ixx="1.0" ixy="0.0" ixz="0.0" iyy="1.0" iyz="0.0" izz="1.0"/>
		</inertial>
		<visual>
			<origin xyz="-0.26749473241944555 -0.3885025156736371 0.062034388594173276" rpy="0 0 0"/>
			<geometry>
				<mesh filename="../raw_data/677/part_meshes/7.dae" />
			</geometry>
		</visual>
	</link>


	<link name="8:arm 2">
		<inertial>
			<origin xyz="0.0 0.0 0.0" rpy="0.0 0.0 0.0"/>
			<mass value="1.0"/>
			<inertia ixx="1.0" ixy="0.0" ixz="0.0" iyy="1.0" iyz="0.0" izz="1.0"/>
		</inertial>
		<visual>
			<origin xyz="0.27090938829282535 -0.40313901448249795 0.05488314819961332" rpy="0 0 0"/>
			<geometry>
				<mesh filename="../raw_data/677/part_meshes/8.dae" />
			</geometry>
		</visual>
	</link>


	<link name="9:backrest 1">
		<inertial>
			<origin xyz="0.0 0.0 0.0" rpy="0.0 0.0 0.0"/>
			<mass value="1.0"/>
			<inertia ixx="1.0" ixy="0.0" ixz="0.0" iyy="1.0" iyz="0.0" izz="1.0"/>
		</inertial>
		<visual>
			<origin xyz="-0.0158500068187714 -0.4220700063705444 0.12497900444269182" rpy="0 0 0"/>
			<geometry>
				<mesh filename="../raw_data/677/part_meshes/9.dae" />
			</geometry>
		</visual>
	</link>


	<link name="10:seat 1">
		<inertial>
			<origin xyz="0.0 0.0 0.0" rpy="0.0 0.0 0.0"/>
			<mass value="1.0"/>
			<inertia ixx="1.0" ixy="0.0" ixz="0.0" iyy="1.0" iyz="0.0" izz="1.0"/>
		</inertial>
		<visual>
			<origin xyz="-0.0 -0.41506899893283844 -0.07989000529050827" rpy="0 0 0"/>
			<geometry>
				<mesh filename="../raw_data/677/part_meshes/10.dae" />
			</geometry>
		</visual>
	</link>


	<link name="11:caster 1">
		<inertial>
			<origin xyz="0.0 0.0 0.0" rpy="0.0 0.0 0.0"/>
			<mass value="1.0"/>
			<inertia ixx="1.0" ixy="0.0" ixz="0.0" iyy="1.0" iyz="0.0" izz="1.0"/>
		</inertial>
		<visual>
			<origin xyz="0.22672291657796179 -0.05018809996545315 -0.10360149874936771" rpy="0 0 0"/>
			<geometry>
				<mesh filename="../raw_data/677/part_meshes/11.dae" />
			</geometry>
		</visual>
	</link>


	<link name="12:caster 2">
		<inertial>
			<origin xyz="0.0 0.0 0.0" rpy="0.0 0.0 0.0"/>
			<mass value="1.0"/>
			<inertia ixx="1.0" ixy="0.0" ixz="0.0" iyy="1.0" iyz="0.0" izz="1.0"/>
		</inertial>
		<visual>
			<origin xyz="-0.028469488594168143 -0.05018809996545315 -0.24764073947692455" rpy="0 0 0"/>
			<geometry>
				<mesh filename="../raw_data/677/part_meshes/12.dae" />
			</geometry>
		</visual>
	</link>


	<link name="13:caster 3">
		<inertial>
			<origin xyz="0.0 0.0 0.0" rpy="0.0 0.0 0.0"/>
			<mass value="1.0"/>
			<inertia ixx="1.0" ixy="0.0" ixz="0.0" iyy="1.0" iyz="0.0" izz="1.0"/>
		</inertial>
		<visual>
			<origin xyz="-0.24431828963640798 -0.05018809996545315 -0.04944960028321506" rpy="0 0 0"/>
			<geometry>
				<mesh filename="../raw_data/677/part_meshes/13.dae" />
			</geometry>
		</visual>
	</link>


	<link name="14:caster 4">
		<inertial>
			<origin xyz="0.0 0.0 0.0" rpy="0.0 0.0 0.0"/>
			<mass value="1.0"/>
			<inertia ixx="1.0" ixy="0.0" ixz="0.0" iyy="1.0" iyz="0.0" izz="1.0"/>
		</inertial>
		<visual>
			<origin xyz="-0.12252772419614041 -0.05018809996545315 0.21707947155364787" rpy="0 0 0"/>
			<geometry>
				<mesh filename="../raw_data/677/part_meshes/14.dae" />
			</geometry>
		</visual>
	</link>


	<link name="15:caster 5">
		<inertial>
			<origin xyz="0.0 0.0 0.0" rpy="0.0 0.0 0.0"/>
			<mass value="1.0"/>
			<inertia ixx="1.0" ixy="0.0" ixz="0.0" iyy="1.0" iyz="0.0" izz="1.0"/>
		</inertial>
		<visual>
			<origin xyz="0.16859175064973114 -0.05018809996545315 0.18361175274259714" rpy="0 0 0"/>
			<geometry>
				<mesh filename="../raw_data/677/part_meshes/15.dae" />
			</geometry>
		</visual>
	</link>


	<link name="16:gas lift piece 2">
		<inertial>
			<origin xyz="0.0 0.0 0.0" rpy="0.0 0.0 0.0"/>
			<mass value="1.0"/>
			<inertia ixx="1.0" ixy="0.0" ixz="0.0" iyy="1.0" iyz="0.0" izz="1.0"/>
		</inertial>
		<visual>
			<origin xyz="-0.0 -0.20668649673461914 -0.0" rpy="0 0 0"/>
			<geometry>
				<mesh filename="../raw_data/677/part_meshes/16.dae" />
			</geometry>
		</visual>
	</link>


	<joint name="0:virtual::1:static" type="fixed">
		<parent link="0:virtual"/>
		<child link="1:static"/>
		<origin xyz="0.0 0.0 0.0" rpy="0 0 0"/>
	</joint>


	<joint name="12:caster 2::2:wheel 1_rotation" type="revolute">
		<parent link="12:caster 2"/>
		<child link="2:wheel 1"/>
		<origin xyz="-0.000806338005540877 -0.02159662021222175 -0.007013236449817661" rpy="0 0 0"/>
		<limit lower="-3.141592653589793" upper="3.141592653589793" effort="10" velocity="3"/>
		<axis xyz="-0.9934555841225584 0.0 0.11421909812157696"/>
	</joint>


	<joint name="11:caster 1::3:wheel 2_rotation" type="revolute">
		<parent link="11:caster 1"/>
		<child link="3:wheel 2"/>
		<origin xyz="0.0064209919791405334 -0.02159662351368752 -0.0029343325137085735" rpy="0 0 0"/>
		<limit lower="-3.141592653589793" upper="3.141592653589793" effort="10" velocity="3"/>
		<axis xyz="0.4156053825341069 0.0 0.9095450324248265"/>
	</joint>


	<joint name="15:caster 5::4:wheel 3_rotation" type="revolute">
		<parent link="15:caster 5"/>
		<child link="4:wheel 3"/>
		<origin xyz="0.0047749959699385225 -0.021596629563646275 0.005200025716809303" rpy="0 0 0"/>
		<limit lower="-3.141592653589793" upper="3.141592653589793" effort="10" velocity="3"/>
		<axis xyz="-0.7365717539154187 0.0 0.6763594098805485"/>
	</joint>


	<joint name="14:caster 4::5:wheel 4_rotation" type="revolute">
		<parent link="14:caster 4"/>
		<child link="5:wheel 4"/>
		<origin xyz="-0.0034698711438533036 -0.02159663021302549 0.006147704785610636" rpy="0 0 0"/>
		<limit lower="-3.141592653589793" upper="3.141592653589793" effort="10" velocity="3"/>
		<axis xyz="0.8708486136989014 0.0 0.4915513116844481"/>
	</joint>


	<joint name="13:caster 3::6:wheel 5_rotation" type="revolute">
		<parent link="13:caster 3"/>
		<child link="6:wheel 5"/>
		<origin xyz="-0.006919784899784842 -0.021596624712401535 -0.0014002970309100332" rpy="0 0 0"/>
		<limit lower="-3.141592653589793" upper="3.141592653589793" effort="10" velocity="3"/>
		<axis xyz="-0.19836819123998164 0.0 0.9801275736883328"/>
	</joint>


	<joint name="16:gas lift piece 2::7:arm 1_rotation" type="revolute">
		<parent link="16:gas lift piece 2"/>
		<child link="7:arm 1"/>
		<origin xyz="0.26749473241944555 0.18181601893901794 -0.062034388594173276" rpy="0 0 0"/>
		<limit lower="0.0" upper="0.45553093477052" effort="10" velocity="3"/>
		<axis xyz="0.9999999999252549 0.0 -1.2226616503777492e-05"/>
	</joint>


	<joint name="16:gas lift piece 2::8:arm 2_rotation" type="revolute">
		<parent link="16:gas lift piece 2"/>
		<child link="8:arm 2"/>
		<origin xyz="-0.27090938829282535 0.1964525177478788 -0.05488314819961332" rpy="0 0 0"/>
		<limit lower="-0.45553093477052" upper="0.0" effort="10" velocity="3"/>
		<axis xyz="-0.9999999999252549 0.0 -1.2226616503777492e-05"/>
	</joint>


	<joint name="10:seat 1::9:backrest 1_rotation" type="revolute">
		<parent link="10:seat 1"/>
		<child link="9:backrest 1"/>
		<origin xyz="0.0158500068187714 0.007001007437705986 -0.2048690097332001" rpy="0 0 0"/>
		<limit lower="-0.21991148575128555" upper="0.3612831551628262" effort="10" velocity="3"/>
		<axis xyz="1.0 0.0 0.0"/>
	</joint>


	<joint name="16:gas lift piece 2::10:seat 1_translation" type="prismatic">
		<parent link="16:gas lift piece 2"/>
		<child link="10:seat 1"/>
		<origin xyz="0.0 0.2083825021982193 0.07989000529050827" rpy="0 0 0"/>
		<limit lower="-0.03417399525642395" upper="0.03417399525642395" effort="10" velocity="3"/>
		<axis xyz="0.0 1.0 0.0"/>
	</joint>


	<joint name="0:virtual::11:caster 1_rotation" type="revolute">
		<parent link="0:virtual"/>
		<child link="11:caster 1"/>
		<origin xyz="-0.22672291657796179 0.05018809996545315 0.10360149874936771" rpy="0 0 0"/>
		<limit lower="-3.141592653589793" upper="3.141592653589793" effort="10" velocity="3"/>
		<axis xyz="0.0 1.0 0.0"/>
	</joint>


	<joint name="0:virtual::12:caster 2_rotation" type="revolute">
		<parent link="0:virtual"/>
		<child link="12:caster 2"/>
		<origin xyz="0.028469488594168143 0.05018809996545315 0.24764073947692455" rpy="0 0 0"/>
		<limit lower="-3.141592653589793" upper="3.141592653589793" effort="10" velocity="3"/>
		<axis xyz="0.0 1.0 0.0"/>
	</joint>


	<joint name="0:virtual::13:caster 3_rotation" type="revolute">
		<parent link="0:virtual"/>
		<child link="13:caster 3"/>
		<origin xyz="0.24431828963640798 0.05018809996545315 0.04944960028321506" rpy="0 0 0"/>
		<limit lower="-3.141592653589793" upper="3.141592653589793" effort="10" velocity="3"/>
		<axis xyz="0.0 1.0 0.0"/>
	</joint>


	<joint name="0:virtual::14:caster 4_rotation" type="revolute">
		<parent link="0:virtual"/>
		<child link="14:caster 4"/>
		<origin xyz="0.12252772419614041 0.05018809996545315 -0.21707947155364787" rpy="0 0 0"/>
		<limit lower="-3.141592653589793" upper="3.141592653589793" effort="10" velocity="3"/>
		<axis xyz="0.0 1.0 0.0"/>
	</joint>


	<joint name="0:virtual::15:caster 5_rotation" type="revolute">
		<parent link="0:virtual"/>
		<child link="15:caster 5"/>
		<origin xyz="-0.16859175064973114 0.05018809996545315 -0.18361175274259714" rpy="0 0 0"/>
		<limit lower="-3.141592653589793" upper="3.141592653589793" effort="10" velocity="3"/>
		<axis xyz="0.0 1.0 0.0"/>
	</joint>


	<joint name="0:virtual::16:gas lift piece 2_rotation" type="revolute">
		<parent link="0:virtual"/>
		<child link="16:gas lift piece 2"/>
		<origin xyz="0.0 0.20668649673461914 0.0" rpy="0 0 0"/>
		<limit lower="-3.141592653589793" upper="3.141592653589793" effort="10" velocity="3"/>
		<axis xyz="0.0 1.0 0.0"/>
	</joint>


</robot>