<robot name="73">


	<link name="0:virtual">
		<visual>
			<origin xyz="0.0 0.0 0.0" rpy="0 0 0"/>
			<geometry>
				<cylinder length="0" radius="0"/>
			</geometry>
		</visual>
	</link>


	<link name="1:static">
		<visual>
			<origin xyz="-0.0 -0.0 -0.0" rpy="0 0 0"/>
			<geometry>
				<mesh filename="../raw_data/73/part_meshes/1.dae" />
			</geometry>
		</visual>
	</link>


	<link name="2:door 1">
		<visual>
			<origin xyz="0.4780362567628476 -1.025975026190281 0.07938755623222465" rpy="0 0 0"/>
			<geometry>
				<mesh filename="../raw_data/73/part_meshes/2.dae" />
			</geometry>
		</visual>
	</link>


	<link name="3:handle 1">
		<visual>
			<origin xyz="-0.01194323920811416 -0.9110000010728836 0.825172258041395" rpy="0 0 0"/>
			<geometry>
				<mesh filename="../raw_data/73/part_meshes/3.dae" />
			</geometry>
		</visual>
	</link>


	<link name="4:handle 2">
		<visual>
			<origin xyz="-0.09759010980901708 -0.9118879768848419 0.8077820489945222" rpy="0 0 0"/>
			<geometry>
				<mesh filename="../raw_data/73/part_meshes/4.dae" />
			</geometry>
		</visual>
	</link>


	<joint name="0:virtual::1:static" type="fixed">
		<parent link="0:virtual"/>
		<child link="1:static"/>
		<origin xyz="0.0 0.0 0.0" rpy="0 0 0"/>
	</joint>


	<joint name="0:virtual::2:door 1_rotation" type="revolute">
		<parent link="0:virtual"/>
		<child link="2:door 1"/>
		<origin xyz="-0.4780362567628476 1.025975026190281 -0.07938755623222465" rpy="0 0 0"/>
		<limit lower="-0.9738937226128359" upper="0.7225663103256524" effort="10" velocity="3"/>
		<axis xyz="0.0 1.0 0.0"/>
	</joint>


	<joint name="2:door 1::3:handle 1_rotation" type="revolute">
		<parent link="2:door 1"/>
		<child link="3:handle 1"/>
		<origin xyz="0.4899794959709618 -0.11497502511739732 -0.7457847018091703" rpy="0 0 0"/>
		<limit lower="0.0" upper="0.4241150082346221" effort="10" velocity="3"/>
		<axis xyz="0.8195820858386489 0.0 0.5729617828200844"/>
	</joint>


	<joint name="2:door 1::4:handle 2_rotation" type="revolute">
		<parent link="2:door 1"/>
		<child link="4:handle 2"/>
		<origin xyz="0.5756263665718647 -0.114087049305439 -0.7283944927622976" rpy="0 0 0"/>
		<limit lower="0.0" upper="0.4241150082346221" effort="10" velocity="3"/>
		<axis xyz="0.8202334092554516 0.0 0.5720289803333208"/>
	</joint>


</robot>