<robot name="74">


	<link name="0:virtual">
		<visual>
			<origin xyz="0.0 0.0 0.0" rpy="0 0 0"/>
			<geometry>
				<cylinder length="0" radius="0"/>
			</geometry>
		</visual>
	</link>


	<link name="1:static">
		<visual>
			<origin xyz="-0.0 -0.0 -0.0" rpy="0 0 0"/>
			<geometry>
				<mesh filename="../raw_data/74/part_meshes/1.dae" />
			</geometry>
		</visual>
	</link>


	<link name="2:faucet base 1">
		<visual>
			<origin xyz="-9.057687326563535e-08 -0.9140680134296417 0.134774663520808" rpy="0 0 0"/>
			<geometry>
				<mesh filename="../raw_data/74/part_meshes/2.dae" />
			</geometry>
		</visual>
	</link>


	<link name="3:cabinet door 1">
		<visual>
			<origin xyz="-0.31957098841667175 -0.34459175541996956 -0.1640470027923584" rpy="0 0 0"/>
			<geometry>
				<mesh filename="../raw_data/74/part_meshes/3.dae" />
			</geometry>
		</visual>
	</link>


	<link name="4:cabinet door 2">
		<visual>
			<origin xyz="0.31957098841667225 -0.3393567390739918 -0.17512799644470214" rpy="0 0 0"/>
			<geometry>
				<mesh filename="../raw_data/74/part_meshes/4.dae" />
			</geometry>
		</visual>
	</link>


	<link name="5:faucet spout 1">
		<visual>
			<origin xyz="0.013174699619412422 -0.9051439762115479 0.12355300039052963" rpy="0 0 0"/>
			<geometry>
				<mesh filename="../raw_data/74/part_meshes/5.dae" />
			</geometry>
		</visual>
	</link>


	<link name="6:faucet handle 1">
		<visual>
			<origin xyz="0.0001647026781300357 -0.9943904876708984 0.13538968784478717" rpy="0 0 0"/>
			<geometry>
				<mesh filename="../raw_data/74/part_meshes/6.dae" />
			</geometry>
		</visual>
	</link>


	<joint name="0:virtual::1:static" type="fixed">
		<parent link="0:virtual"/>
		<child link="1:static"/>
		<origin xyz="0.0 0.0 0.0" rpy="0 0 0"/>
	</joint>


	<joint name="0:virtual::2:faucet base 1_rotation" type="revolute">
		<parent link="0:virtual"/>
		<child link="2:faucet base 1"/>
		<origin xyz="9.057687326563535e-08 0.9140680134296417 -0.134774663520808" rpy="0 0 0"/>
		<limit lower="-1.0995574287564276" upper="0.5811946409141118" effort="10" velocity="3"/>
		<axis xyz="0.0 1.0 0.0"/>
	</joint>


	<joint name="0:virtual::3:cabinet door 1_rotation" type="revolute">
		<parent link="0:virtual"/>
		<child link="3:cabinet door 1"/>
		<origin xyz="0.31957098841667175 0.34459175541996956 0.1640470027923584" rpy="0 0 0"/>
		<limit lower="0.0" upper="2.1205750411731104" effort="10" velocity="3"/>
		<axis xyz="0.0 1.0 0.0"/>
	</joint>


	<joint name="0:virtual::4:cabinet door 2_rotation" type="revolute">
		<parent link="0:virtual"/>
		<child link="4:cabinet door 2"/>
		<origin xyz="-0.31957098841667225 0.3393567390739918 0.17512799644470214" rpy="0 0 0"/>
		<limit lower="-1.7749998492782328" upper="0.0" effort="10" velocity="3"/>
		<axis xyz="0.0 1.0 0.0"/>
	</joint>


	<joint name="2:faucet base 1::5:faucet spout 1_rotation" type="revolute">
		<parent link="2:faucet base 1"/>
		<child link="5:faucet spout 1"/>
		<origin xyz="-0.013174790196285688 -0.008924037218093872 0.011221663130278364" rpy="0 0 0"/>
		<limit lower="-1.0838494654884785" upper="1.0210176124166828" effort="10" velocity="3"/>
		<axis xyz="0.0 1.0 0.0"/>
	</joint>


	<joint name="2:faucet base 1::6:faucet handle 1_rotation" type="revolute">
		<parent link="2:faucet base 1"/>
		<child link="6:faucet handle 1"/>
		<origin xyz="-0.00016479325500330134 0.08032247424125671 -0.0006150243239791686" rpy="0 0 0"/>
		<limit lower="-0.8796459430051422" upper="0.5811946409141118" effort="10" velocity="3"/>
		<axis xyz="0.0 1.0 0.0"/>
	</joint>


</robot>