<robot name="756">


	<link name="0:virtual">
		<visual>
			<origin xyz="0.0 0.0 0.0" rpy="0 0 0"/>
			<geometry>
				<cylinder length="0" radius="0"/>
			</geometry>
		</visual>
	</link>


	<link name="1:static">
		<visual>
			<origin xyz="-0.0 -0.0 -0.0" rpy="0 0 0"/>
			<geometry>
				<mesh filename="raw_data/756/part_meshes/1.dae" />
			</geometry>
		</visual>
	</link>


	<link name="2:door 1">
		<visual>
			<origin xyz="-0.7500000298023224 -1.2599999997764826 -0.012499945238232613" rpy="0 0 0"/>
			<geometry>
				<mesh filename="raw_data/756/part_meshes/2.dae" />
			</geometry>
		</visual>
	</link>


	<link name="3:door 2">
		<visual>
			<origin xyz="1.050000011920929 -1.2599999997764826 -0.012499945238232613" rpy="0 0 0"/>
			<geometry>
				<mesh filename="raw_data/756/part_meshes/3.dae" />
			</geometry>
		</visual>
	</link>


	<joint name="0:virtual::1:static" type="fixed">
		<parent link="0:virtual"/>
		<child link="1:static"/>
		<origin xyz="0.0 0.0 0.0" rpy="0 0 0"/>
	</joint>


	<joint name="0:virtual::2:door 1_translation" type="prismatic">
		<parent link="0:virtual"/>
		<child link="2:door 1"/>
		<origin xyz="0.7500000298023224 1.2599999997764826 0.012499945238232613" rpy="0 0 0"/>
		<limit lower="-0.211000071525574" upper="0.454999928474426" effort="10" velocity="3"/>
		<axis xyz="1.0 0.0 0.0"/>
	</joint>


	<joint name="0:virtual::3:door 2_translation" type="prismatic">
		<parent link="0:virtual"/>
		<child link="3:door 2"/>
		<origin xyz="-1.050000011920929 1.2599999997764826 0.012499945238232613" rpy="0 0 0"/>
		<limit lower="-0.211000071525574" upper="0.454999928474426" effort="10" velocity="3"/>
		<axis xyz="1.0 0.0 0.0"/>
	</joint>


</robot>