<robot name="79">


	<link name="0:virtual">
		<visual>
			<origin xyz="0.0 0.0 0.0" rpy="0 0 0"/>
			<geometry>
				<cylinder length="0" radius="0"/>
			</geometry>
		</visual>
	</link>


	<link name="1:static">
		<visual>
			<origin xyz="-0.0 -0.0 -0.0" rpy="0 0 0"/>
			<geometry>
				<mesh filename="raw_data/79/part_meshes/1.dae" />
			</geometry>
		</visual>
	</link>


	<link name="2:faucet 1">
		<visual>
			<origin xyz="-0.0014748996171254896 -0.24136299443244932 0.2599252815319291" rpy="0 0 0"/>
			<geometry>
				<mesh filename="raw_data/79/part_meshes/2.dae" />
			</geometry>
		</visual>
	</link>


	<link name="3:faucet handle 1">
		<visual>
			<origin xyz="-0.01354882414032587 -0.30136299443244935 0.24598898551727488" rpy="0 0 0"/>
			<geometry>
				<mesh filename="raw_data/79/part_meshes/3.dae" />
			</geometry>
		</visual>
	</link>


	<joint name="0:virtual::1:static" type="fixed">
		<parent link="0:virtual"/>
		<child link="1:static"/>
		<origin xyz="0.0 0.0 0.0" rpy="0 0 0"/>
	</joint>


	<joint name="0:virtual::2:faucet 1_rotation" type="revolute">
		<parent link="0:virtual"/>
		<child link="2:faucet 1"/>
		<origin xyz="0.0014748996171254896 0.24136299443244932 -0.2599252815319291" rpy="0 0 0"/>
		<limit lower="-0.4084070449666731" upper="0.3612831551628262" effort="10" velocity="3"/>
		<axis xyz="0.0 1.0 0.0"/>
	</joint>


	<joint name="2:faucet 1::3:faucet handle 1_rotation" type="revolute">
		<parent link="2:faucet 1"/>
		<child link="3:faucet handle 1"/>
		<origin xyz="0.01207392452320038 0.060000000000000026 0.013936296014654237" rpy="0 0 0"/>
		<limit lower="-0.45553093477052" upper="0.0" effort="10" velocity="3"/>
		<axis xyz="0.9999859955398833 0.0 -0.005292326908696847"/>
	</joint>


</robot>