<robot name="87">


	<link name="0:virtual">
		<visual>
			<origin xyz="0.0 0.0 0.0" rpy="0 0 0"/>
			<geometry>
				<cylinder length="0" radius="0"/>
			</geometry>
		</visual>
	</link>


	<link name="1:faucet handle 1">
		<inertial>
			<origin xyz="0.0 0.0 0.0" rpy="0.0 0.0 0.0"/>
			<mass value="1.0"/>
			<inertia ixx="1.0" ixy="0.0" ixz="0.0" iyy="1.0" iyz="0.0" izz="1.0"/>
		</inertial>
		<visual>
			<origin xyz="0.0030253873595520167 -0.9455100102424622 0.16515578260625746" rpy="0 0 0"/>
			<geometry>
				<mesh filename="../raw_data/87/part_meshes/1.dae" />
			</geometry>
		</visual>
	</link>


	<link name="2:faucet spout 1">
		<inertial>
			<origin xyz="0.0 0.0 0.0" rpy="0.0 0.0 0.0"/>
			<mass value="1.0"/>
			<inertia ixx="1.0" ixy="0.0" ixz="0.0" iyy="1.0" iyz="0.0" izz="1.0"/>
		</inertial>
		<visual>
			<origin xyz="-0.009291199372985299 -0.8753380179405212 0.15965299202253996" rpy="0 0 0"/>
			<geometry>
				<mesh filename="../raw_data/87/part_meshes/2.dae" />
			</geometry>
		</visual>
	</link>


	<link name="3:drawer 1">
		<inertial>
			<origin xyz="0.0 0.0 0.0" rpy="0.0 0.0 0.0"/>
			<mass value="1.0"/>
			<inertia ixx="1.0" ixy="0.0" ixz="0.0" iyy="1.0" iyz="0.0" izz="1.0"/>
		</inertial>
		<visual>
			<origin xyz="0.18705202674027532 -0.3405275046825409 -0.023874498903751373" rpy="0 0 0"/>
			<geometry>
				<mesh filename="../raw_data/87/part_meshes/3.dae" />
			</geometry>
		</visual>
	</link>


	<link name="4:drawer 2">
		<inertial>
			<origin xyz="0.0 0.0 0.0" rpy="0.0 0.0 0.0"/>
			<mass value="1.0"/>
			<inertia ixx="1.0" ixy="0.0" ixz="0.0" iyy="1.0" iyz="0.0" izz="1.0"/>
		</inertial>
		<visual>
			<origin xyz="-0.18652293641935103 -0.34032250195741653 -0.023874498903751373" rpy="0 0 0"/>
			<geometry>
				<mesh filename="../raw_data/87/part_meshes/4.dae" />
			</geometry>
		</visual>
	</link>


	<joint name="4:drawer 2::1:faucet handle 1_rotation" type="revolute">
		<parent link="4:drawer 2"/>
		<child link="1:faucet handle 1"/>
		<origin xyz="-0.18954832377890304 0.6051875082850456 -0.18903028151000884" rpy="0 0 0"/>
		<limit lower="-1.2095131716320704" upper="1.2095131716320704" effort="10" velocity="3"/>
		<axis xyz="0.0 1.0 0.0"/>
	</joint>


	<joint name="4:drawer 2::2:faucet spout 1_rotation" type="revolute">
		<parent link="4:drawer 2"/>
		<child link="2:faucet spout 1"/>
		<origin xyz="-0.17723173704636572 0.5350155159831047 -0.18352749092629134" rpy="0 0 0"/>
		<limit lower="-0.895353906273091" upper="0.4398229715025711" effort="10" velocity="3"/>
		<axis xyz="0.0 1.0 0.0"/>
	</joint>


	<joint name="0:virtual::3:drawer 1_translation" type="prismatic">
		<parent link="0:virtual"/>
		<child link="3:drawer 1"/>
		<origin xyz="-0.18705202674027532 0.3405275046825409 0.023874498903751373" rpy="0 0 0"/>
		<limit lower="-0.0002934866547585" upper="0.352706513345242" effort="10" velocity="3"/>
		<axis xyz="0.0 0.0 1.0"/>
	</joint>


	<joint name="0:virtual::4:drawer 2_translation" type="prismatic">
		<parent link="0:virtual"/>
		<child link="4:drawer 2"/>
		<origin xyz="0.18652293641935103 0.34032250195741653 0.023874498903751373" rpy="0 0 0"/>
		<limit lower="-0.0002934866547585" upper="0.352706513345242" effort="10" velocity="3"/>
		<axis xyz="0.0 0.0 1.0"/>
	</joint>


</robot>