<robot name="s__1222">


	<link name="0:virtual">
		<visual>
			<origin xyz="0.0 0.0 0.0" rpy="0 0 0"/>
			<geometry>
				<cylinder length="0" radius="0"/>
			</geometry>
		</visual>
	</link>


	<link name="1:static">
		<visual>
			<origin xyz="-0.0 -0.0 -0.0" rpy="0 0 0"/>
			<geometry>
				<mesh filename="raw_data/s__1222/part_meshes/1.dae" />
			</geometry>
		</visual>
	</link>


	<link name="2:drawer 1">
		<visual>
			<origin xyz="-0.521000012755394 -0.44425299763679504 0.08452750742435455" rpy="0 0 0"/>
			<geometry>
				<mesh filename="raw_data/s__1222/part_meshes/2.dae" />
			</geometry>
		</visual>
	</link>


	<link name="3:drawer 2">
		<visual>
			<origin xyz="-0.521000012755394 -0.28316449373960495 0.08452750742435455" rpy="0 0 0"/>
			<geometry>
				<mesh filename="raw_data/s__1222/part_meshes/3.dae" />
			</geometry>
		</visual>
	</link>


	<link name="4:drawer 3">
		<visual>
			<origin xyz="-0.521000012755394 -0.12207619845867157 0.08452750742435455" rpy="0 0 0"/>
			<geometry>
				<mesh filename="raw_data/s__1222/part_meshes/4.dae" />
			</geometry>
		</visual>
	</link>


	<link name="5:cabinet door 1">
		<visual>
			<origin xyz="0.7200000286102295 -0.28316464461386204 -0.21668200194835663" rpy="0 0 0"/>
			<geometry>
				<mesh filename="raw_data/s__1222/part_meshes/5.dae" />
			</geometry>
		</visual>
	</link>


	<joint name="0:virtual::1:static" type="fixed">
		<parent link="0:virtual"/>
		<child link="1:static"/>
		<origin xyz="0.0 0.0 0.0" rpy="0 0 0"/>
	</joint>


	<joint name="0:virtual::2:drawer 1_translation" type="prismatic">
		<parent link="0:virtual"/>
		<child link="2:drawer 1"/>
		<origin xyz="0.521000012755394 0.44425299763679504 -0.08452750742435455" rpy="0 0 0"/>
		<limit lower="-0.0001124999821186" upper="0.348887500017881" effort="10" velocity="3"/>
		<axis xyz="0.0 0.0 1.0"/>
	</joint>


	<joint name="0:virtual::3:drawer 2_translation" type="prismatic">
		<parent link="0:virtual"/>
		<child link="3:drawer 2"/>
		<origin xyz="0.521000012755394 0.28316449373960495 -0.08452750742435455" rpy="0 0 0"/>
		<limit lower="-0.0001124999821186" upper="0.348887500017881" effort="10" velocity="3"/>
		<axis xyz="0.0 0.0 1.0"/>
	</joint>


	<joint name="0:virtual::4:drawer 3_translation" type="prismatic">
		<parent link="0:virtual"/>
		<child link="4:drawer 3"/>
		<origin xyz="0.521000012755394 0.12207619845867157 -0.08452750742435455" rpy="0 0 0"/>
		<limit lower="-0.0001124999821186" upper="0.348887500017881" effort="10" velocity="3"/>
		<axis xyz="0.0 0.0 1.0"/>
	</joint>


	<joint name="0:virtual::5:cabinet door 1_rotation" type="revolute">
		<parent link="0:virtual"/>
		<child link="5:cabinet door 1"/>
		<origin xyz="-0.7200000286102295 0.28316464461386204 0.21668200194835663" rpy="0 0 0"/>
		<limit lower="-3.141592653589793" upper="0.0" effort="10" velocity="3"/>
		<axis xyz="0.0 1.0 0.0"/>
	</joint>


</robot>