<robot name="s__1132">


	<link name="0:virtual">
		<visual>
			<origin xyz="0.0 0.0 0.0" rpy="0 0 0"/>
			<geometry>
				<cylinder length="0" radius="0"/>
			</geometry>
		</visual>
	</link>


	<link name="1:static">
		<visual>
			<origin xyz="-0.0 -0.0 -0.0" rpy="0 0 0"/>
			<geometry>
				<mesh filename="../raw_data/s__1132/part_meshes/1.dae" />
			</geometry>
		</visual>
	</link>


	<link name="2:cabinet door 1">
		<visual>
			<origin xyz="0.3105000073909756 -0.399999987334013 -0.2645560029745102" rpy="0 0 0"/>
			<geometry>
				<mesh filename="../raw_data/s__1132/part_meshes/2.dae" />
			</geometry>
		</visual>
	</link>


	<link name="3:drawer 1">
		<visual>
			<origin xyz="-0.5149999856948853 -0.7800000011920929 0.014219507575035095" rpy="0 0 0"/>
			<geometry>
				<mesh filename="../raw_data/s__1132/part_meshes/3.dae" />
			</geometry>
		</visual>
	</link>


	<link name="4:drawer 2">
		<visual>
			<origin xyz="-0.5149999856948853 -0.5699999928474426 0.014219507575035095" rpy="0 0 0"/>
			<geometry>
				<mesh filename="../raw_data/s__1132/part_meshes/4.dae" />
			</geometry>
		</visual>
	</link>


	<link name="5:drawer 3">
		<visual>
			<origin xyz="-0.5149999856948853 -0.26999999210238457 0.014219507575035095" rpy="0 0 0"/>
			<geometry>
				<mesh filename="../raw_data/s__1132/part_meshes/5.dae" />
			</geometry>
		</visual>
	</link>


	<link name="6:drawer 4">
		<visual>
			<origin xyz="0.5149999856948853 -0.26999999210238457 0.014219507575035095" rpy="0 0 0"/>
			<geometry>
				<mesh filename="../raw_data/s__1132/part_meshes/6.dae" />
			</geometry>
		</visual>
	</link>


	<link name="7:drawer 5">
		<visual>
			<origin xyz="0.5149999856948853 -0.5699999928474426 0.014219507575035095" rpy="0 0 0"/>
			<geometry>
				<mesh filename="../raw_data/s__1132/part_meshes/7.dae" />
			</geometry>
		</visual>
	</link>


	<link name="8:drawer 6">
		<visual>
			<origin xyz="0.5149999856948853 -0.7800000011920929 0.014219507575035095" rpy="0 0 0"/>
			<geometry>
				<mesh filename="../raw_data/s__1132/part_meshes/8.dae" />
			</geometry>
		</visual>
	</link>


	<joint name="0:virtual::1:static" type="fixed">
		<parent link="0:virtual"/>
		<child link="1:static"/>
		<origin xyz="0.0 0.0 0.0" rpy="0 0 0"/>
	</joint>


	<joint name="0:virtual::2:cabinet door 1_rotation" type="revolute">
		<parent link="0:virtual"/>
		<child link="2:cabinet door 1"/>
		<origin xyz="-0.3105000073909756 0.399999987334013 0.2645560029745102" rpy="0 0 0"/>
		<limit lower="-2.827433388230814" upper="0.0" effort="10" velocity="3"/>
		<axis xyz="0.0 1.0 0.0"/>
	</joint>


	<joint name="0:virtual::3:drawer 1_translation" type="prismatic">
		<parent link="0:virtual"/>
		<child link="3:drawer 1"/>
		<origin xyz="0.5149999856948853 0.7800000011920929 -0.014219507575035095" rpy="0 0 0"/>
		<limit lower="-0.000333972454071" upper="0.280666027545929" effort="10" velocity="3"/>
		<axis xyz="0.0 0.0 1.0"/>
	</joint>


	<joint name="0:virtual::4:drawer 2_translation" type="prismatic">
		<parent link="0:virtual"/>
		<child link="4:drawer 2"/>
		<origin xyz="0.5149999856948853 0.5699999928474426 -0.014219507575035095" rpy="0 0 0"/>
		<limit lower="-0.000333972454071" upper="0.280666027545929" effort="10" velocity="3"/>
		<axis xyz="0.0 0.0 1.0"/>
	</joint>


	<joint name="0:virtual::5:drawer 3_translation" type="prismatic">
		<parent link="0:virtual"/>
		<child link="5:drawer 3"/>
		<origin xyz="0.5149999856948853 0.26999999210238457 -0.014219507575035095" rpy="0 0 0"/>
		<limit lower="-0.000333972454071" upper="0.280666027545929" effort="10" velocity="3"/>
		<axis xyz="0.0 0.0 1.0"/>
	</joint>


	<joint name="0:virtual::6:drawer 4_translation" type="prismatic">
		<parent link="0:virtual"/>
		<child link="6:drawer 4"/>
		<origin xyz="-0.5149999856948853 0.26999999210238457 -0.014219507575035095" rpy="0 0 0"/>
		<limit lower="-0.000333972454071" upper="0.280666027545929" effort="10" velocity="3"/>
		<axis xyz="0.0 0.0 1.0"/>
	</joint>


	<joint name="0:virtual::7:drawer 5_translation" type="prismatic">
		<parent link="0:virtual"/>
		<child link="7:drawer 5"/>
		<origin xyz="-0.5149999856948853 0.5699999928474426 -0.014219507575035095" rpy="0 0 0"/>
		<limit lower="-0.000333972454071" upper="0.280666027545929" effort="10" velocity="3"/>
		<axis xyz="0.0 0.0 1.0"/>
	</joint>


	<joint name="0:virtual::8:drawer 6_translation" type="prismatic">
		<parent link="0:virtual"/>
		<child link="8:drawer 6"/>
		<origin xyz="-0.5149999856948853 0.7800000011920929 -0.014219507575035095" rpy="0 0 0"/>
		<limit lower="-0.000333972454071" upper="0.280666027545929" effort="10" velocity="3"/>
		<axis xyz="0.0 0.0 1.0"/>
	</joint>


</robot>