<robot name="s__1158">


	<link name="0:virtual">
		<visual>
			<origin xyz="0.0 0.0 0.0" rpy="0 0 0"/>
			<geometry>
				<cylinder length="0" radius="0"/>
			</geometry>
		</visual>
	</link>


	<link name="1:static">
		<visual>
			<origin xyz="-0.0 -0.0 -0.0" rpy="0 0 0"/>
			<geometry>
				<mesh filename="../raw_data/s__1158/part_meshes/1.dae" />
			</geometry>
		</visual>
	</link>


	<link name="2:cabinet door 1">
		<visual>
			<origin xyz="-0.6092090010643005 -0.4602770060300827 -0.2628780007362366" rpy="0 0 0"/>
			<geometry>
				<mesh filename="../raw_data/s__1158/part_meshes/2.dae" />
			</geometry>
		</visual>
	</link>


	<link name="3:cabinet door 2">
		<visual>
			<origin xyz="0.613368742757447 -0.4602770060300827 -0.2522439956665039" rpy="0 0 0"/>
			<geometry>
				<mesh filename="../raw_data/s__1158/part_meshes/3.dae" />
			</geometry>
		</visual>
	</link>


	<joint name="0:virtual::1:static" type="fixed">
		<parent link="0:virtual"/>
		<child link="1:static"/>
		<origin xyz="0.0 0.0 0.0" rpy="0 0 0"/>
	</joint>


	<joint name="0:virtual::2:cabinet door 1_rotation" type="revolute">
		<parent link="0:virtual"/>
		<child link="2:cabinet door 1"/>
		<origin xyz="0.6092090010643005 0.4602770060300827 0.2628780007362366" rpy="0 0 0"/>
		<limit lower="0.0" upper="2.183406894244906" effort="10" velocity="3"/>
		<axis xyz="0.0 1.0 0.0"/>
	</joint>


	<joint name="0:virtual::3:cabinet door 2_rotation" type="revolute">
		<parent link="0:virtual"/>
		<child link="3:cabinet door 2"/>
		<origin xyz="-0.613368742757447 0.4602770060300827 0.2522439956665039" rpy="0 0 0"/>
		<limit lower="-2.214822820780804" upper="0.0" effort="10" velocity="3"/>
		<axis xyz="0.0 1.0 0.0"/>
	</joint>


</robot>