<robot name="s__1002">


	<link name="0:virtual">
		<visual>
			<origin xyz="0.0 0.0 0.0" rpy="0 0 0"/>
			<geometry>
				<cylinder length="0" radius="0"/>
			</geometry>
		</visual>
	</link>


	<link name="1:static">
		<visual>
			<origin xyz="-0.0 -0.0 -0.0" rpy="0 0 0"/>
			<geometry>
				<mesh filename="../raw_data/s__1002/part_meshes/1.dae" />
			</geometry>
		</visual>
	</link>


	<link name="2:drawer 1">
		<visual>
			<origin xyz="0.22404842084506527 -0.6517989933490753 -0.0030025020241737366" rpy="0 0 0"/>
			<geometry>
				<mesh filename="../raw_data/s__1002/part_meshes/2.dae" />
			</geometry>
		</visual>
	</link>


	<link name="3:drawer 2">
		<visual>
			<origin xyz="-0.2289761924127881 -0.6519995033740997 -0.009659622906194931" rpy="0 0 0"/>
			<geometry>
				<mesh filename="../raw_data/s__1002/part_meshes/3.dae" />
			</geometry>
		</visual>
	</link>


	<link name="4:drawer 3">
		<visual>
			<origin xyz="-0.0 -0.45045149326324463 -0.0030025020241737366" rpy="0 0 0"/>
			<geometry>
				<mesh filename="../raw_data/s__1002/part_meshes/4.dae" />
			</geometry>
		</visual>
	</link>


	<link name="5:drawer 4">
		<visual>
			<origin xyz="-0.0 -0.2232007458806038 -0.0030025020241737366" rpy="0 0 0"/>
			<geometry>
				<mesh filename="../raw_data/s__1002/part_meshes/5.dae" />
			</geometry>
		</visual>
	</link>


	<joint name="0:virtual::1:static" type="fixed">
		<parent link="0:virtual"/>
		<child link="1:static"/>
		<origin xyz="0.0 0.0 0.0" rpy="0 0 0"/>
	</joint>


	<joint name="0:virtual::2:drawer 1_translation" type="prismatic">
		<parent link="0:virtual"/>
		<child link="2:drawer 1"/>
		<origin xyz="-0.22404842084506527 0.6517989933490753 0.0030025020241737366" rpy="0 0 0"/>
		<limit lower="-0.0003550020456314" upper="0.357644997954369" effort="10" velocity="3"/>
		<axis xyz="0.0 0.0 1.0"/>
	</joint>


	<joint name="0:virtual::3:drawer 2_translation" type="prismatic">
		<parent link="0:virtual"/>
		<child link="3:drawer 2"/>
		<origin xyz="0.2289761924127881 0.6519995033740997 0.009659622906194931" rpy="0 0 0"/>
		<limit lower="-0.24012603238303895" upper="0.24012603238303895" effort="10" velocity="3"/>
		<axis xyz="-0.022816297244594566 0.0 0.9997396744053156"/>
	</joint>


	<joint name="0:virtual::4:drawer 3_translation" type="prismatic">
		<parent link="0:virtual"/>
		<child link="4:drawer 3"/>
		<origin xyz="0.0 0.45045149326324463 0.0030025020241737366" rpy="0 0 0"/>
		<limit lower="-0.0003550020456314" upper="0.405644997954369" effort="10" velocity="3"/>
		<axis xyz="0.0 0.0 1.0"/>
	</joint>


	<joint name="0:virtual::5:drawer 4_translation" type="prismatic">
		<parent link="0:virtual"/>
		<child link="5:drawer 4"/>
		<origin xyz="0.0 0.2232007458806038 0.0030025020241737366" rpy="0 0 0"/>
		<limit lower="-0.0003550020456314" upper="0.405644997954369" effort="10" velocity="3"/>
		<axis xyz="0.0 0.0 1.0"/>
	</joint>


</robot>