<robot name="s__1249">


	<link name="0:virtual">
		<visual>
			<origin xyz="0.0 0.0 0.0" rpy="0 0 0"/>
			<geometry>
				<cylinder length="0" radius="0"/>
			</geometry>
		</visual>
	</link>


	<link name="1:static">
		<visual>
			<origin xyz="-0.0 -0.0 -0.0" rpy="0 0 0"/>
			<geometry>
				<mesh filename="raw_data/s__1249/part_meshes/1.dae" />
			</geometry>
		</visual>
	</link>


	<link name="2:faucet handle 1">
		<visual>
			<origin xyz="1.0483477637624394 -0.9616730017662048 0.2910869707179954" rpy="0 0 0"/>
			<geometry>
				<mesh filename="raw_data/s__1249/part_meshes/2.dae" />
			</geometry>
		</visual>
	</link>


	<link name="3:faucet lift rod 1">
		<visual>
			<origin xyz="0.9250001608975427 -0.9515649676322937 0.3011934459505527" rpy="0 0 0"/>
			<geometry>
				<mesh filename="raw_data/s__1249/part_meshes/3.dae" />
			</geometry>
		</visual>
	</link>


	<link name="4:faucet lift rod 2">
		<visual>
			<origin xyz="-0.9249999001612884 -0.9515649676322937 0.3011933341572664" rpy="0 0 0"/>
			<geometry>
				<mesh filename="raw_data/s__1249/part_meshes/4.dae" />
			</geometry>
		</visual>
	</link>


	<link name="5:cabinet door 1">
		<visual>
			<origin xyz="-1.074999988079071 -0.3999999947845936 -0.22299999743700027" rpy="0 0 0"/>
			<geometry>
				<mesh filename="raw_data/s__1249/part_meshes/5.dae" />
			</geometry>
		</visual>
	</link>


	<link name="6:cabinet door 2">
		<visual>
			<origin xyz="-0.7750000059604645 -0.3999999947845936 -0.22299999743700027" rpy="0 0 0"/>
			<geometry>
				<mesh filename="raw_data/s__1249/part_meshes/6.dae" />
			</geometry>
		</visual>
	</link>


	<link name="7:cabinet door 3">
		<visual>
			<origin xyz="0.7750000059604645 -0.3999999947845936 -0.22299999743700027" rpy="0 0 0"/>
			<geometry>
				<mesh filename="raw_data/s__1249/part_meshes/7.dae" />
			</geometry>
		</visual>
	</link>


	<link name="8:cabinet door 4">
		<visual>
			<origin xyz="1.211499966621399 -0.3674999991059303 -0.22000000154972077" rpy="0 0 0"/>
			<geometry>
				<mesh filename="raw_data/s__1249/part_meshes/8.dae" />
			</geometry>
		</visual>
	</link>


	<link name="9:drawer 1">
		<visual>
			<origin xyz="-0.4749999940395355 -0.5499999970197678 0.05649749934673309" rpy="0 0 0"/>
			<geometry>
				<mesh filename="raw_data/s__1249/part_meshes/9.dae" />
			</geometry>
		</visual>
	</link>


	<link name="10:drawer 2">
		<visual>
			<origin xyz="-0.4749999940395355 -0.2500000037252903 0.05649749934673309" rpy="0 0 0"/>
			<geometry>
				<mesh filename="raw_data/s__1249/part_meshes/10.dae" />
			</geometry>
		</visual>
	</link>


	<link name="11:drawer 3">
		<visual>
			<origin xyz="0.4749999940395355 -0.2500000037252903 0.05649749934673309" rpy="0 0 0"/>
			<geometry>
				<mesh filename="raw_data/s__1249/part_meshes/11.dae" />
			</geometry>
		</visual>
	</link>


	<link name="12:drawer 4">
		<visual>
			<origin xyz="0.4749999940395355 -0.5499999970197678 0.05649749934673309" rpy="0 0 0"/>
			<geometry>
				<mesh filename="raw_data/s__1249/part_meshes/12.dae" />
			</geometry>
		</visual>
	</link>


	<link name="13:drawer 5">
		<visual>
			<origin xyz="-0.0 -0.699999988079071 0.0589974969625473" rpy="0 0 0"/>
			<geometry>
				<mesh filename="raw_data/s__1249/part_meshes/13.dae" />
			</geometry>
		</visual>
	</link>


	<link name="14:drawer 6">
		<visual>
			<origin xyz="-0.4749999940395355 -0.7849999964237213 0.0589974969625473" rpy="0 0 0"/>
			<geometry>
				<mesh filename="raw_data/s__1249/part_meshes/14.dae" />
			</geometry>
		</visual>
	</link>


	<link name="15:drawer 7">
		<visual>
			<origin xyz="-0.9249999821186066 -0.7849999964237213 0.008211009204387665" rpy="0 0 0"/>
			<geometry>
				<mesh filename="raw_data/s__1249/part_meshes/15.dae" />
			</geometry>
		</visual>
	</link>


	<link name="16:drawer 8">
		<visual>
			<origin xyz="0.4749999940395355 -0.7849999964237213 0.0589974969625473" rpy="0 0 0"/>
			<geometry>
				<mesh filename="raw_data/s__1249/part_meshes/16.dae" />
			</geometry>
		</visual>
	</link>


	<link name="17:drawer 9">
		<visual>
			<origin xyz="0.9249999821186066 -0.7849999964237213 0.008211277425289154" rpy="0 0 0"/>
			<geometry>
				<mesh filename="raw_data/s__1249/part_meshes/17.dae" />
			</geometry>
		</visual>
	</link>


	<link name="18:faucet handle 2">
		<visual>
			<origin xyz="-0.8036218631467004 -0.9572769994735717 0.29963982456509924" rpy="0 0 0"/>
			<geometry>
				<mesh filename="raw_data/s__1249/part_meshes/18.dae" />
			</geometry>
		</visual>
	</link>


	<link name="19:faucet handle 3">
		<visual>
			<origin xyz="-1.0643813787312422 -0.9572769994735718 0.3152838359203729" rpy="0 0 0"/>
			<geometry>
				<mesh filename="raw_data/s__1249/part_meshes/19.dae" />
			</geometry>
		</visual>
	</link>


	<link name="20:faucet handle 4">
		<visual>
			<origin xyz="0.8073064237234654 -0.9672769994735718 0.302922795153217" rpy="0 0 0"/>
			<geometry>
				<mesh filename="raw_data/s__1249/part_meshes/20.dae" />
			</geometry>
		</visual>
	</link>


	<joint name="0:virtual::1:static" type="fixed">
		<parent link="0:virtual"/>
		<child link="1:static"/>
		<origin xyz="0.0 0.0 0.0" rpy="0 0 0"/>
	</joint>


	<joint name="0:virtual::2:faucet handle 1_rotation" type="revolute">
		<parent link="0:virtual"/>
		<child link="2:faucet handle 1"/>
		<origin xyz="-1.0483477637624394 0.9616730017662048 -0.2910869707179954" rpy="0 0 0"/>
		<limit lower="0.20420352248333656" upper="1.1623892818282235" effort="10" velocity="3"/>
		<axis xyz="0.0 1.0 0.0"/>
	</joint>


	<joint name="0:virtual::3:faucet lift rod 1_translation" type="prismatic">
		<parent link="0:virtual"/>
		<child link="3:faucet lift rod 1"/>
		<origin xyz="-0.9250001608975427 0.9515649676322937 -0.3011934459505527" rpy="0 0 0"/>
		<limit lower="0.0" upper="0.0430000321865082" effort="10" velocity="3"/>
		<axis xyz="0.0 1.0 0.0"/>
	</joint>


	<joint name="0:virtual::4:faucet lift rod 2_translation" type="prismatic">
		<parent link="0:virtual"/>
		<child link="4:faucet lift rod 2"/>
		<origin xyz="0.9249999001612884 0.9515649676322937 -0.3011933341572664" rpy="0 0 0"/>
		<limit lower="0.0" upper="0.0430000321865082" effort="10" velocity="3"/>
		<axis xyz="0.0 1.0 0.0"/>
	</joint>


	<joint name="0:virtual::5:cabinet door 1_rotation" type="revolute">
		<parent link="0:virtual"/>
		<child link="5:cabinet door 1"/>
		<origin xyz="1.074999988079071 0.3999999947845936 0.22299999743700027" rpy="0 0 0"/>
		<limit lower="-2.0420352248333655" upper="0.0" effort="10" velocity="3"/>
		<axis xyz="0.0 1.0 0.0"/>
	</joint>


	<joint name="0:virtual::6:cabinet door 2_rotation" type="revolute">
		<parent link="0:virtual"/>
		<child link="6:cabinet door 2"/>
		<origin xyz="0.7750000059604645 0.3999999947845936 0.22299999743700027" rpy="0 0 0"/>
		<limit lower="-2.0420352248333655" upper="0.0" effort="10" velocity="3"/>
		<axis xyz="0.0 1.0 0.0"/>
	</joint>


	<joint name="0:virtual::7:cabinet door 3_rotation" type="revolute">
		<parent link="0:virtual"/>
		<child link="7:cabinet door 3"/>
		<origin xyz="-0.7750000059604645 0.3999999947845936 0.22299999743700027" rpy="0 0 0"/>
		<limit lower="-2.0420352248333655" upper="0.0" effort="10" velocity="3"/>
		<axis xyz="0.0 1.0 0.0"/>
	</joint>


	<joint name="0:virtual::8:cabinet door 4_rotation" type="revolute">
		<parent link="0:virtual"/>
		<child link="8:cabinet door 4"/>
		<origin xyz="-1.211499966621399 0.3674999991059303 0.22000000154972077" rpy="0 0 0"/>
		<limit lower="-2.0420352248333655" upper="0.0" effort="10" velocity="3"/>
		<axis xyz="0.0 1.0 0.0"/>
	</joint>


	<joint name="0:virtual::9:drawer 1_translation" type="prismatic">
		<parent link="0:virtual"/>
		<child link="9:drawer 1"/>
		<origin xyz="0.4749999940395355 0.5499999970197678 -0.05649749934673309" rpy="0 0 0"/>
		<limit lower="0.0060000066161156" upper="0.450000006616116" effort="10" velocity="3"/>
		<axis xyz="0.0 0.0 1.0"/>
	</joint>


	<joint name="0:virtual::10:drawer 2_translation" type="prismatic">
		<parent link="0:virtual"/>
		<child link="10:drawer 2"/>
		<origin xyz="0.4749999940395355 0.2500000037252903 -0.05649749934673309" rpy="0 0 0"/>
		<limit lower="0.0060000066161156" upper="0.450000006616116" effort="10" velocity="3"/>
		<axis xyz="0.0 0.0 1.0"/>
	</joint>


	<joint name="0:virtual::11:drawer 3_translation" type="prismatic">
		<parent link="0:virtual"/>
		<child link="11:drawer 3"/>
		<origin xyz="-0.4749999940395355 0.2500000037252903 -0.05649749934673309" rpy="0 0 0"/>
		<limit lower="0.0060000066161156" upper="0.450000006616116" effort="10" velocity="3"/>
		<axis xyz="0.0 0.0 1.0"/>
	</joint>


	<joint name="0:virtual::12:drawer 4_translation" type="prismatic">
		<parent link="0:virtual"/>
		<child link="12:drawer 4"/>
		<origin xyz="-0.4749999940395355 0.5499999970197678 -0.05649749934673309" rpy="0 0 0"/>
		<limit lower="0.0060000066161156" upper="0.450000006616116" effort="10" velocity="3"/>
		<axis xyz="0.0 0.0 1.0"/>
	</joint>


	<joint name="0:virtual::13:drawer 5_translation" type="prismatic">
		<parent link="0:virtual"/>
		<child link="13:drawer 5"/>
		<origin xyz="0.0 0.699999988079071 -0.0589974969625473" rpy="0 0 0"/>
		<limit lower="0.0060000066161156" upper="0.450000006616116" effort="10" velocity="3"/>
		<axis xyz="0.0 0.0 1.0"/>
	</joint>


	<joint name="0:virtual::14:drawer 6_translation" type="prismatic">
		<parent link="0:virtual"/>
		<child link="14:drawer 6"/>
		<origin xyz="0.4749999940395355 0.7849999964237213 -0.0589974969625473" rpy="0 0 0"/>
		<limit lower="0.0060000066161156" upper="0.450000006616116" effort="10" velocity="3"/>
		<axis xyz="0.0 0.0 1.0"/>
	</joint>


	<joint name="0:virtual::15:drawer 7_translation" type="prismatic">
		<parent link="0:virtual"/>
		<child link="15:drawer 7"/>
		<origin xyz="0.9249999821186066 0.7849999964237213 -0.008211009204387665" rpy="0 0 0"/>
		<limit lower="0.0" upper="0.282000006616116" effort="10" velocity="3"/>
		<axis xyz="0.0 0.0 1.0"/>
	</joint>


	<joint name="0:virtual::16:drawer 8_translation" type="prismatic">
		<parent link="0:virtual"/>
		<child link="16:drawer 8"/>
		<origin xyz="-0.4749999940395355 0.7849999964237213 -0.0589974969625473" rpy="0 0 0"/>
		<limit lower="0.0060000066161156" upper="0.450000006616116" effort="10" velocity="3"/>
		<axis xyz="0.0 0.0 1.0"/>
	</joint>


	<joint name="0:virtual::17:drawer 9_translation" type="prismatic">
		<parent link="0:virtual"/>
		<child link="17:drawer 9"/>
		<origin xyz="-0.9249999821186066 0.7849999964237213 -0.008211277425289154" rpy="0 0 0"/>
		<limit lower="0.0" upper="0.282000006616116" effort="10" velocity="3"/>
		<axis xyz="0.0 0.0 1.0"/>
	</joint>


	<joint name="0:virtual::18:faucet handle 2_rotation" type="revolute">
		<parent link="0:virtual"/>
		<child link="18:faucet handle 2"/>
		<origin xyz="0.8036218631467004 0.9572769994735717 -0.29963982456509924" rpy="0 0 0"/>
		<limit lower="0.3612831551628262" upper="1.6336281798666925" effort="10" velocity="3"/>
		<axis xyz="0.0 1.0 0.0"/>
	</joint>


	<joint name="0:virtual::19:faucet handle 3_rotation" type="revolute">
		<parent link="0:virtual"/>
		<child link="19:faucet handle 3"/>
		<origin xyz="1.0643813787312422 0.9572769994735718 -0.3152838359203729" rpy="0 0 0"/>
		<limit lower="-1.1152653920243765" upper="0.0" effort="10" velocity="3"/>
		<axis xyz="0.0 1.0 0.0"/>
	</joint>


	<joint name="0:virtual::20:faucet handle 4_rotation" type="revolute">
		<parent link="0:virtual"/>
		<child link="20:faucet handle 4"/>
		<origin xyz="-0.8073064237234654 0.9672769994735718 -0.302922795153217" rpy="0 0 0"/>
		<limit lower="-0.9424777960769379" upper="0.21991148575128555" effort="10" velocity="3"/>
		<axis xyz="0.0 1.0 0.0"/>
	</joint>


</robot>