<robot name="s__1508">


	<link name="0:virtual">
		<visual>
			<origin xyz="0.0 0.0 0.0" rpy="0 0 0"/>
			<geometry>
				<cylinder length="0" radius="0"/>
			</geometry>
		</visual>
	</link>


	<link name="1:static">
		<inertial>
			<origin xyz="0.0 0.0 0.0" rpy="0.0 0.0 0.0"/>
			<mass value="1.0"/>
			<inertia ixx="1.0" ixy="0.0" ixz="0.0" iyy="1.0" iyz="0.0" izz="1.0"/>
		</inertial>
		<visual>
			<origin xyz="-0.0 -0.0 -0.0" rpy="0 0 0"/>
			<geometry>
				<mesh filename="../raw_data/s__1508/part_meshes/1.dae" />
			</geometry>
		</visual>
	</link>


	<link name="2:wheel 1">
		<inertial>
			<origin xyz="0.0 0.0 0.0" rpy="0.0 0.0 0.0"/>
			<mass value="1.0"/>
			<inertia ixx="1.0" ixy="0.0" ixz="0.0" iyy="1.0" iyz="0.0" izz="1.0"/>
		</inertial>
		<visual>
			<origin xyz="1.6549603499449037e-05 -0.024030689260598592 -0.26853000372656644" rpy="0 0 0"/>
			<geometry>
				<mesh filename="../raw_data/s__1508/part_meshes/2.dae" />
			</geometry>
		</visual>
	</link>


	<link name="3:wheel 2">
		<inertial>
			<origin xyz="0.0 0.0 0.0" rpy="0.0 0.0 0.0"/>
			<mass value="1.0"/>
			<inertia ixx="1.0" ixy="0.0" ixz="0.0" iyy="1.0" iyz="0.0" izz="1.0"/>
		</inertial>
		<visual>
			<origin xyz="-0.2531254846982236 -0.024030684938082914 -0.08340679241842791" rpy="0 0 0"/>
			<geometry>
				<mesh filename="../raw_data/s__1508/part_meshes/3.dae" />
			</geometry>
		</visual>
	</link>


	<link name="4:wheel 3">
		<inertial>
			<origin xyz="0.0 0.0 0.0" rpy="0.0 0.0 0.0"/>
			<mass value="1.0"/>
			<inertia ixx="1.0" ixy="0.0" ixz="0.0" iyy="1.0" iyz="0.0" izz="1.0"/>
		</inertial>
		<visual>
			<origin xyz="-0.15646899976791168 -0.024030678455602583 0.21617850306209435" rpy="0 0 0"/>
			<geometry>
				<mesh filename="../raw_data/s__1508/part_meshes/4.dae" />
			</geometry>
		</visual>
	</link>


	<link name="5:wheel 4">
		<inertial>
			<origin xyz="0.0 0.0 0.0" rpy="0.0 0.0 0.0"/>
			<mass value="1.0"/>
			<inertia ixx="1.0" ixy="0.0" ixz="0.0" iyy="1.0" iyz="0.0" izz="1.0"/>
		</inertial>
		<visual>
			<origin xyz="0.1564103489535026 -0.02403067851358287 0.21620879470425722" rpy="0 0 0"/>
			<geometry>
				<mesh filename="../raw_data/s__1508/part_meshes/5.dae" />
			</geometry>
		</visual>
	</link>


	<link name="6:wheel 5">
		<inertial>
			<origin xyz="0.0 0.0 0.0" rpy="0.0 0.0 0.0"/>
			<mass value="1.0"/>
			<inertia ixx="1.0" ixy="0.0" ixz="0.0" iyy="1.0" iyz="0.0" izz="1.0"/>
		</inertial>
		<visual>
			<origin xyz="0.2531245203602135 -0.02403068503110717 -0.08335790578505245" rpy="0 0 0"/>
			<geometry>
				<mesh filename="../raw_data/s__1508/part_meshes/6.dae" />
			</geometry>
		</visual>
	</link>


	<link name="7:backrest 1">
		<inertial>
			<origin xyz="0.0 0.0 0.0" rpy="0.0 0.0 0.0"/>
			<mass value="1.0"/>
			<inertia ixx="1.0" ixy="0.0" ixz="0.0" iyy="1.0" iyz="0.0" izz="1.0"/>
		</inertial>
		<visual>
			<origin xyz="-8.501112461090088e-06 -0.7412914931774139 0.23334699869155884" rpy="0 0 0"/>
			<geometry>
				<mesh filename="../raw_data/s__1508/part_meshes/7.dae" />
			</geometry>
		</visual>
	</link>


	<link name="8:seat 1">
		<inertial>
			<origin xyz="0.0 0.0 0.0" rpy="0.0 0.0 0.0"/>
			<mass value="1.0"/>
			<inertia ixx="1.0" ixy="0.0" ixz="0.0" iyy="1.0" iyz="0.0" izz="1.0"/>
		</inertial>
		<visual>
			<origin xyz="-1.2970228624120672e-05 -0.4281120002269745 -0.014817997978811498" rpy="0 0 0"/>
			<geometry>
				<mesh filename="../raw_data/s__1508/part_meshes/8.dae" />
			</geometry>
		</visual>
	</link>


	<link name="9:caster 1">
		<inertial>
			<origin xyz="0.0 0.0 0.0" rpy="0.0 0.0 0.0"/>
			<mass value="1.0"/>
			<inertia ixx="1.0" ixy="0.0" ixz="0.0" iyy="1.0" iyz="0.0" izz="1.0"/>
		</inertial>
		<visual>
			<origin xyz="2.0709666597386716e-05 -0.04157970007508993 -0.2915453588700644" rpy="0 0 0"/>
			<geometry>
				<mesh filename="../raw_data/s__1508/part_meshes/9.dae" />
			</geometry>
		</visual>
	</link>


	<link name="10:caster 2">
		<inertial>
			<origin xyz="0.0 0.0 0.0" rpy="0.0 0.0 0.0"/>
			<mass value="1.0"/>
			<inertia ixx="1.0" ixy="0.0" ixz="0.0" iyy="1.0" iyz="0.0" izz="1.0"/>
		</inertial>
		<visual>
			<origin xyz="-0.26913199088336787 -0.04157970007508993 -0.08864603178010733" rpy="0 0 0"/>
			<geometry>
				<mesh filename="../raw_data/s__1508/part_meshes/10.dae" />
			</geometry>
		</visual>
	</link>


	<link name="11:caster 3">
		<inertial>
			<origin xyz="0.0 0.0 0.0" rpy="0.0 0.0 0.0"/>
			<mass value="1.0"/>
			<inertia ixx="1.0" ixy="0.0" ixz="0.0" iyy="1.0" iyz="0.0" izz="1.0"/>
		</inertial>
		<visual>
			<origin xyz="-0.1662378404256559 -0.04157970007508993 0.22970955098294518" rpy="0 0 0"/>
			<geometry>
				<mesh filename="../raw_data/s__1508/part_meshes/11.dae" />
			</geometry>
		</visual>
	</link>


	<link name="12:caster 4">
		<inertial>
			<origin xyz="0.0 0.0 0.0" rpy="0.0 0.0 0.0"/>
			<mass value="1.0"/>
			<inertia ixx="1.0" ixy="0.0" ixz="0.0" iyy="1.0" iyz="0.0" izz="1.0"/>
		</inertial>
		<visual>
			<origin xyz="0.16969645905184771 -0.04157970007508993 0.23462198528743686" rpy="0 0 0"/>
			<geometry>
				<mesh filename="../raw_data/s__1508/part_meshes/12.dae" />
			</geometry>
		</visual>
	</link>


	<link name="13:caster 5">
		<inertial>
			<origin xyz="0.0 0.0 0.0" rpy="0.0 0.0 0.0"/>
			<mass value="1.0"/>
			<inertia ixx="1.0" ixy="0.0" ixz="0.0" iyy="1.0" iyz="0.0" izz="1.0"/>
		</inertial>
		<visual>
			<origin xyz="0.25663893552291744 -0.04157970007508993 -0.08450657330175097" rpy="0 0 0"/>
			<geometry>
				<mesh filename="../raw_data/s__1508/part_meshes/13.dae" />
			</geometry>
		</visual>
	</link>


	<link name="14:lever 1">
		<inertial>
			<origin xyz="0.0 0.0 0.0" rpy="0.0 0.0 0.0"/>
			<mass value="1.0"/>
			<inertia ixx="1.0" ixy="0.0" ixz="0.0" iyy="1.0" iyz="0.0" izz="1.0"/>
		</inertial>
		<visual>
			<origin xyz="0.037004882996964195 -0.36934199929237366 -0.0024251050390433695" rpy="0 0 0"/>
			<geometry>
				<mesh filename="../raw_data/s__1508/part_meshes/14.dae" />
			</geometry>
		</visual>
	</link>


	<link name="15:knob 1">
		<inertial>
			<origin xyz="0.0 0.0 0.0" rpy="0.0 0.0 0.0"/>
			<mass value="1.0"/>
			<inertia ixx="1.0" ixy="0.0" ixz="0.0" iyy="1.0" iyz="0.0" izz="1.0"/>
		</inertial>
		<visual>
			<origin xyz="-8.60169529914856e-06 -0.337973490357399 0.12636735290288925" rpy="0 0 0"/>
			<geometry>
				<mesh filename="../raw_data/s__1508/part_meshes/15.dae" />
			</geometry>
		</visual>
	</link>


	<link name="16:gas lift piece 2">
		<inertial>
			<origin xyz="0.0 0.0 0.0" rpy="0.0 0.0 0.0"/>
			<mass value="1.0"/>
			<inertia ixx="1.0" ixy="0.0" ixz="0.0" iyy="1.0" iyz="0.0" izz="1.0"/>
		</inertial>
		<visual>
			<origin xyz="-8.54771903711915e-06 -0.23213400319218636 -0.000581345748679768" rpy="0 0 0"/>
			<geometry>
				<mesh filename="../raw_data/s__1508/part_meshes/16.dae" />
			</geometry>
		</visual>
	</link>


	<joint name="0:virtual::1:static" type="fixed">
		<parent link="0:virtual"/>
		<child link="1:static"/>
		<origin xyz="0.0 0.0 0.0" rpy="0 0 0"/>
	</joint>


	<joint name="9:caster 1::2:wheel 1_rotation" type="revolute">
		<parent link="9:caster 1"/>
		<child link="2:wheel 1"/>
		<origin xyz="4.1600630979376795e-06 -0.01754901081449134 -0.02301535514349795" rpy="0 0 0"/>
		<limit lower="-3.141592653589793" upper="3.141592653589793" effort="10" velocity="3"/>
		<axis xyz="0.9999999836203655 0.0 0.00018099521812153224"/>
	</joint>


	<joint name="10:caster 2::3:wheel 2_rotation" type="revolute">
		<parent link="10:caster 2"/>
		<child link="3:wheel 2"/>
		<origin xyz="-0.016006506185144265 -0.017549015137007018 -0.005239239361679415" rpy="0 0 0"/>
		<limit lower="-3.141592653589793" upper="3.141592653589793" effort="10" velocity="3"/>
		<axis xyz="0.30730543735973154 0.0 -0.951610933191262"/>
	</joint>


	<joint name="11:caster 3::4:wheel 3_rotation" type="revolute">
		<parent link="11:caster 3"/>
		<child link="4:wheel 3"/>
		<origin xyz="-0.009768840657744221 -0.01754902161948735 0.01353104792085083" rpy="0 0 0"/>
		<limit lower="-3.141592653589793" upper="3.141592653589793" effort="10" velocity="3"/>
		<axis xyz="-0.8070202168023243 0.0 -0.5905238095727638"/>
	</joint>


	<joint name="12:caster 4::5:wheel 4_rotation" type="revolute">
		<parent link="12:caster 4"/>
		<child link="5:wheel 4"/>
		<origin xyz="0.013286110098345127 -0.01754902156150706 0.01841319058317964" rpy="0 0 0"/>
		<limit lower="-3.141592653589793" upper="3.141592653589793" effort="10" velocity="3"/>
		<axis xyz="0.807231616222354 0.0 -0.5902347988479215"/>
	</joint>


	<joint name="13:caster 5::6:wheel 5_rotation" type="revolute">
		<parent link="13:caster 5"/>
		<child link="6:wheel 5"/>
		<origin xyz="0.0035144151627039544 -0.017549015043982763 -0.0011486675166985233" rpy="0 0 0"/>
		<limit lower="-3.141592653589793" upper="3.141592653589793" effort="10" velocity="3"/>
		<axis xyz="0.3069675191834118 0.0 0.9517199914714316"/>
	</joint>


	<joint name="16:gas lift piece 2::7:backrest 1_translation" type="prismatic">
		<parent link="16:gas lift piece 2"/>
		<child link="7:backrest 1"/>
		<origin xyz="-4.6606576029062374e-08 0.5091574899852276 -0.2339283444402386" rpy="0 0 0"/>
		<limit lower="-0.127640021085739" upper="0.00035997891426086" effort="10" velocity="3"/>
		<axis xyz="0.0 1.0 0.0"/>
	</joint>


	<joint name="16:gas lift piece 2::8:seat 1_translation" type="prismatic">
		<parent link="16:gas lift piece 2"/>
		<child link="8:seat 1"/>
		<origin xyz="4.422509587001522e-06 0.19597799703478813 0.01423665223013173" rpy="0 0 0"/>
		<limit lower="-0.019693002104759216" upper="0.019693002104759216" effort="10" velocity="3"/>
		<axis xyz="0.0 1.0 0.0"/>
	</joint>


	<joint name="0:virtual::9:caster 1_rotation" type="revolute">
		<parent link="0:virtual"/>
		<child link="9:caster 1"/>
		<origin xyz="-2.0709666597386716e-05 0.04157970007508993 0.2915453588700644" rpy="0 0 0"/>
		<limit lower="-3.141592653589793" upper="3.141592653589793" effort="10" velocity="3"/>
		<axis xyz="0.0 1.0 0.0"/>
	</joint>


	<joint name="0:virtual::10:caster 2_rotation" type="revolute">
		<parent link="0:virtual"/>
		<child link="10:caster 2"/>
		<origin xyz="0.26913199088336787 0.04157970007508993 0.08864603178010733" rpy="0 0 0"/>
		<limit lower="-3.141592653589793" upper="3.141592653589793" effort="10" velocity="3"/>
		<axis xyz="0.0 1.0 0.0"/>
	</joint>


	<joint name="0:virtual::11:caster 3_rotation" type="revolute">
		<parent link="0:virtual"/>
		<child link="11:caster 3"/>
		<origin xyz="0.1662378404256559 0.04157970007508993 -0.22970955098294518" rpy="0 0 0"/>
		<limit lower="-3.141592653589793" upper="3.141592653589793" effort="10" velocity="3"/>
		<axis xyz="0.0 1.0 0.0"/>
	</joint>


	<joint name="0:virtual::12:caster 4_rotation" type="revolute">
		<parent link="0:virtual"/>
		<child link="12:caster 4"/>
		<origin xyz="-0.16969645905184771 0.04157970007508993 -0.23462198528743686" rpy="0 0 0"/>
		<limit lower="-3.141592653589793" upper="3.141592653589793" effort="10" velocity="3"/>
		<axis xyz="0.0 1.0 0.0"/>
	</joint>


	<joint name="0:virtual::13:caster 5_rotation" type="revolute">
		<parent link="0:virtual"/>
		<child link="13:caster 5"/>
		<origin xyz="-0.25663893552291744 0.04157970007508993 0.08450657330175097" rpy="0 0 0"/>
		<limit lower="-3.141592653589793" upper="3.141592653589793" effort="10" velocity="3"/>
		<axis xyz="0.0 1.0 0.0"/>
	</joint>


	<joint name="16:gas lift piece 2::14:lever 1_rotation" type="revolute">
		<parent link="16:gas lift piece 2"/>
		<child link="14:lever 1"/>
		<origin xyz="-0.037013430716001314 0.1372079961001873 0.0018437592903636016" rpy="0 0 0"/>
		<limit lower="-0.20420352248333656" upper="0.18849555921538758" effort="10" velocity="3"/>
		<axis xyz="0.0 0.0 1.0"/>
	</joint>


	<joint name="16:gas lift piece 2::15:knob 1_rotation" type="revolute">
		<parent link="16:gas lift piece 2"/>
		<child link="15:knob 1"/>
		<origin xyz="5.3976262029409305e-08 0.10583948716521263 -0.12694869865156902" rpy="0 0 0"/>
		<limit lower="-3.141592653589793" upper="3.141592653589793" effort="10" velocity="3"/>
		<axis xyz="0.0 1.0 0.0"/>
	</joint>


	<joint name="0:virtual::16:gas lift piece 2_rotation" type="revolute">
		<parent link="0:virtual"/>
		<child link="16:gas lift piece 2"/>
		<origin xyz="8.54771903711915e-06 0.23213400319218636 0.000581345748679768" rpy="0 0 0"/>
		<limit lower="-3.141592653589793" upper="3.141592653589793" effort="10" velocity="3"/>
		<axis xyz="0.0 1.0 0.0"/>
	</joint>


</robot>