<robot name="s__1504">


	<link name="0:virtual">
		<visual>
			<origin xyz="0.0 0.0 0.0" rpy="0 0 0"/>
			<geometry>
				<cylinder length="0" radius="0"/>
			</geometry>
		</visual>
	</link>


	<link name="1:static">
		<visual>
			<origin xyz="-0.0 -0.0 -0.0" rpy="0 0 0"/>
			<geometry>
				<mesh filename="../raw_data/s__1504/part_meshes/1.dae" />
			</geometry>
		</visual>
	</link>


	<link name="2:caster 1">
		<visual>
			<origin xyz="-0.1726880817683915 -0.03431604988873005 0.2535004614759138" rpy="0 0 0"/>
			<geometry>
				<mesh filename="../raw_data/s__1504/part_meshes/2.dae" />
			</geometry>
		</visual>
	</link>


	<link name="3:caster 2">
		<visual>
			<origin xyz="0.17268820881031688 -0.03431604988873005 0.25350041136257684" rpy="0 0 0"/>
			<geometry>
				<mesh filename="../raw_data/s__1504/part_meshes/3.dae" />
			</geometry>
		</visual>
	</link>


	<link name="4:caster 3">
		<visual>
			<origin xyz="0.2794399185597632 -0.03431604988873005 -0.07210891907322665" rpy="0 0 0"/>
			<geometry>
				<mesh filename="../raw_data/s__1504/part_meshes/4.dae" />
			</geometry>
		</visual>
	</link>


	<link name="5:backrest 1">
		<visual>
			<origin xyz="-0.0 -0.3603470027446747 0.23086650669574738" rpy="0 0 0"/>
			<geometry>
				<mesh filename="../raw_data/s__1504/part_meshes/5.dae" />
			</geometry>
		</visual>
	</link>


	<link name="6:seat 1">
		<visual>
			<origin xyz="-0.0 -0.4065764993429184 -0.05126550793647766" rpy="0 0 0"/>
			<geometry>
				<mesh filename="../raw_data/s__1504/part_meshes/6.dae" />
			</geometry>
		</visual>
	</link>


	<link name="7:wheel 1">
		<visual>
			<origin xyz="-0.2768285310232935 -0.019832543317044316 -0.07126754771307525" rpy="0 0 0"/>
			<geometry>
				<mesh filename="../raw_data/s__1504/part_meshes/7.dae" />
			</geometry>
		</visual>
	</link>


	<link name="8:wheel 2">
		<visual>
			<origin xyz="-0.17108932663571008 -0.01983253633534421 0.2513194582419507" rpy="0 0 0"/>
			<geometry>
				<mesh filename="../raw_data/s__1504/part_meshes/8.dae" />
			</geometry>
		</visual>
	</link>


	<link name="9:gas lift piece 2">
		<visual>
			<origin xyz="-1.3089108911318315e-09 -0.1397012546658516 0.017893296272549243" rpy="0 0 0"/>
			<geometry>
				<mesh filename="../raw_data/s__1504/part_meshes/9.dae" />
			</geometry>
		</visual>
	</link>


	<link name="10:wheel 3">
		<visual>
			<origin xyz="0.17108949665557513 -0.019832536383294297 0.25131900117946354" rpy="0 0 0"/>
			<geometry>
				<mesh filename="../raw_data/s__1504/part_meshes/10.dae" />
			</geometry>
		</visual>
	</link>


	<link name="11:wheel 4">
		<visual>
			<origin xyz="0.27682844939245504 -0.019832543394594282 -0.07126794576669399" rpy="0 0 0"/>
			<geometry>
				<mesh filename="../raw_data/s__1504/part_meshes/11.dae" />
			</geometry>
		</visual>
	</link>


	<link name="12:wheel 5">
		<visual>
			<origin xyz="-0.0 -0.019832547940854428 -0.27063749730587006" rpy="0 0 0"/>
			<geometry>
				<mesh filename="../raw_data/s__1504/part_meshes/12.dae" />
			</geometry>
		</visual>
	</link>


	<link name="13:lever 1">
		<visual>
			<origin xyz="0.021680368093770774 -0.3463520109653473 -0.000868899357443222" rpy="0 0 0"/>
			<geometry>
				<mesh filename="../raw_data/s__1504/part_meshes/13.dae" />
			</geometry>
		</visual>
	</link>


	<link name="14:knob 1">
		<visual>
			<origin xyz="-0.0010679472846793318 -0.31059399247169495 -0.10447310617651248" rpy="0 0 0"/>
			<geometry>
				<mesh filename="../raw_data/s__1504/part_meshes/14.dae" />
			</geometry>
		</visual>
	</link>


	<link name="15:caster 4">
		<visual>
			<origin xyz="-0.0 -0.03431604988873005 -0.2734000086784363" rpy="0 0 0"/>
			<geometry>
				<mesh filename="../raw_data/s__1504/part_meshes/15.dae" />
			</geometry>
		</visual>
	</link>


	<link name="16:caster 5">
		<visual>
			<origin xyz="-0.27943994968227437 -0.03431604988873005 -0.07210874297944554" rpy="0 0 0"/>
			<geometry>
				<mesh filename="../raw_data/s__1504/part_meshes/16.dae" />
			</geometry>
		</visual>
	</link>


	<joint name="0:virtual::1:static" type="fixed">
		<parent link="0:virtual"/>
		<child link="1:static"/>
		<origin xyz="0.0 0.0 0.0" rpy="0 0 0"/>
	</joint>


	<joint name="0:virtual::2:caster 1_rotation" type="revolute">
		<parent link="0:virtual"/>
		<child link="2:caster 1"/>
		<origin xyz="0.1726880817683915 0.03431604988873005 -0.2535004614759138" rpy="0 0 0"/>
		<limit lower="-3.141592653589793" upper="3.141592653589793" effort="10" velocity="3"/>
		<axis xyz="0.0 1.0 0.0"/>
	</joint>


	<joint name="0:virtual::3:caster 2_rotation" type="revolute">
		<parent link="0:virtual"/>
		<child link="3:caster 2"/>
		<origin xyz="-0.17268820881031688 0.03431604988873005 -0.25350041136257684" rpy="0 0 0"/>
		<limit lower="-3.141592653589793" upper="3.141592653589793" effort="10" velocity="3"/>
		<axis xyz="0.0 1.0 0.0"/>
	</joint>


	<joint name="0:virtual::4:caster 3_rotation" type="revolute">
		<parent link="0:virtual"/>
		<child link="4:caster 3"/>
		<origin xyz="-0.2794399185597632 0.03431604988873005 0.07210891907322665" rpy="0 0 0"/>
		<limit lower="-3.141592653589793" upper="3.141592653589793" effort="10" velocity="3"/>
		<axis xyz="0.0 1.0 0.0"/>
	</joint>


	<joint name="6:seat 1::5:backrest 1_rotation" type="revolute">
		<parent link="6:seat 1"/>
		<child link="5:backrest 1"/>
		<origin xyz="0.0 -0.04622949659824371 -0.28213201463222504" rpy="0 0 0"/>
		<limit lower="-0.3141592653589793" upper="0.25132741228718347" effort="10" velocity="3"/>
		<axis xyz="-1.0 0.0 0.0"/>
	</joint>


	<joint name="9:gas lift piece 2::6:seat 1_translation" type="prismatic">
		<parent link="9:gas lift piece 2"/>
		<child link="6:seat 1"/>
		<origin xyz="-1.3089108911318315e-09 0.2668752446770668 0.0691588042090269" rpy="0 0 0"/>
		<limit lower="-0.030886992812156677" upper="0.030886992812156677" effort="10" velocity="3"/>
		<axis xyz="0.0 1.0 0.0"/>
	</joint>


	<joint name="0:virtual::7:wheel 1_rotation" type="revolute">
		<parent link="0:virtual"/>
		<child link="7:wheel 1"/>
		<origin xyz="0.2768285310232935 0.019832543317044316 0.07126754771307525" rpy="0 0 0"/>
		<limit lower="-3.141592653589793" upper="3.141592653589793" effort="10" velocity="3"/>
		<axis xyz="-0.3114833270056346 0.0 0.9502516177294839"/>
	</joint>


	<joint name="0:virtual::8:wheel 2_rotation" type="revolute">
		<parent link="0:virtual"/>
		<child link="8:wheel 2"/>
		<origin xyz="0.17108932663571008 0.01983253633534421 -0.2513194582419507" rpy="0 0 0"/>
		<limit lower="-3.141592653589793" upper="3.141592653589793" effort="10" velocity="3"/>
		<axis xyz="-0.8114636493271234 0.0 -0.5844028968277856"/>
	</joint>


	<joint name="0:virtual::9:gas lift piece 2_rotation" type="revolute">
		<parent link="0:virtual"/>
		<child link="9:gas lift piece 2"/>
		<origin xyz="1.3089108911318315e-09 0.1397012546658516 -0.017893296272549243" rpy="0 0 0"/>
		<limit lower="-3.141592653589793" upper="3.141592653589793" effort="10" velocity="3"/>
		<axis xyz="0.0 1.0 0.0"/>
	</joint>


	<joint name="0:virtual::10:wheel 3_rotation" type="revolute">
		<parent link="0:virtual"/>
		<child link="10:wheel 3"/>
		<origin xyz="-0.17108949665557513 0.019832536383294297 -0.25131900117946354" rpy="0 0 0"/>
		<limit lower="-3.141592653589793" upper="3.141592653589793" effort="10" velocity="3"/>
		<axis xyz="0.8114573779861489 0.0 -0.5844116047032643"/>
	</joint>


	<joint name="0:virtual::11:wheel 4_rotation" type="revolute">
		<parent link="0:virtual"/>
		<child link="11:wheel 4"/>
		<origin xyz="-0.27682844939245504 0.019832543394594282 0.07126794576669399" rpy="0 0 0"/>
		<limit lower="-3.141592653589793" upper="3.141592653589793" effort="10" velocity="3"/>
		<axis xyz="-0.31146740184651406 0.0 -0.9502568376954633"/>
	</joint>


	<joint name="0:virtual::12:wheel 5_rotation" type="revolute">
		<parent link="0:virtual"/>
		<child link="12:wheel 5"/>
		<origin xyz="0.0 0.019832547940854428 0.27063749730587006" rpy="0 0 0"/>
		<limit lower="-3.141592653589793" upper="3.141592653589793" effort="10" velocity="3"/>
		<axis xyz="1.0 0.0 0.0"/>
	</joint>


	<joint name="9:gas lift piece 2::13:lever 1_rotation" type="revolute">
		<parent link="9:gas lift piece 2"/>
		<child link="13:lever 1"/>
		<origin xyz="-0.021680369402681664 0.2066507562994957 0.018762195629992463" rpy="0 0 0"/>
		<limit lower="-0.1413716694115407" upper="0.25132741228718347" effort="10" velocity="3"/>
		<axis xyz="-0.13127950170753452 0.0 -0.9913453951229215"/>
	</joint>


	<joint name="9:gas lift piece 2::14:knob 1_rotation" type="revolute">
		<parent link="9:gas lift piece 2"/>
		<child link="14:knob 1"/>
		<origin xyz="0.0010679459757684407 0.17089273780584335 0.12236640244906172" rpy="0 0 0"/>
		<limit lower="-0.4084070449666731" upper="0.1413716694115407" effort="10" velocity="3"/>
		<axis xyz="0.0 1.0 0.0"/>
	</joint>


	<joint name="0:virtual::15:caster 4_rotation" type="revolute">
		<parent link="0:virtual"/>
		<child link="15:caster 4"/>
		<origin xyz="0.0 0.03431604988873005 0.2734000086784363" rpy="0 0 0"/>
		<limit lower="-3.141592653589793" upper="3.141592653589793" effort="10" velocity="3"/>
		<axis xyz="0.0 1.0 0.0"/>
	</joint>


	<joint name="0:virtual::16:caster 5_rotation" type="revolute">
		<parent link="0:virtual"/>
		<child link="16:caster 5"/>
		<origin xyz="0.27943994968227437 0.03431604988873005 0.07210874297944554" rpy="0 0 0"/>
		<limit lower="-3.141592653589793" upper="3.141592653589793" effort="10" velocity="3"/>
		<axis xyz="0.0 1.0 0.0"/>
	</joint>


</robot>