<robot name="s__1201">


	<link name="0:virtual">
		<visual>
			<origin xyz="0.0 0.0 0.0" rpy="0 0 0"/>
			<geometry>
				<cylinder length="0" radius="0"/>
			</geometry>
		</visual>
	</link>


	<link name="1:static">
		<visual>
			<origin xyz="-0.0 -0.0 -0.0" rpy="0 0 0"/>
			<geometry>
				<mesh filename="raw_data/s__1201/part_meshes/1.dae" />
			</geometry>
		</visual>
	</link>


	<link name="2:drawer 1">
		<visual>
			<origin xyz="-0.48914600908756256 -0.4422750025987625 -0.40566201508045197" rpy="0 0 0"/>
			<geometry>
				<mesh filename="raw_data/s__1201/part_meshes/2.dae" />
			</geometry>
		</visual>
	</link>


	<link name="3:drawer 2">
		<visual>
			<origin xyz="-0.4892653673887253 -0.27920999377965927 -0.40566201508045197" rpy="0 0 0"/>
			<geometry>
				<mesh filename="raw_data/s__1201/part_meshes/3.dae" />
			</geometry>
		</visual>
	</link>


	<link name="4:drawer 3">
		<visual>
			<origin xyz="-0.5001460164785385 -0.1161458995193243 -0.40566201508045197" rpy="0 0 0"/>
			<geometry>
				<mesh filename="raw_data/s__1201/part_meshes/4.dae" />
			</geometry>
		</visual>
	</link>


	<link name="5:drawer 4">
		<visual>
			<origin xyz="0.5256620198488235 -0.4422750025987625 0.3581460043787956" rpy="0 0 0"/>
			<geometry>
				<mesh filename="raw_data/s__1201/part_meshes/5.dae" />
			</geometry>
		</visual>
	</link>


	<link name="6:drawer 5">
		<visual>
			<origin xyz="0.5256620198488235 -0.27920999377965927 0.3581460043787956" rpy="0 0 0"/>
			<geometry>
				<mesh filename="raw_data/s__1201/part_meshes/6.dae" />
			</geometry>
		</visual>
	</link>


	<link name="7:drawer 6">
		<visual>
			<origin xyz="0.5256620198488235 -0.1161458995193243 0.3581460043787956" rpy="0 0 0"/>
			<geometry>
				<mesh filename="raw_data/s__1201/part_meshes/7.dae" />
			</geometry>
		</visual>
	</link>


	<joint name="0:virtual::1:static" type="fixed">
		<parent link="0:virtual"/>
		<child link="1:static"/>
		<origin xyz="0.0 0.0 0.0" rpy="0 0 0"/>
	</joint>


	<joint name="0:virtual::2:drawer 1_translation" type="prismatic">
		<parent link="0:virtual"/>
		<child link="2:drawer 1"/>
		<origin xyz="0.48914600908756256 0.4422750025987625 0.40566201508045197" rpy="0 0 0"/>
		<limit lower="-0.380237472176552" upper="0.0" effort="10" velocity="3"/>
		<axis xyz="1.0 0.0 0.0"/>
	</joint>


	<joint name="0:virtual::3:drawer 2_translation" type="prismatic">
		<parent link="0:virtual"/>
		<child link="3:drawer 2"/>
		<origin xyz="0.4892653673887253 0.27920999377965927 0.40566201508045197" rpy="0 0 0"/>
		<limit lower="-0.380237472176552" upper="0.0" effort="10" velocity="3"/>
		<axis xyz="1.0 0.0 0.0"/>
	</joint>


	<joint name="0:virtual::4:drawer 3_translation" type="prismatic">
		<parent link="0:virtual"/>
		<child link="4:drawer 3"/>
		<origin xyz="0.5001460164785385 0.1161458995193243 0.40566201508045197" rpy="0 0 0"/>
		<limit lower="-0.380237472176552" upper="0.0" effort="10" velocity="3"/>
		<axis xyz="1.0 0.0 0.0"/>
	</joint>


	<joint name="0:virtual::5:drawer 4_translation" type="prismatic">
		<parent link="0:virtual"/>
		<child link="5:drawer 4"/>
		<origin xyz="-0.5256620198488235 0.4422750025987625 -0.3581460043787956" rpy="0 0 0"/>
		<limit lower="-0.0002375392317772" upper="0.359762460768223" effort="10" velocity="3"/>
		<axis xyz="0.0 0.0 1.0"/>
	</joint>


	<joint name="0:virtual::6:drawer 5_translation" type="prismatic">
		<parent link="0:virtual"/>
		<child link="6:drawer 5"/>
		<origin xyz="-0.5256620198488235 0.27920999377965927 -0.3581460043787956" rpy="0 0 0"/>
		<limit lower="-0.0002375392317772" upper="0.359762460768223" effort="10" velocity="3"/>
		<axis xyz="0.0 0.0 1.0"/>
	</joint>


	<joint name="0:virtual::7:drawer 6_translation" type="prismatic">
		<parent link="0:virtual"/>
		<child link="7:drawer 6"/>
		<origin xyz="-0.5256620198488235 0.1161458995193243 -0.3581460043787956" rpy="0 0 0"/>
		<limit lower="-0.0002375392317772" upper="0.359762460768223" effort="10" velocity="3"/>
		<axis xyz="0.0 0.0 1.0"/>
	</joint>


</robot>