<robot name="s__2090">


	<link name="0:virtual">
		<visual>
			<origin xyz="0.0 0.0 0.0" rpy="0 0 0"/>
			<geometry>
				<cylinder length="0" radius="0"/>
			</geometry>
		</visual>
	</link>


	<link name="1:static">
		<visual>
			<origin xyz="-0.0 -0.0 -0.0" rpy="0 0 0"/>
			<geometry>
				<mesh filename="raw_data/s__2090/part_meshes/1.dae" />
			</geometry>
		</visual>
	</link>


	<link name="2:drawer 1">
		<visual>
			<origin xyz="-0.20000001043081284 -0.5297195017337799 0.0022474974393844604" rpy="0 0 0"/>
			<geometry>
				<mesh filename="raw_data/s__2090/part_meshes/2.dae" />
			</geometry>
		</visual>
	</link>


	<link name="3:drawer 2">
		<visual>
			<origin xyz="-0.20000001043081284 -0.7084999978542328 0.0022475048899650574" rpy="0 0 0"/>
			<geometry>
				<mesh filename="raw_data/s__2090/part_meshes/3.dae" />
			</geometry>
		</visual>
	</link>


	<link name="4:drawer 3">
		<visual>
			<origin xyz="-0.20000001043081284 -0.35071949660778046 0.0022474974393844604" rpy="0 0 0"/>
			<geometry>
				<mesh filename="raw_data/s__2090/part_meshes/4.dae" />
			</geometry>
		</visual>
	</link>


	<link name="5:drawer 4">
		<visual>
			<origin xyz="-0.20000001043081284 -0.17171970382332802 0.0022474974393844604" rpy="0 0 0"/>
			<geometry>
				<mesh filename="raw_data/s__2090/part_meshes/5.dae" />
			</geometry>
		</visual>
	</link>


	<link name="6:cabinet door 1">
		<visual>
			<origin xyz="0.5775610208511353 -0.43978049606084824 -0.1782499998807907" rpy="0 0 0"/>
			<geometry>
				<mesh filename="raw_data/s__2090/part_meshes/6.dae" />
			</geometry>
		</visual>
	</link>


	<joint name="0:virtual::1:static" type="fixed">
		<parent link="0:virtual"/>
		<child link="1:static"/>
		<origin xyz="0.0 0.0 0.0" rpy="0 0 0"/>
	</joint>


	<joint name="0:virtual::2:drawer 1_translation" type="prismatic">
		<parent link="0:virtual"/>
		<child link="2:drawer 1"/>
		<origin xyz="0.20000001043081284 0.5297195017337799 -0.0022474974393844604" rpy="0 0 0"/>
		<limit lower="0.0" upper="0.346499998033047" effort="10" velocity="3"/>
		<axis xyz="0.0 0.0 1.0"/>
	</joint>


	<joint name="0:virtual::3:drawer 2_translation" type="prismatic">
		<parent link="0:virtual"/>
		<child link="3:drawer 2"/>
		<origin xyz="0.20000001043081284 0.7084999978542328 -0.0022475048899650574" rpy="0 0 0"/>
		<limit lower="0.0" upper="0.346499998033047" effort="10" velocity="3"/>
		<axis xyz="0.0 0.0 1.0"/>
	</joint>


	<joint name="0:virtual::4:drawer 3_translation" type="prismatic">
		<parent link="0:virtual"/>
		<child link="4:drawer 3"/>
		<origin xyz="0.20000001043081284 0.35071949660778046 -0.0022474974393844604" rpy="0 0 0"/>
		<limit lower="0.0" upper="0.346499998033047" effort="10" velocity="3"/>
		<axis xyz="0.0 0.0 1.0"/>
	</joint>


	<joint name="0:virtual::5:drawer 4_translation" type="prismatic">
		<parent link="0:virtual"/>
		<child link="5:drawer 4"/>
		<origin xyz="0.20000001043081284 0.17171970382332802 -0.0022474974393844604" rpy="0 0 0"/>
		<limit lower="0.0" upper="0.346499998033047" effort="10" velocity="3"/>
		<axis xyz="0.0 0.0 1.0"/>
	</joint>


	<joint name="0:virtual::6:cabinet door 1_rotation" type="revolute">
		<parent link="0:virtual"/>
		<child link="6:cabinet door 1"/>
		<origin xyz="-0.5775610208511353 0.43978049606084824 0.1782499998807907" rpy="0 0 0"/>
		<limit lower="-2.3876104167282426" upper="0.0" effort="10" velocity="3"/>
		<axis xyz="0.0 1.0 0.0"/>
	</joint>


</robot>